Workbook
Name AEA_Name: #REF!
Name AEA_Name: #REF!
Name Slicer_AEA_Name: #N/A

Sheet Summary
C1: =Detail[[#Headers],[Total Special Ed Weighting in Addition to 1.0]] -> Total Special Ed Weighting in Addition to 1.0 | D1: =Detail[[#Headers],[Budget Enrollment]] -> Budget Enrollment | E1: =Detail[[#Headers],[AEA Weighted Enrollment]] -> AEA Weighted Enrollment | F1: =Detail[[#Headers],[Resident Accredited Nonpublic Students]] -> Resident Accredited Nonpublic Students | G1: =Detail[[#Headers],[Shared-Time Nonpublic Pupils Counted in Line 1.1]] -> Shared-Time Nonpublic Pupils Counted in Line 1.1 | H1: =Detail[[#Headers],[Total Enrollment Served - AEA Media and Ed Services]] -> Total Enrollment Served - AEA Media and Ed Services | I1: =Detail[[#Headers],[AEA Special Ed Support Cost Per Pupil]] -> AEA Special Ed Support Cost Per Pupil | J1: =Detail[[#Headers],[AEA Media Cost Per Pupil]] -> AEA Media Cost Per Pupil | K1: =Detail[[#Headers],[AEA Ed Services Cost Per Pupil]] -> AEA Ed Services Cost Per Pupil
A2: AEA | B2: AEA Name | C2: Special Ed Weights | D2: Budget Enrollment | E2: Weighted Enrollment | F2: Nonpublic | G2: Shared-Time | H2: Media/Ed Served | I2: Support Cost PP | J2: Media Cost PP | K2: Ed Cost PP
A3: {=IFERROR(INDEX(Detail[AEA], MATCH(0,COUNTIF(Summary!$A$2:'Summary'!A2, Detail[AEA]), 0)),"")} -> 01 | B3: =INDEX(Detail[],MATCH(Summary!$A3,Detail[AEA],0),2) -> Keystone AEA 1 | C3: =SUMIFS(INDEX(Detail[],0,MATCH(C$1,Detail[#Headers],0)),Detail[AEA],$A3) -> 4389.61 | D3: =SUMIFS(INDEX(Detail[],0,MATCH(D$1,Detail[#Headers],0)),Detail[AEA],$A3) -> 27827.9 | E3: =SUMIFS(INDEX(Detail[],0,MATCH(E$1,Detail[#Headers],0)),Detail[AEA],$A3) -> 32217.51 | F3: =SUMIFS(INDEX(Detail[],0,MATCH(F$1,Detail[#Headers],0)),Detail[AEA],$A3) -> 3727 | G3: =SUMIFS(INDEX(Detail[],0,MATCH(G$1,Detail[#Headers],0)),Detail[AEA],$A3) -> 15.7 | H3: =SUMIFS(INDEX(Detail[],0,MATCH(H$1,Detail[#Headers],0)),Detail[AEA],$A3) -> 31540 | I3: =INDEX(Detail[],MATCH($A3,Detail[AEA],0),MATCH(I$1,Detail[#Headers],0)) -> 348.14 | J3: =INDEX(Detail[],MATCH($A3,Detail[AEA],0),MATCH(J$1,Detail[#Headers],0)) -> 62.44 | K3: =INDEX(Detail[],MATCH($A3,Detail[AEA],0),MATCH(K$1,Detail[#Headers],0)) -> 69.56
A4: {=IFERROR(INDEX(Detail[AEA], MATCH(0,COUNTIF(Summary!$A$2:'Summary'!A3, Detail[AEA]), 0)),"")} -> 05 | B4: =INDEX(Detail[],MATCH(Summary!$A4,Detail[AEA],0),2) -> Prairie Lakes AEA 8 | C4: =SUMIFS(INDEX(Detail[],0,MATCH(C$1,Detail[#Headers],0)),Detail[AEA],$A4) -> 4071.59 | D4: =SUMIFS(INDEX(Detail[],0,MATCH(D$1,Detail[#Headers],0)),Detail[AEA],$A4) -> 30049.2 | E4: =SUMIFS(INDEX(Detail[],0,MATCH(E$1,Detail[#Headers],0)),Detail[AEA],$A4) -> 34120.79 | F4: =SUMIFS(INDEX(Detail[],0,MATCH(F$1,Detail[#Headers],0)),Detail[AEA],$A4) -> 1962 | G4: =SUMIFS(INDEX(Detail[],0,MATCH(G$1,Detail[#Headers],0)),Detail[AEA],$A4) -> 23.6 | H4: =SUMIFS(INDEX(Detail[],0,MATCH(H$1,Detail[#Headers],0)),Detail[AEA],$A4) -> 31989 | I4: =INDEX(Detail[],MATCH($A4,Detail[AEA],0),MATCH(I$1,Detail[#Headers],0)) -> 343.89 | J4: =INDEX(Detail[],MATCH($A4,Detail[AEA],0),MATCH(J$1,Detail[#Headers],0)) -> 62.52 | K4: =INDEX(Detail[],MATCH($A4,Detail[AEA],0),MATCH(K$1,Detail[#Headers],0)) -> 70.03
A5: {=IFERROR(INDEX(Detail[AEA], MATCH(0,COUNTIF(Summary!$A$2:'Summary'!A4, Detail[AEA]), 0)),"")} -> 07 | B5: =INDEX(Detail[],MATCH(Summary!$A5,Detail[AEA],0),2) -> Central Rivers | C5: =SUMIFS(INDEX(Detail[],0,MATCH(C$1,Detail[#Headers],0)),Detail[AEA],$A5) -> 9425.97 | D5: =SUMIFS(INDEX(Detail[],0,MATCH(D$1,Detail[#Headers],0)),Detail[AEA],$A5) -> 61183.6 | E5: =SUMIFS(INDEX(Detail[],0,MATCH(E$1,Detail[#Headers],0)),Detail[AEA],$A5) -> 70609.57 | F5: =SUMIFS(INDEX(Detail[],0,MATCH(F$1,Detail[#Headers],0)),Detail[AEA],$A5) -> 3223 | G5: =SUMIFS(INDEX(Detail[],0,MATCH(G$1,Detail[#Headers],0)),Detail[AEA],$A5) -> 36.6 | H5: =SUMIFS(INDEX(Detail[],0,MATCH(H$1,Detail[#Headers],0)),Detail[AEA],$A5) -> 64374 | I5: =INDEX(Detail[],MATCH($A5,Detail[AEA],0),MATCH(I$1,Detail[#Headers],0)) -> 337.26 | J5: =INDEX(Detail[],MATCH($A5,Detail[AEA],0),MATCH(J$1,Detail[#Headers],0)) -> 62.47 | K5: =INDEX(Detail[],MATCH($A5,Detail[AEA],0),MATCH(K$1,Detail[#Headers],0)) -> 69.65
A6: {=IFERROR(INDEX(Detail[AEA], MATCH(0,COUNTIF(Summary!$A$2:'Summary'!A5, Detail[AEA]), 0)),"")} -> 09 | B6: =INDEX(Detail[],MATCH(Summary!$A6,Detail[AEA],0),2) -> Mississippi Bend AEA 9 | C6: =SUMIFS(INDEX(Detail[],0,MATCH(C$1,Detail[#Headers],0)),Detail[AEA],$A6) -> 6569.17 | D6: =SUMIFS(INDEX(Detail[],0,MATCH(D$1,Detail[#Headers],0)),Detail[AEA],$A6) -> 45239.7 | E6: =SUMIFS(INDEX(Detail[],0,MATCH(E$1,Detail[#Headers],0)),Detail[AEA],$A6) -> 51808.87 | F6: =SUMIFS(INDEX(Detail[],0,MATCH(F$1,Detail[#Headers],0)),Detail[AEA],$A6) -> 2989 | G6: =SUMIFS(INDEX(Detail[],0,MATCH(G$1,Detail[#Headers],0)),Detail[AEA],$A6) -> 5 | H6: =SUMIFS(INDEX(Detail[],0,MATCH(H$1,Detail[#Headers],0)),Detail[AEA],$A6) -> 48224 | I6: =INDEX(Detail[],MATCH($A6,Detail[AEA],0),MATCH(I$1,Detail[#Headers],0)) -> 334.9 | J6: =INDEX(Detail[],MATCH($A6,Detail[AEA],0),MATCH(J$1,Detail[#Headers],0)) -> 61.98 | K6: =INDEX(Detail[],MATCH($A6,Detail[AEA],0),MATCH(K$1,Detail[#Headers],0)) -> 67.73
A7: {=IFERROR(INDEX(Detail[AEA], MATCH(0,COUNTIF(Summary!$A$2:'Summary'!A6, Detail[AEA]), 0)),"")} -> 10 | B7: =INDEX(Detail[],MATCH(Summary!$A7,Detail[AEA],0),2) -> Grant Wood AEA 10 | C7: =SUMIFS(INDEX(Detail[],0,MATCH(C$1,Detail[#Headers],0)),Detail[AEA],$A7) -> 8446.91 | D7: =SUMIFS(INDEX(Detail[],0,MATCH(D$1,Detail[#Headers],0)),Detail[AEA],$A7) -> 69432.1 | E7: =SUMIFS(INDEX(Detail[],0,MATCH(E$1,Detail[#Headers],0)),Detail[AEA],$A7) -> 77879.01 | F7: =SUMIFS(INDEX(Detail[],0,MATCH(F$1,Detail[#Headers],0)),Detail[AEA],$A7) -> 4286 | G7: =SUMIFS(INDEX(Detail[],0,MATCH(G$1,Detail[#Headers],0)),Detail[AEA],$A7) -> 25.5 | H7: =SUMIFS(INDEX(Detail[],0,MATCH(H$1,Detail[#Headers],0)),Detail[AEA],$A7) -> 73695 | I7: =INDEX(Detail[],MATCH($A7,Detail[AEA],0),MATCH(I$1,Detail[#Headers],0)) -> 332.98 | J7: =INDEX(Detail[],MATCH($A7,Detail[AEA],0),MATCH(J$1,Detail[#Headers],0)) -> 62.16 | K7: =INDEX(Detail[],MATCH($A7,Detail[AEA],0),MATCH(K$1,Detail[#Headers],0)) -> 68.33
A8: {=IFERROR(INDEX(Detail[AEA], MATCH(0,COUNTIF(Summary!$A$2:'Summary'!A7, Detail[AEA]), 0)),"")} -> 11 | B8: =INDEX(Detail[],MATCH(Summary!$A8,Detail[AEA],0),2) -> Heartland AEA 11 | C8: =SUMIFS(INDEX(Detail[],0,MATCH(C$1,Detail[#Headers],0)),Detail[AEA],$A8) -> 19094.84 | D8: =SUMIFS(INDEX(Detail[],0,MATCH(D$1,Detail[#Headers],0)),Detail[AEA],$A8) -> 142154.8 | E8: =SUMIFS(INDEX(Detail[],0,MATCH(E$1,Detail[#Headers],0)),Detail[AEA],$A8) -> 161249.64 | F8: =SUMIFS(INDEX(Detail[],0,MATCH(F$1,Detail[#Headers],0)),Detail[AEA],$A8) -> 9930 | G8: =SUMIFS(INDEX(Detail[],0,MATCH(G$1,Detail[#Headers],0)),Detail[AEA],$A8) -> 85.1 | H8: =SUMIFS(INDEX(Detail[],0,MATCH(H$1,Detail[#Headers],0)),Detail[AEA],$A8) -> 152000 | I8: =INDEX(Detail[],MATCH($A8,Detail[AEA],0),MATCH(I$1,Detail[#Headers],0)) -> 325.88 | J8: =INDEX(Detail[],MATCH($A8,Detail[AEA],0),MATCH(J$1,Detail[#Headers],0)) -> 62.04 | K8: =INDEX(Detail[],MATCH($A8,Detail[AEA],0),MATCH(K$1,Detail[#Headers],0)) -> 68.15
A9: {=IFERROR(INDEX(Detail[AEA], MATCH(0,COUNTIF(Summary!$A$2:'Summary'!A8, Detail[AEA]), 0)),"")} -> 12 | B9: =INDEX(Detail[],MATCH(Summary!$A9,Detail[AEA],0),2) -> Northwest AEA | C9: =SUMIFS(INDEX(Detail[],0,MATCH(C$1,Detail[#Headers],0)),Detail[AEA],$A9) -> 5850.88 | D9: =SUMIFS(INDEX(Detail[],0,MATCH(D$1,Detail[#Headers],0)),Detail[AEA],$A9) -> 39907.6 | E9: =SUMIFS(INDEX(Detail[],0,MATCH(E$1,Detail[#Headers],0)),Detail[AEA],$A9) -> 45758.48 | F9: =SUMIFS(INDEX(Detail[],0,MATCH(F$1,Detail[#Headers],0)),Detail[AEA],$A9) -> 5387 | G9: =SUMIFS(INDEX(Detail[],0,MATCH(G$1,Detail[#Headers],0)),Detail[AEA],$A9) -> 42.3 | H9: =SUMIFS(INDEX(Detail[],0,MATCH(H$1,Detail[#Headers],0)),Detail[AEA],$A9) -> 45252 | I9: =INDEX(Detail[],MATCH($A9,Detail[AEA],0),MATCH(I$1,Detail[#Headers],0)) -> 340.52 | J9: =INDEX(Detail[],MATCH($A9,Detail[AEA],0),MATCH(J$1,Detail[#Headers],0)) -> 62.45 | K9: =INDEX(Detail[],MATCH($A9,Detail[AEA],0),MATCH(K$1,Detail[#Headers],0)) -> 69.93
A10: {=IFERROR(INDEX(Detail[AEA], MATCH(0,COUNTIF(Summary!$A$2:'Summary'!A9, Detail[AEA]), 0)),"")} -> 13 | B10: =INDEX(Detail[],MATCH(Summary!$A10,Detail[AEA],0),2) -> Green Hills AEA 13 | C10: =SUMIFS(INDEX(Detail[],0,MATCH(C$1,Detail[#Headers],0)),Detail[AEA],$A10) -> 6034.71 | D10: =SUMIFS(INDEX(Detail[],0,MATCH(D$1,Detail[#Headers],0)),Detail[AEA],$A10) -> 36818.9 | E10: =SUMIFS(INDEX(Detail[],0,MATCH(E$1,Detail[#Headers],0)),Detail[AEA],$A10) -> 42853.61 | F10: =SUMIFS(INDEX(Detail[],0,MATCH(F$1,Detail[#Headers],0)),Detail[AEA],$A10) -> 1034 | G10: =SUMIFS(INDEX(Detail[],0,MATCH(G$1,Detail[#Headers],0)),Detail[AEA],$A10) -> 4.6 | H10: =SUMIFS(INDEX(Detail[],0,MATCH(H$1,Detail[#Headers],0)),Detail[AEA],$A10) -> 37852 | I10: =INDEX(Detail[],MATCH($A10,Detail[AEA],0),MATCH(I$1,Detail[#Headers],0)) -> 333.94 | J10: =INDEX(Detail[],MATCH($A10,Detail[AEA],0),MATCH(J$1,Detail[#Headers],0)) -> 62.17 | K10: =INDEX(Detail[],MATCH($A10,Detail[AEA],0),MATCH(K$1,Detail[#Headers],0)) -> 68.73
A11: {=IFERROR(INDEX(Detail[AEA], MATCH(0,COUNTIF(Summary!$A$2:'Summary'!A10, Detail[AEA]), 0)),"")} -> 15 | B11: =INDEX(Detail[],MATCH(Summary!$A11,Detail[AEA],0),2) -> Great Prairie AEA 15 | C11: =SUMIFS(INDEX(Detail[],0,MATCH(C$1,Detail[#Headers],0)),Detail[AEA],$A11) -> 4768.12 | D11: =SUMIFS(INDEX(Detail[],0,MATCH(D$1,Detail[#Headers],0)),Detail[AEA],$A11) -> 33861.7 | E11: =SUMIFS(INDEX(Detail[],0,MATCH(E$1,Detail[#Headers],0)),Detail[AEA],$A11) -> 38629.82 | F11: =SUMIFS(INDEX(Detail[],0,MATCH(F$1,Detail[#Headers],0)),Detail[AEA],$A11) -> 1154 | G11: =SUMIFS(INDEX(Detail[],0,MATCH(G$1,Detail[#Headers],0)),Detail[AEA],$A11) -> 13.3 | H11: =SUMIFS(INDEX(Detail[],0,MATCH(H$1,Detail[#Headers],0)),Detail[AEA],$A11) -> 35004 | I11: =INDEX(Detail[],MATCH($A11,Detail[AEA],0),MATCH(I$1,Detail[#Headers],0)) -> 331.3 | J11: =INDEX(Detail[],MATCH($A11,Detail[AEA],0),MATCH(J$1,Detail[#Headers],0)) -> 62.14 | K11: =INDEX(Detail[],MATCH($A11,Detail[AEA],0),MATCH(K$1,Detail[#Headers],0)) -> 68.3
C12: =SUM(C3:C11) -> 68651.8 | D12: =SUM(D3:D11) -> 486475.5 | E12: =SUM(E3:E11) -> 555127.3 | F12: =SUM(F3:F11) -> 33692 | G12: =SUM(G3:G11) -> 251.7 | H12: =SUM(H3:H11) -> 519930
C14: =Detail[[#Headers],[AEA Teacher Salary Supplement District Cost Per Pupil]] -> AEA Teacher Salary Supplement District Cost Per Pupil | D14: =Detail[[#Headers],[Professional Development Supplement District Cost Per Pupil]] -> Professional Development Supplement District Cost Per Pupil | E14: =Detail[[#Headers],[AEA Special Ed Support District Cost without Adjustment]] -> AEA Special Ed Support District Cost without Adjustment | F14: =Detail[[#Headers],[AEA Special Ed Support Adjustment]] -> AEA Special Ed Support Adjustment | G14: =Detail[[#Headers],[Special Education Total Cost]] -> Special Education Total Cost | H14: =Detail[[#Headers],[AEA Media Services District Cost]] -> AEA Media Services District Cost | I14: =Detail[[#Headers],[AEA Ed Services District Cost]] -> AEA Ed Services District Cost | J14: =Detail[[#Headers],[AEA Sharing District Cost]] -> AEA Sharing District Cost
A15: =A2 -> AEA | B15: =B2 -> AEA Name | C15: Teach Sal Cost PP | D15: Prof Dev Cost PP | E15: Spec ED Support | F15: Spec Ed Adjust | G15: Special Ed Total Cost | H15: Media Services | I15: Education Services | J15: Sharing Operations
A16: =A3 -> 01 | B16: =B3 -> Keystone AEA 1 | C16: =INDEX(Detail[],MATCH($A16,Detail[AEA],0),MATCH(C$14,Detail[#Headers],0)) -> 34.47 | D16: =INDEX(Detail[],MATCH($A16,Detail[AEA],0),MATCH(D$14,Detail[#Headers],0)) -> 3.74 | E16: =SUMIFS(INDEX(Detail[],0,MATCH(E$14,Detail[#Headers],0)),Detail[AEA],$A16) -> 11216201 | F16: =SUMIFS(INDEX(Detail[],0,MATCH(F$14,Detail[#Headers],0)),Detail[AEA],$A16) -> 10552 | G16: =SUMIFS(INDEX(Detail[],0,MATCH(G$14,Detail[#Headers],0)),Detail[AEA],$A16) -> 11226753 | H16: =SUMIFS(INDEX(Detail[],0,MATCH(H$14,Detail[#Headers],0)),Detail[AEA],$A16) -> 1969358 | I16: =SUMIFS(INDEX(Detail[],0,MATCH(I$14,Detail[#Headers],0)),Detail[AEA],$A16) -> 2193922 | J16: =SUMIFS(INDEX(Detail[],0,MATCH(J$14,Detail[#Headers],0)),Detail[AEA],$A16) -> 30001
A17: =A4 -> 05 | B17: =B4 -> Prairie Lakes AEA 8 | C17: =INDEX(Detail[],MATCH($A17,Detail[AEA],0),MATCH(C$14,Detail[#Headers],0)) -> 36.43 | D17: =INDEX(Detail[],MATCH($A17,Detail[AEA],0),MATCH(D$14,Detail[#Headers],0)) -> 4.33 | E17: =SUMIFS(INDEX(Detail[],0,MATCH(E$14,Detail[#Headers],0)),Detail[AEA],$A17) -> 11733799 | F17: =SUMIFS(INDEX(Detail[],0,MATCH(F$14,Detail[#Headers],0)),Detail[AEA],$A17) -> 73537 | G17: =SUMIFS(INDEX(Detail[],0,MATCH(G$14,Detail[#Headers],0)),Detail[AEA],$A17) -> 11807336 | H17: =SUMIFS(INDEX(Detail[],0,MATCH(H$14,Detail[#Headers],0)),Detail[AEA],$A17) -> 1999952 | I17: =SUMIFS(INDEX(Detail[],0,MATCH(I$14,Detail[#Headers],0)),Detail[AEA],$A17) -> 2240189 | J17: =SUMIFS(INDEX(Detail[],0,MATCH(J$14,Detail[#Headers],0)),Detail[AEA],$A17) -> 0
A18: =A5 -> 07 | B18: =B5 -> Central Rivers | C18: =INDEX(Detail[],MATCH($A18,Detail[AEA],0),MATCH(C$14,Detail[#Headers],0)) -> 41.7 | D18: =INDEX(Detail[],MATCH($A18,Detail[AEA],0),MATCH(D$14,Detail[#Headers],0)) -> 4.8 | E18: =SUMIFS(INDEX(Detail[],0,MATCH(E$14,Detail[#Headers],0)),Detail[AEA],$A18) -> 23813783 | F18: =SUMIFS(INDEX(Detail[],0,MATCH(F$14,Detail[#Headers],0)),Detail[AEA],$A18) -> 120712 | G18: =SUMIFS(INDEX(Detail[],0,MATCH(G$14,Detail[#Headers],0)),Detail[AEA],$A18) -> 23934495 | H18: =SUMIFS(INDEX(Detail[],0,MATCH(H$14,Detail[#Headers],0)),Detail[AEA],$A18) -> 4021446 | I18: =SUMIFS(INDEX(Detail[],0,MATCH(I$14,Detail[#Headers],0)),Detail[AEA],$A18) -> 4483647 | J18: =SUMIFS(INDEX(Detail[],0,MATCH(J$14,Detail[#Headers],0)),Detail[AEA],$A18) -> 30001
A19: =A6 -> 09 | B19: =B6 -> Mississippi Bend AEA 9 | C19: =INDEX(Detail[],MATCH($A19,Detail[AEA],0),MATCH(C$14,Detail[#Headers],0)) -> 30.77 | D19: =INDEX(Detail[],MATCH($A19,Detail[AEA],0),MATCH(D$14,Detail[#Headers],0)) -> 3.61 | E19: =SUMIFS(INDEX(Detail[],0,MATCH(E$14,Detail[#Headers],0)),Detail[AEA],$A19) -> 17350789 | F19: =SUMIFS(INDEX(Detail[],0,MATCH(F$14,Detail[#Headers],0)),Detail[AEA],$A19) -> 103802 | G19: =SUMIFS(INDEX(Detail[],0,MATCH(G$14,Detail[#Headers],0)),Detail[AEA],$A19) -> 17454591 | H19: =SUMIFS(INDEX(Detail[],0,MATCH(H$14,Detail[#Headers],0)),Detail[AEA],$A19) -> 2988923 | I19: =SUMIFS(INDEX(Detail[],0,MATCH(I$14,Detail[#Headers],0)),Detail[AEA],$A19) -> 3266212 | J19: =SUMIFS(INDEX(Detail[],0,MATCH(J$14,Detail[#Headers],0)),Detail[AEA],$A19) -> 0
A20: =A7 -> 10 | B20: =B7 -> Grant Wood AEA 10 | C20: =INDEX(Detail[],MATCH($A20,Detail[AEA],0),MATCH(C$14,Detail[#Headers],0)) -> 31.52 | D20: =INDEX(Detail[],MATCH($A20,Detail[AEA],0),MATCH(D$14,Detail[#Headers],0)) -> 3.67 | E20: =SUMIFS(INDEX(Detail[],0,MATCH(E$14,Detail[#Headers],0)),Detail[AEA],$A20) -> 25932153 | F20: =SUMIFS(INDEX(Detail[],0,MATCH(F$14,Detail[#Headers],0)),Detail[AEA],$A20) -> 80473 | G20: =SUMIFS(INDEX(Detail[],0,MATCH(G$14,Detail[#Headers],0)),Detail[AEA],$A20) -> 26012626 | H20: =SUMIFS(INDEX(Detail[],0,MATCH(H$14,Detail[#Headers],0)),Detail[AEA],$A20) -> 4580882 | I20: =SUMIFS(INDEX(Detail[],0,MATCH(I$14,Detail[#Headers],0)),Detail[AEA],$A20) -> 5035582 | J20: =SUMIFS(INDEX(Detail[],0,MATCH(J$14,Detail[#Headers],0)),Detail[AEA],$A20) -> 30001
A21: =A8 -> 11 | B21: =B8 -> Heartland AEA 11 | C21: =INDEX(Detail[],MATCH($A21,Detail[AEA],0),MATCH(C$14,Detail[#Headers],0)) -> 27.75 | D21: =INDEX(Detail[],MATCH($A21,Detail[AEA],0),MATCH(D$14,Detail[#Headers],0)) -> 3.48 | E21: =SUMIFS(INDEX(Detail[],0,MATCH(E$14,Detail[#Headers],0)),Detail[AEA],$A21) -> 52548033 | F21: =SUMIFS(INDEX(Detail[],0,MATCH(F$14,Detail[#Headers],0)),Detail[AEA],$A21) -> 23368 | G21: =SUMIFS(INDEX(Detail[],0,MATCH(G$14,Detail[#Headers],0)),Detail[AEA],$A21) -> 52571401 | H21: =SUMIFS(INDEX(Detail[],0,MATCH(H$14,Detail[#Headers],0)),Detail[AEA],$A21) -> 9430082 | I21: =SUMIFS(INDEX(Detail[],0,MATCH(I$14,Detail[#Headers],0)),Detail[AEA],$A21) -> 10358799 | J21: =SUMIFS(INDEX(Detail[],0,MATCH(J$14,Detail[#Headers],0)),Detail[AEA],$A21) -> 0
A22: =A9 -> 12 | B22: =B9 -> Northwest AEA | C22: =INDEX(Detail[],MATCH($A22,Detail[AEA],0),MATCH(C$14,Detail[#Headers],0)) -> 34.31 | D22: =INDEX(Detail[],MATCH($A22,Detail[AEA],0),MATCH(D$14,Detail[#Headers],0)) -> 4.09 | E22: =SUMIFS(INDEX(Detail[],0,MATCH(E$14,Detail[#Headers],0)),Detail[AEA],$A22) -> 15581675 | F22: =SUMIFS(INDEX(Detail[],0,MATCH(F$14,Detail[#Headers],0)),Detail[AEA],$A22) -> 31999 | G22: =SUMIFS(INDEX(Detail[],0,MATCH(G$14,Detail[#Headers],0)),Detail[AEA],$A22) -> 15613674 | H22: =SUMIFS(INDEX(Detail[],0,MATCH(H$14,Detail[#Headers],0)),Detail[AEA],$A22) -> 2825990 | I22: =SUMIFS(INDEX(Detail[],0,MATCH(I$14,Detail[#Headers],0)),Detail[AEA],$A22) -> 3164474 | J22: =SUMIFS(INDEX(Detail[],0,MATCH(J$14,Detail[#Headers],0)),Detail[AEA],$A22) -> 30001
A23: =A10 -> 13 | B23: =B10 -> Green Hills AEA 13 | C23: =INDEX(Detail[],MATCH($A23,Detail[AEA],0),MATCH(C$14,Detail[#Headers],0)) -> 34.29 | D23: =INDEX(Detail[],MATCH($A23,Detail[AEA],0),MATCH(D$14,Detail[#Headers],0)) -> 3.7 | E23: =SUMIFS(INDEX(Detail[],0,MATCH(E$14,Detail[#Headers],0)),Detail[AEA],$A23) -> 14310536 | F23: =SUMIFS(INDEX(Detail[],0,MATCH(F$14,Detail[#Headers],0)),Detail[AEA],$A23) -> 49638 | G23: =SUMIFS(INDEX(Detail[],0,MATCH(G$14,Detail[#Headers],0)),Detail[AEA],$A23) -> 14360174 | H23: =SUMIFS(INDEX(Detail[],0,MATCH(H$14,Detail[#Headers],0)),Detail[AEA],$A23) -> 2353258 | I23: =SUMIFS(INDEX(Detail[],0,MATCH(I$14,Detail[#Headers],0)),Detail[AEA],$A23) -> 2601568 | J23: =SUMIFS(INDEX(Detail[],0,MATCH(J$14,Detail[#Headers],0)),Detail[AEA],$A23) -> 30002
A24: =A11 -> 15 | B24: =B11 -> Great Prairie AEA 15 | C24: =INDEX(Detail[],MATCH($A24,Detail[AEA],0),MATCH(C$14,Detail[#Headers],0)) -> 33.3 | D24: =INDEX(Detail[],MATCH($A24,Detail[AEA],0),MATCH(D$14,Detail[#Headers],0)) -> 3.65 | E24: =SUMIFS(INDEX(Detail[],0,MATCH(E$14,Detail[#Headers],0)),Detail[AEA],$A24) -> 12798057 | F24: =SUMIFS(INDEX(Detail[],0,MATCH(F$14,Detail[#Headers],0)),Detail[AEA],$A24) -> 84859 | G24: =SUMIFS(INDEX(Detail[],0,MATCH(G$14,Detail[#Headers],0)),Detail[AEA],$A24) -> 12882916 | H24: =SUMIFS(INDEX(Detail[],0,MATCH(H$14,Detail[#Headers],0)),Detail[AEA],$A24) -> 2175147 | I24: =SUMIFS(INDEX(Detail[],0,MATCH(I$14,Detail[#Headers],0)),Detail[AEA],$A24) -> 2390777 | J24: =SUMIFS(INDEX(Detail[],0,MATCH(J$14,Detail[#Headers],0)),Detail[AEA],$A24) -> 30000
E25: =SUM(E16:E24) -> 185285026 | F25: =SUM(F16:F24) -> 578940 | G25: =SUM(G16:G24) -> 185863966 | H25: =SUM(H16:H24) -> 32345038 | I25: =SUM(I16:I24) -> 35735170 | J25: =SUM(J16:J24) -> 180006
C27: =Detail[[#Headers],[AEA Teacher Salary Supplement District Cost]] -> AEA Teacher Salary Supplement District Cost | D27: =Detail[[#Headers],[AEA Professional Development Supplement District Cost]] -> AEA Professional Development Supplement District Cost | E27: =Detail[[#Headers],[Subtotal Budget]] -> Subtotal Budget | F27: =Detail[[#Headers],[AEA Statewide State Aid Reduction]] -> AEA Statewide State Aid Reduction | G27: =Detail[[#Headers],[Total Budget]] -> Total Budget | H27: =Detail[[#Headers],[State Aid Portion]] -> State Aid Portion | I27: =Detail[[#Headers],[Property Tax Portion]] -> Property Tax Portion
A28: =A15 -> AEA | B28: =B15 -> AEA Name | C28: Teacher Salary Supplement | D28: Professional Development Supplement | E28: Subtotal Budget | F28: Prorata Reduction | G28: Total Budget | H28: State Aid | I28: Property Tax
A29: =A16 -> 01 | B29: =B16 -> Keystone AEA 1 | C29: =SUMIFS(INDEX(Detail[],0,MATCH(C$27,Detail[#Headers],0)),Detail[AEA],$A29) -> 1110571 | D29: =SUMIFS(INDEX(Detail[],0,MATCH(D$27,Detail[#Headers],0)),Detail[AEA],$A29) -> 120492 | E29: =SUMIFS(INDEX(Detail[],0,MATCH(E$27,Detail[#Headers],0)),Detail[AEA],$A29) -> 16651097 | F29: =SUMIFS(INDEX(Detail[],0,MATCH(F$27,Detail[#Headers],0)),Detail[AEA],$A29) -> 2094923 | G29: =SUMIFS(INDEX(Detail[],0,MATCH(G$27,Detail[#Headers],0)),Detail[AEA],$A29) -> 14556174 | H29: =SUMIFS(INDEX(Detail[],0,MATCH(H$27,Detail[#Headers],0)),Detail[AEA],$A29) -> 7664312 | I29: =SUMIFS(INDEX(Detail[],0,MATCH(I$27,Detail[#Headers],0)),Detail[AEA],$A29) -> 6891862
A30: =A17 -> 05 | B30: =B17 -> Prairie Lakes AEA 8 | C30: =SUMIFS(INDEX(Detail[],0,MATCH(C$27,Detail[#Headers],0)),Detail[AEA],$A30) -> 1244494 | D30: =SUMIFS(INDEX(Detail[],0,MATCH(D$27,Detail[#Headers],0)),Detail[AEA],$A30) -> 147912 | E30: =SUMIFS(INDEX(Detail[],0,MATCH(E$27,Detail[#Headers],0)),Detail[AEA],$A30) -> 17439883 | F30: =SUMIFS(INDEX(Detail[],0,MATCH(F$27,Detail[#Headers],0)),Detail[AEA],$A30) -> 2227501 | G30: =SUMIFS(INDEX(Detail[],0,MATCH(G$27,Detail[#Headers],0)),Detail[AEA],$A30) -> 15212382 | H30: =SUMIFS(INDEX(Detail[],0,MATCH(H$27,Detail[#Headers],0)),Detail[AEA],$A30) -> 8172796 | I30: =SUMIFS(INDEX(Detail[],0,MATCH(I$27,Detail[#Headers],0)),Detail[AEA],$A30) -> 7039586
A31: =A18 -> 07 | B31: =B18 -> Central Rivers | C31: =SUMIFS(INDEX(Detail[],0,MATCH(C$27,Detail[#Headers],0)),Detail[AEA],$A31) -> 2947977 | D31: =SUMIFS(INDEX(Detail[],0,MATCH(D$27,Detail[#Headers],0)),Detail[AEA],$A31) -> 339319 | E31: =SUMIFS(INDEX(Detail[],0,MATCH(E$27,Detail[#Headers],0)),Detail[AEA],$A31) -> 35756885 | F31: =SUMIFS(INDEX(Detail[],0,MATCH(F$27,Detail[#Headers],0)),Detail[AEA],$A31) -> 4134155 | G31: =SUMIFS(INDEX(Detail[],0,MATCH(G$27,Detail[#Headers],0)),Detail[AEA],$A31) -> 31622730 | H31: =SUMIFS(INDEX(Detail[],0,MATCH(H$27,Detail[#Headers],0)),Detail[AEA],$A31) -> 17817550 | I31: =SUMIFS(INDEX(Detail[],0,MATCH(I$27,Detail[#Headers],0)),Detail[AEA],$A31) -> 13805180
A32: =A19 -> 09 | B32: =B19 -> Mississippi Bend AEA 9 | C32: =SUMIFS(INDEX(Detail[],0,MATCH(C$27,Detail[#Headers],0)),Detail[AEA],$A32) -> 1594669 | D32: =SUMIFS(INDEX(Detail[],0,MATCH(D$27,Detail[#Headers],0)),Detail[AEA],$A32) -> 187087 | E32: =SUMIFS(INDEX(Detail[],0,MATCH(E$27,Detail[#Headers],0)),Detail[AEA],$A32) -> 25491482 | F32: =SUMIFS(INDEX(Detail[],0,MATCH(F$27,Detail[#Headers],0)),Detail[AEA],$A32) -> 3008239 | G32: =SUMIFS(INDEX(Detail[],0,MATCH(G$27,Detail[#Headers],0)),Detail[AEA],$A32) -> 22483243 | H32: =SUMIFS(INDEX(Detail[],0,MATCH(H$27,Detail[#Headers],0)),Detail[AEA],$A32) -> 12451056 | I32: =SUMIFS(INDEX(Detail[],0,MATCH(I$27,Detail[#Headers],0)),Detail[AEA],$A32) -> 10032187
A33: =A20 -> 10 | B33: =B20 -> Grant Wood AEA 10 | C33: =SUMIFS(INDEX(Detail[],0,MATCH(C$27,Detail[#Headers],0)),Detail[AEA],$A33) -> 2456867 | D33: =SUMIFS(INDEX(Detail[],0,MATCH(D$27,Detail[#Headers],0)),Detail[AEA],$A33) -> 286050 | E33: =SUMIFS(INDEX(Detail[],0,MATCH(E$27,Detail[#Headers],0)),Detail[AEA],$A33) -> 38402008 | F33: =SUMIFS(INDEX(Detail[],0,MATCH(F$27,Detail[#Headers],0)),Detail[AEA],$A33) -> 3820494 | G33: =SUMIFS(INDEX(Detail[],0,MATCH(G$27,Detail[#Headers],0)),Detail[AEA],$A33) -> 34581514 | H33: =SUMIFS(INDEX(Detail[],0,MATCH(H$27,Detail[#Headers],0)),Detail[AEA],$A33) -> 19506268 | I33: =SUMIFS(INDEX(Detail[],0,MATCH(I$27,Detail[#Headers],0)),Detail[AEA],$A33) -> 15075246
A34: =A21 -> 11 | B34: =B21 -> Heartland AEA 11 | C34: =SUMIFS(INDEX(Detail[],0,MATCH(C$27,Detail[#Headers],0)),Detail[AEA],$A34) -> 4475270 | D34: =SUMIFS(INDEX(Detail[],0,MATCH(D$27,Detail[#Headers],0)),Detail[AEA],$A34) -> 561231 | E34: =SUMIFS(INDEX(Detail[],0,MATCH(E$27,Detail[#Headers],0)),Detail[AEA],$A34) -> 77396783 | F34: =SUMIFS(INDEX(Detail[],0,MATCH(F$27,Detail[#Headers],0)),Detail[AEA],$A34) -> 6768337 | G34: =SUMIFS(INDEX(Detail[],0,MATCH(G$27,Detail[#Headers],0)),Detail[AEA],$A34) -> 70628446 | H34: =SUMIFS(INDEX(Detail[],0,MATCH(H$27,Detail[#Headers],0)),Detail[AEA],$A34) -> 40838071 | I34: =SUMIFS(INDEX(Detail[],0,MATCH(I$27,Detail[#Headers],0)),Detail[AEA],$A34) -> 29790375
A35: =A22 -> 12 | B35: =B22 -> Northwest AEA | C35: =SUMIFS(INDEX(Detail[],0,MATCH(C$27,Detail[#Headers],0)),Detail[AEA],$A35) -> 1570341 | D35: =SUMIFS(INDEX(Detail[],0,MATCH(D$27,Detail[#Headers],0)),Detail[AEA],$A35) -> 187192 | E35: =SUMIFS(INDEX(Detail[],0,MATCH(E$27,Detail[#Headers],0)),Detail[AEA],$A35) -> 23391672 | F35: =SUMIFS(INDEX(Detail[],0,MATCH(F$27,Detail[#Headers],0)),Detail[AEA],$A35) -> 2531689 | G35: =SUMIFS(INDEX(Detail[],0,MATCH(G$27,Detail[#Headers],0)),Detail[AEA],$A35) -> 20859983 | H35: =SUMIFS(INDEX(Detail[],0,MATCH(H$27,Detail[#Headers],0)),Detail[AEA],$A35) -> 11329342 | I35: =SUMIFS(INDEX(Detail[],0,MATCH(I$27,Detail[#Headers],0)),Detail[AEA],$A35) -> 9530641
A36: =A23 -> 13 | B36: =B23 -> Green Hills AEA 13 | C36: =SUMIFS(INDEX(Detail[],0,MATCH(C$27,Detail[#Headers],0)),Detail[AEA],$A36) -> 1471486 | D36: =SUMIFS(INDEX(Detail[],0,MATCH(D$27,Detail[#Headers],0)),Detail[AEA],$A36) -> 158737 | E36: =SUMIFS(INDEX(Detail[],0,MATCH(E$27,Detail[#Headers],0)),Detail[AEA],$A36) -> 20975225 | F36: =SUMIFS(INDEX(Detail[],0,MATCH(F$27,Detail[#Headers],0)),Detail[AEA],$A36) -> 2572196 | G36: =SUMIFS(INDEX(Detail[],0,MATCH(G$27,Detail[#Headers],0)),Detail[AEA],$A36) -> 18403029 | H36: =SUMIFS(INDEX(Detail[],0,MATCH(H$27,Detail[#Headers],0)),Detail[AEA],$A36) -> 10395097 | I36: =SUMIFS(INDEX(Detail[],0,MATCH(I$27,Detail[#Headers],0)),Detail[AEA],$A36) -> 8007932
A37: =A24 -> 15 | B37: =B24 -> Great Prairie AEA 15 | C37: =SUMIFS(INDEX(Detail[],0,MATCH(C$27,Detail[#Headers],0)),Detail[AEA],$A37) -> 1289025 | D37: =SUMIFS(INDEX(Detail[],0,MATCH(D$27,Detail[#Headers],0)),Detail[AEA],$A37) -> 141245 | E37: =SUMIFS(INDEX(Detail[],0,MATCH(E$27,Detail[#Headers],0)),Detail[AEA],$A37) -> 18909110 | F37: =SUMIFS(INDEX(Detail[],0,MATCH(F$27,Detail[#Headers],0)),Detail[AEA],$A37) -> 2399597 | G37: =SUMIFS(INDEX(Detail[],0,MATCH(G$27,Detail[#Headers],0)),Detail[AEA],$A37) -> 16509513 | H37: =SUMIFS(INDEX(Detail[],0,MATCH(H$27,Detail[#Headers],0)),Detail[AEA],$A37) -> 9252847 | I37: =SUMIFS(INDEX(Detail[],0,MATCH(I$27,Detail[#Headers],0)),Detail[AEA],$A37) -> 7256666
C38: =SUM(C29:C37) -> 18160700 | D38: =SUM(D29:D37) -> 2129265 | E38: =SUM(E29:E37) -> 274414145 | F38: =SUM(F29:F37) -> 29557131 | G38: =SUM(G29:G37) -> 244857014 | H38: =SUM(H29:H37) -> 137427339 | I38: =SUM(I29:I37) -> 107429675

Sheet StateAidVsPropertyTax
A1: AEA | B1: AEA Name | C1: =Breakdown[[#Headers],[AEA Special Ed Support District Cost Formula Generated]] -> AEA Special Ed Support District Cost Formula Generated | D1: =Breakdown[[#Headers],[State Aid Portion Special Ed]] -> State Aid Portion Special Ed | E1: =Breakdown[[#Headers],[AEA Statewide State Aid Reduction]] -> AEA Statewide State Aid Reduction | F1: =Breakdown[[#Headers],[State Aid Special Ed Minus Reduction]] -> State Aid Special Ed Minus Reduction | G1: =Breakdown[[#Headers],[Special Education Property Tax Portion]] -> Special Education Property Tax Portion | H1: =Breakdown[[#Headers],[AEA Special Ed Support Adjustment]] -> AEA Special Ed Support Adjustment | I1: =Breakdown[[#Headers],[Total Special Ed Funding Removing Reduction Including Adjustment]] -> Total Special Ed Funding Removing Reduction Including Adjustment
A2: {=IFERROR(INDEX(Detail[AEA], MATCH(0,COUNTIF(StateAidVsPropertyTax!$A$1:'StateAidVsPropertyTax'!A1, Detail[AEA]), 0)),"")} -> 01 | B2: =INDEX(Detail[],MATCH(StateAidVsPropertyTax!$A2,Detail[AEA],0),2) -> Keystone AEA 1 | C2: =SUMIFS(INDEX(Breakdown[],0,MATCH(C$1,Breakdown[#Headers],0)),Breakdown[AEA],$A2) -> 11216201 | D2: =SUMIFS(INDEX(Breakdown[],0,MATCH(D$1,Breakdown[#Headers],0)),Breakdown[AEA],$A2) -> 8505423 | E2: =SUMIFS(INDEX(Breakdown[],0,MATCH(E$1,Breakdown[#Headers],0)),Breakdown[AEA],$A2) -> 2094923 | F2: =SUMIFS(INDEX(Breakdown[],0,MATCH(F$1,Breakdown[#Headers],0)),Breakdown[AEA],$A2) -> 6410500 | G2: =SUMIFS(INDEX(Breakdown[],0,MATCH(G$1,Breakdown[#Headers],0)),Breakdown[AEA],$A2) -> 2710778 | H2: =SUMIFS(INDEX(Breakdown[],0,MATCH(H$1,Breakdown[#Headers],0)),Breakdown[AEA],$A2) -> 10552 | I2: =SUMIFS(INDEX(Breakdown[],0,MATCH(I$1,Breakdown[#Headers],0)),Breakdown[AEA],$A2) -> 9131830 | P2: =G11+D23+H11+C35+D35-G35 -> -15
A3: {=IFERROR(INDEX(Detail[AEA], MATCH(0,COUNTIF(StateAidVsPropertyTax!$A$1:'StateAidVsPropertyTax'!A2, Detail[AEA]), 0)),"")} -> 05 | B3: =INDEX(Detail[],MATCH(StateAidVsPropertyTax!$A3,Detail[AEA],0),2) -> Prairie Lakes AEA 8 | C3: =SUMIFS(INDEX(Breakdown[],0,MATCH(C$1,Breakdown[#Headers],0)),Breakdown[AEA],$A3) -> 11733799 | D3: =SUMIFS(INDEX(Breakdown[],0,MATCH(D$1,Breakdown[#Headers],0)),Breakdown[AEA],$A3) -> 9007891 | E3: =SUMIFS(INDEX(Breakdown[],0,MATCH(E$1,Breakdown[#Headers],0)),Breakdown[AEA],$A3) -> 2227501 | F3: =SUMIFS(INDEX(Breakdown[],0,MATCH(F$1,Breakdown[#Headers],0)),Breakdown[AEA],$A3) -> 6780390 | G3: =SUMIFS(INDEX(Breakdown[],0,MATCH(G$1,Breakdown[#Headers],0)),Breakdown[AEA],$A3) -> 2725908 | H3: =SUMIFS(INDEX(Breakdown[],0,MATCH(H$1,Breakdown[#Headers],0)),Breakdown[AEA],$A3) -> 73537 | I3: =SUMIFS(INDEX(Breakdown[],0,MATCH(I$1,Breakdown[#Headers],0)),Breakdown[AEA],$A3) -> 9579835 | P3: =F11+C23+F23+G23-F35 -> 15
A4: {=IFERROR(INDEX(Detail[AEA], MATCH(0,COUNTIF(StateAidVsPropertyTax!$A$1:'StateAidVsPropertyTax'!A3, Detail[AEA]), 0)),"")} -> 07 | B4: =INDEX(Detail[],MATCH(StateAidVsPropertyTax!$A4,Detail[AEA],0),2) -> Central Rivers | C4: =SUMIFS(INDEX(Breakdown[],0,MATCH(C$1,Breakdown[#Headers],0)),Breakdown[AEA],$A4) -> 23813783 | D4: =SUMIFS(INDEX(Breakdown[],0,MATCH(D$1,Breakdown[#Headers],0)),Breakdown[AEA],$A4) -> 18640929 | E4: =SUMIFS(INDEX(Breakdown[],0,MATCH(E$1,Breakdown[#Headers],0)),Breakdown[AEA],$A4) -> 4134155 | F4: =SUMIFS(INDEX(Breakdown[],0,MATCH(F$1,Breakdown[#Headers],0)),Breakdown[AEA],$A4) -> 14506774 | G4: =SUMIFS(INDEX(Breakdown[],0,MATCH(G$1,Breakdown[#Headers],0)),Breakdown[AEA],$A4) -> 5172854 | H4: =SUMIFS(INDEX(Breakdown[],0,MATCH(H$1,Breakdown[#Headers],0)),Breakdown[AEA],$A4) -> 120712 | I4: =SUMIFS(INDEX(Breakdown[],0,MATCH(I$1,Breakdown[#Headers],0)),Breakdown[AEA],$A4) -> 19800340
A5: {=IFERROR(INDEX(Detail[AEA], MATCH(0,COUNTIF(StateAidVsPropertyTax!$A$1:'StateAidVsPropertyTax'!A4, Detail[AEA]), 0)),"")} -> 09 | B5: =INDEX(Detail[],MATCH(StateAidVsPropertyTax!$A5,Detail[AEA],0),2) -> Mississippi Bend AEA 9 | C5: =SUMIFS(INDEX(Breakdown[],0,MATCH(C$1,Breakdown[#Headers],0)),Breakdown[AEA],$A5) -> 17350789 | D5: =SUMIFS(INDEX(Breakdown[],0,MATCH(D$1,Breakdown[#Headers],0)),Breakdown[AEA],$A5) -> 13677539 | E5: =SUMIFS(INDEX(Breakdown[],0,MATCH(E$1,Breakdown[#Headers],0)),Breakdown[AEA],$A5) -> 3008239 | F5: =SUMIFS(INDEX(Breakdown[],0,MATCH(F$1,Breakdown[#Headers],0)),Breakdown[AEA],$A5) -> 10669300 | G5: =SUMIFS(INDEX(Breakdown[],0,MATCH(G$1,Breakdown[#Headers],0)),Breakdown[AEA],$A5) -> 3673250 | H5: =SUMIFS(INDEX(Breakdown[],0,MATCH(H$1,Breakdown[#Headers],0)),Breakdown[AEA],$A5) -> 103802 | I5: =SUMIFS(INDEX(Breakdown[],0,MATCH(I$1,Breakdown[#Headers],0)),Breakdown[AEA],$A5) -> 14446352
A6: {=IFERROR(INDEX(Detail[AEA], MATCH(0,COUNTIF(StateAidVsPropertyTax!$A$1:'StateAidVsPropertyTax'!A5, Detail[AEA]), 0)),"")} -> 10 | B6: =INDEX(Detail[],MATCH(StateAidVsPropertyTax!$A6,Detail[AEA],0),2) -> Grant Wood AEA 10 | C6: =SUMIFS(INDEX(Breakdown[],0,MATCH(C$1,Breakdown[#Headers],0)),Breakdown[AEA],$A6) -> 25932153 | D6: =SUMIFS(INDEX(Breakdown[],0,MATCH(D$1,Breakdown[#Headers],0)),Breakdown[AEA],$A6) -> 20560060 | E6: =SUMIFS(INDEX(Breakdown[],0,MATCH(E$1,Breakdown[#Headers],0)),Breakdown[AEA],$A6) -> 3820494 | F6: =SUMIFS(INDEX(Breakdown[],0,MATCH(F$1,Breakdown[#Headers],0)),Breakdown[AEA],$A6) -> 16739566 | G6: =SUMIFS(INDEX(Breakdown[],0,MATCH(G$1,Breakdown[#Headers],0)),Breakdown[AEA],$A6) -> 5372093 | H6: =SUMIFS(INDEX(Breakdown[],0,MATCH(H$1,Breakdown[#Headers],0)),Breakdown[AEA],$A6) -> 80473 | I6: =SUMIFS(INDEX(Breakdown[],0,MATCH(I$1,Breakdown[#Headers],0)),Breakdown[AEA],$A6) -> 22192132
A7: {=IFERROR(INDEX(Detail[AEA], MATCH(0,COUNTIF(StateAidVsPropertyTax!$A$1:'StateAidVsPropertyTax'!A6, Detail[AEA]), 0)),"")} -> 11 | B7: =INDEX(Detail[],MATCH(StateAidVsPropertyTax!$A7,Detail[AEA],0),2) -> Heartland AEA 11 | C7: =SUMIFS(INDEX(Breakdown[],0,MATCH(C$1,Breakdown[#Headers],0)),Breakdown[AEA],$A7) -> 52548033 | D7: =SUMIFS(INDEX(Breakdown[],0,MATCH(D$1,Breakdown[#Headers],0)),Breakdown[AEA],$A7) -> 42569907 | E7: =SUMIFS(INDEX(Breakdown[],0,MATCH(E$1,Breakdown[#Headers],0)),Breakdown[AEA],$A7) -> 6768337 | F7: =SUMIFS(INDEX(Breakdown[],0,MATCH(F$1,Breakdown[#Headers],0)),Breakdown[AEA],$A7) -> 35801570 | G7: =SUMIFS(INDEX(Breakdown[],0,MATCH(G$1,Breakdown[#Headers],0)),Breakdown[AEA],$A7) -> 9978126 | H7: =SUMIFS(INDEX(Breakdown[],0,MATCH(H$1,Breakdown[#Headers],0)),Breakdown[AEA],$A7) -> 23368 | I7: =SUMIFS(INDEX(Breakdown[],0,MATCH(I$1,Breakdown[#Headers],0)),Breakdown[AEA],$A7) -> 45803064
A8: {=IFERROR(INDEX(Detail[AEA], MATCH(0,COUNTIF(StateAidVsPropertyTax!$A$1:'StateAidVsPropertyTax'!A7, Detail[AEA]), 0)),"")} -> 12 | B8: =INDEX(Detail[],MATCH(StateAidVsPropertyTax!$A8,Detail[AEA],0),2) -> Northwest AEA | C8: =SUMIFS(INDEX(Breakdown[],0,MATCH(C$1,Breakdown[#Headers],0)),Breakdown[AEA],$A8) -> 15581675 | D8: =SUMIFS(INDEX(Breakdown[],0,MATCH(D$1,Breakdown[#Headers],0)),Breakdown[AEA],$A8) -> 12080239 | E8: =SUMIFS(INDEX(Breakdown[],0,MATCH(E$1,Breakdown[#Headers],0)),Breakdown[AEA],$A8) -> 2531689 | F8: =SUMIFS(INDEX(Breakdown[],0,MATCH(F$1,Breakdown[#Headers],0)),Breakdown[AEA],$A8) -> 9548550 | G8: =SUMIFS(INDEX(Breakdown[],0,MATCH(G$1,Breakdown[#Headers],0)),Breakdown[AEA],$A8) -> 3501436 | H8: =SUMIFS(INDEX(Breakdown[],0,MATCH(H$1,Breakdown[#Headers],0)),Breakdown[AEA],$A8) -> 31999 | I8: =SUMIFS(INDEX(Breakdown[],0,MATCH(I$1,Breakdown[#Headers],0)),Breakdown[AEA],$A8) -> 13081985
A9: {=IFERROR(INDEX(Detail[AEA], MATCH(0,COUNTIF(StateAidVsPropertyTax!$A$1:'StateAidVsPropertyTax'!A8, Detail[AEA]), 0)),"")} -> 13 | B9: =INDEX(Detail[],MATCH(StateAidVsPropertyTax!$A9,Detail[AEA],0),2) -> Green Hills AEA 13 | C9: =SUMIFS(INDEX(Breakdown[],0,MATCH(C$1,Breakdown[#Headers],0)),Breakdown[AEA],$A9) -> 14310536 | D9: =SUMIFS(INDEX(Breakdown[],0,MATCH(D$1,Breakdown[#Headers],0)),Breakdown[AEA],$A9) -> 11313351 | E9: =SUMIFS(INDEX(Breakdown[],0,MATCH(E$1,Breakdown[#Headers],0)),Breakdown[AEA],$A9) -> 2572196 | F9: =SUMIFS(INDEX(Breakdown[],0,MATCH(F$1,Breakdown[#Headers],0)),Breakdown[AEA],$A9) -> 8741155 | G9: =SUMIFS(INDEX(Breakdown[],0,MATCH(G$1,Breakdown[#Headers],0)),Breakdown[AEA],$A9) -> 2997185 | H9: =SUMIFS(INDEX(Breakdown[],0,MATCH(H$1,Breakdown[#Headers],0)),Breakdown[AEA],$A9) -> 49638 | I9: =SUMIFS(INDEX(Breakdown[],0,MATCH(I$1,Breakdown[#Headers],0)),Breakdown[AEA],$A9) -> 11787978
A10: {=IFERROR(INDEX(Detail[AEA], MATCH(0,COUNTIF(StateAidVsPropertyTax!$A$1:'StateAidVsPropertyTax'!A9, Detail[AEA]), 0)),"")} -> 15 | B10: =INDEX(Detail[],MATCH(StateAidVsPropertyTax!$A10,Detail[AEA],0),2) -> Great Prairie AEA 15 | C10: =SUMIFS(INDEX(Breakdown[],0,MATCH(C$1,Breakdown[#Headers],0)),Breakdown[AEA],$A10) -> 12798057 | D10: =SUMIFS(INDEX(Breakdown[],0,MATCH(D$1,Breakdown[#Headers],0)),Breakdown[AEA],$A10) -> 10198273 | E10: =SUMIFS(INDEX(Breakdown[],0,MATCH(E$1,Breakdown[#Headers],0)),Breakdown[AEA],$A10) -> 2399597 | F10: =SUMIFS(INDEX(Breakdown[],0,MATCH(F$1,Breakdown[#Headers],0)),Breakdown[AEA],$A10) -> 7798676 | G10: =SUMIFS(INDEX(Breakdown[],0,MATCH(G$1,Breakdown[#Headers],0)),Breakdown[AEA],$A10) -> 2599784 | H10: =SUMIFS(INDEX(Breakdown[],0,MATCH(H$1,Breakdown[#Headers],0)),Breakdown[AEA],$A10) -> 84859 | I10: =SUMIFS(INDEX(Breakdown[],0,MATCH(I$1,Breakdown[#Headers],0)),Breakdown[AEA],$A10) -> 10483319
C11: =SUM(C2:C10) -> 185285026 | D11: =SUM(D2:D10) -> 146553612 | E11: =SUM(E2:E10) -> 29557131 | F11: =SUM(F2:F10) -> 116996481 | G11: =SUM(G2:G10) -> 38731414 | H11: =SUM(H2:H10) -> 578940 | I11: =SUM(I2:I10) -> 156306835
A13: =A1 -> AEA | B13: =B1 -> AEA Name | C13: =Breakdown[[#Headers],[State Aid Portion Sharing Operations]] -> State Aid Portion Sharing Operations | D13: =Breakdown[[#Headers],[Sharing Operations Property Tax]] -> Sharing Operations Property Tax | E13: =Breakdown[[#Headers],[Total AEA Sharing Operations]] -> Total AEA Sharing Operations | F13: =Breakdown[[#Headers],[AEA Teacher Salary Supplement District Cost]] -> AEA Teacher Salary Supplement District Cost | G13: =Breakdown[[#Headers],[AEA Professional Development Supplement District Cost]] -> AEA Professional Development Supplement District Cost
A14: =A2 -> 01 | B14: =B2 -> Keystone AEA 1 | C14: =SUMIFS(INDEX(Breakdown[],0,MATCH(C$13,Breakdown[#Headers],0)),Breakdown[AEA],$A14) -> 22751 | D14: =SUMIFS(INDEX(Breakdown[],0,MATCH(D$13,Breakdown[#Headers],0)),Breakdown[AEA],$A14) -> 7250 | E14: =SUMIFS(INDEX(Breakdown[],0,MATCH(E$13,Breakdown[#Headers],0)),Breakdown[AEA],$A14) -> 30001 | F14: =SUMIFS(INDEX(Breakdown[],0,MATCH(F$13,Breakdown[#Headers],0)),Breakdown[AEA],$A14) -> 1110571 | G14: =SUMIFS(INDEX(Breakdown[],0,MATCH(G$13,Breakdown[#Headers],0)),Breakdown[AEA],$A14) -> 120492
A15: =A3 -> 05 | B15: =B3 -> Prairie Lakes AEA 8 | C15: =SUMIFS(INDEX(Breakdown[],0,MATCH(C$13,Breakdown[#Headers],0)),Breakdown[AEA],$A15) -> 0 | D15: =SUMIFS(INDEX(Breakdown[],0,MATCH(D$13,Breakdown[#Headers],0)),Breakdown[AEA],$A15) -> 0 | E15: =SUMIFS(INDEX(Breakdown[],0,MATCH(E$13,Breakdown[#Headers],0)),Breakdown[AEA],$A15) -> 0 | F15: =SUMIFS(INDEX(Breakdown[],0,MATCH(F$13,Breakdown[#Headers],0)),Breakdown[AEA],$A15) -> 1244494 | G15: =SUMIFS(INDEX(Breakdown[],0,MATCH(G$13,Breakdown[#Headers],0)),Breakdown[AEA],$A15) -> 147912 | H15: State Aid Portion
A16: =A4 -> 07 | B16: =B4 -> Central Rivers | C16: =SUMIFS(INDEX(Breakdown[],0,MATCH(C$13,Breakdown[#Headers],0)),Breakdown[AEA],$A16) -> 23483 | D16: =SUMIFS(INDEX(Breakdown[],0,MATCH(D$13,Breakdown[#Headers],0)),Breakdown[AEA],$A16) -> 6518 | E16: =SUMIFS(INDEX(Breakdown[],0,MATCH(E$13,Breakdown[#Headers],0)),Breakdown[AEA],$A16) -> 30001 | F16: =SUMIFS(INDEX(Breakdown[],0,MATCH(F$13,Breakdown[#Headers],0)),Breakdown[AEA],$A16) -> 2947977 | G16: =SUMIFS(INDEX(Breakdown[],0,MATCH(G$13,Breakdown[#Headers],0)),Breakdown[AEA],$A16) -> 339319
A17: =A5 -> 09 | B17: =B5 -> Mississippi Bend AEA 9 | C17: =SUMIFS(INDEX(Breakdown[],0,MATCH(C$13,Breakdown[#Headers],0)),Breakdown[AEA],$A17) -> 0 | D17: =SUMIFS(INDEX(Breakdown[],0,MATCH(D$13,Breakdown[#Headers],0)),Breakdown[AEA],$A17) -> 0 | E17: =SUMIFS(INDEX(Breakdown[],0,MATCH(E$13,Breakdown[#Headers],0)),Breakdown[AEA],$A17) -> 0 | F17: =SUMIFS(INDEX(Breakdown[],0,MATCH(F$13,Breakdown[#Headers],0)),Breakdown[AEA],$A17) -> 1594669 | G17: =SUMIFS(INDEX(Breakdown[],0,MATCH(G$13,Breakdown[#Headers],0)),Breakdown[AEA],$A17) -> 187087 | H17: Propery Tax Portion
A18: =A6 -> 10 | B18: =B6 -> Grant Wood AEA 10 | C18: =SUMIFS(INDEX(Breakdown[],0,MATCH(C$13,Breakdown[#Headers],0)),Breakdown[AEA],$A18) -> 23788 | D18: =SUMIFS(INDEX(Breakdown[],0,MATCH(D$13,Breakdown[#Headers],0)),Breakdown[AEA],$A18) -> 6213 | E18: =SUMIFS(INDEX(Breakdown[],0,MATCH(E$13,Breakdown[#Headers],0)),Breakdown[AEA],$A18) -> 30001 | F18: =SUMIFS(INDEX(Breakdown[],0,MATCH(F$13,Breakdown[#Headers],0)),Breakdown[AEA],$A18) -> 2456867 | G18: =SUMIFS(INDEX(Breakdown[],0,MATCH(G$13,Breakdown[#Headers],0)),Breakdown[AEA],$A18) -> 286050
A19: =A7 -> 11 | B19: =B7 -> Heartland AEA 11 | C19: =SUMIFS(INDEX(Breakdown[],0,MATCH(C$13,Breakdown[#Headers],0)),Breakdown[AEA],$A19) -> 0 | D19: =SUMIFS(INDEX(Breakdown[],0,MATCH(D$13,Breakdown[#Headers],0)),Breakdown[AEA],$A19) -> 0 | E19: =SUMIFS(INDEX(Breakdown[],0,MATCH(E$13,Breakdown[#Headers],0)),Breakdown[AEA],$A19) -> 0 | F19: =SUMIFS(INDEX(Breakdown[],0,MATCH(F$13,Breakdown[#Headers],0)),Breakdown[AEA],$A19) -> 4475270 | G19: =SUMIFS(INDEX(Breakdown[],0,MATCH(G$13,Breakdown[#Headers],0)),Breakdown[AEA],$A19) -> 561231
A20: =A8 -> 12 | B20: =B8 -> Northwest AEA | C20: =SUMIFS(INDEX(Breakdown[],0,MATCH(C$13,Breakdown[#Headers],0)),Breakdown[AEA],$A20) -> 23261 | D20: =SUMIFS(INDEX(Breakdown[],0,MATCH(D$13,Breakdown[#Headers],0)),Breakdown[AEA],$A20) -> 6740 | E20: =SUMIFS(INDEX(Breakdown[],0,MATCH(E$13,Breakdown[#Headers],0)),Breakdown[AEA],$A20) -> 30001 | F20: =SUMIFS(INDEX(Breakdown[],0,MATCH(F$13,Breakdown[#Headers],0)),Breakdown[AEA],$A20) -> 1570341 | G20: =SUMIFS(INDEX(Breakdown[],0,MATCH(G$13,Breakdown[#Headers],0)),Breakdown[AEA],$A20) -> 187192
A21: =A9 -> 13 | B21: =B9 -> Green Hills AEA 13 | C21: =SUMIFS(INDEX(Breakdown[],0,MATCH(C$13,Breakdown[#Headers],0)),Breakdown[AEA],$A21) -> 23720 | D21: =SUMIFS(INDEX(Breakdown[],0,MATCH(D$13,Breakdown[#Headers],0)),Breakdown[AEA],$A21) -> 6282 | E21: =SUMIFS(INDEX(Breakdown[],0,MATCH(E$13,Breakdown[#Headers],0)),Breakdown[AEA],$A21) -> 30002 | F21: =SUMIFS(INDEX(Breakdown[],0,MATCH(F$13,Breakdown[#Headers],0)),Breakdown[AEA],$A21) -> 1471486 | G21: =SUMIFS(INDEX(Breakdown[],0,MATCH(G$13,Breakdown[#Headers],0)),Breakdown[AEA],$A21) -> 158737
A22: =A10 -> 15 | B22: =B10 -> Great Prairie AEA 15 | C22: =SUMIFS(INDEX(Breakdown[],0,MATCH(C$13,Breakdown[#Headers],0)),Breakdown[AEA],$A22) -> 23905 | D22: =SUMIFS(INDEX(Breakdown[],0,MATCH(D$13,Breakdown[#Headers],0)),Breakdown[AEA],$A22) -> 6095 | E22: =SUMIFS(INDEX(Breakdown[],0,MATCH(E$13,Breakdown[#Headers],0)),Breakdown[AEA],$A22) -> 30000 | F22: =SUMIFS(INDEX(Breakdown[],0,MATCH(F$13,Breakdown[#Headers],0)),Breakdown[AEA],$A22) -> 1289025 | G22: =SUMIFS(INDEX(Breakdown[],0,MATCH(G$13,Breakdown[#Headers],0)),Breakdown[AEA],$A22) -> 141245
C23: =SUM(C14:C22) -> 140908 | D23: =SUM(D14:D22) -> 39098 | E23: =SUM(E14:E22) -> 180006 | F23: =SUM(F14:F22) -> 18160700 | G23: =SUM(G14:G22) -> 2129265
A25: =A13 -> AEA | B25: =B13 -> AEA Name | C25: =Breakdown[[#Headers],[AEA Media Services District Cost]] -> AEA Media Services District Cost | D25: =Breakdown[[#Headers],[AEA Ed Services District Cost]] -> AEA Ed Services District Cost | E25: =Breakdown[[#Headers],[Total Budget]] -> Total Budget | F25: =Breakdown[[#Headers],[State Aid Portion]] -> State Aid Portion | G25: =Breakdown[[#Headers],[Property Tax Portion]] -> Property Tax Portion
A26: =A14 -> 01 | B26: =B14 -> Keystone AEA 1 | C26: =SUMIFS(INDEX(Breakdown[],0,MATCH(C$25,Breakdown[#Headers],0)),Breakdown[AEA],$A26) -> 1969358 | D26: =SUMIFS(INDEX(Breakdown[],0,MATCH(D$25,Breakdown[#Headers],0)),Breakdown[AEA],$A26) -> 2193922 | E26: =SUMIFS(INDEX(Breakdown[],0,MATCH(E$25,Breakdown[#Headers],0)),Breakdown[AEA],$A26) -> 14556174 | F26: =SUMIFS(INDEX(Breakdown[],0,MATCH(F$25,Breakdown[#Headers],0)),Breakdown[AEA],$A26) -> 7664312 | G26: =SUMIFS(INDEX(Breakdown[],0,MATCH(G$25,Breakdown[#Headers],0)),Breakdown[AEA],$A26) -> 6891862
A27: =A15 -> 05 | B27: =B15 -> Prairie Lakes AEA 8 | C27: =SUMIFS(INDEX(Breakdown[],0,MATCH(C$25,Breakdown[#Headers],0)),Breakdown[AEA],$A27) -> 1999952 | D27: =SUMIFS(INDEX(Breakdown[],0,MATCH(D$25,Breakdown[#Headers],0)),Breakdown[AEA],$A27) -> 2240189 | E27: =SUMIFS(INDEX(Breakdown[],0,MATCH(E$25,Breakdown[#Headers],0)),Breakdown[AEA],$A27) -> 15212382 | F27: =SUMIFS(INDEX(Breakdown[],0,MATCH(F$25,Breakdown[#Headers],0)),Breakdown[AEA],$A27) -> 8172796 | G27: =SUMIFS(INDEX(Breakdown[],0,MATCH(G$25,Breakdown[#Headers],0)),Breakdown[AEA],$A27) -> 7039586
A28: =A16 -> 07 | B28: =B16 -> Central Rivers | C28: =SUMIFS(INDEX(Breakdown[],0,MATCH(C$25,Breakdown[#Headers],0)),Breakdown[AEA],$A28) -> 4021446 | D28: =SUMIFS(INDEX(Breakdown[],0,MATCH(D$25,Breakdown[#Headers],0)),Breakdown[AEA],$A28) -> 4483647 | E28: =SUMIFS(INDEX(Breakdown[],0,MATCH(E$25,Breakdown[#Headers],0)),Breakdown[AEA],$A28) -> 31622730 | F28: =SUMIFS(INDEX(Breakdown[],0,MATCH(F$25,Breakdown[#Headers],0)),Breakdown[AEA],$A28) -> 17817550 | G28: =SUMIFS(INDEX(Breakdown[],0,MATCH(G$25,Breakdown[#Headers],0)),Breakdown[AEA],$A28) -> 13805180
A29: =A17 -> 09 | B29: =B17 -> Mississippi Bend AEA 9 | C29: =SUMIFS(INDEX(Breakdown[],0,MATCH(C$25,Breakdown[#Headers],0)),Breakdown[AEA],$A29) -> 2988923 | D29: =SUMIFS(INDEX(Breakdown[],0,MATCH(D$25,Breakdown[#Headers],0)),Breakdown[AEA],$A29) -> 3266212 | E29: =SUMIFS(INDEX(Breakdown[],0,MATCH(E$25,Breakdown[#Headers],0)),Breakdown[AEA],$A29) -> 22483243 | F29: =SUMIFS(INDEX(Breakdown[],0,MATCH(F$25,Breakdown[#Headers],0)),Breakdown[AEA],$A29) -> 12451056 | G29: =SUMIFS(INDEX(Breakdown[],0,MATCH(G$25,Breakdown[#Headers],0)),Breakdown[AEA],$A29) -> 10032187
A30: =A18 -> 10 | B30: =B18 -> Grant Wood AEA 10 | C30: =SUMIFS(INDEX(Breakdown[],0,MATCH(C$25,Breakdown[#Headers],0)),Breakdown[AEA],$A30) -> 4580882 | D30: =SUMIFS(INDEX(Breakdown[],0,MATCH(D$25,Breakdown[#Headers],0)),Breakdown[AEA],$A30) -> 5035582 | E30: =SUMIFS(INDEX(Breakdown[],0,MATCH(E$25,Breakdown[#Headers],0)),Breakdown[AEA],$A30) -> 34581514 | F30: =SUMIFS(INDEX(Breakdown[],0,MATCH(F$25,Breakdown[#Headers],0)),Breakdown[AEA],$A30) -> 19506268 | G30: =SUMIFS(INDEX(Breakdown[],0,MATCH(G$25,Breakdown[#Headers],0)),Breakdown[AEA],$A30) -> 15075246
A31: =A19 -> 11 | B31: =B19 -> Heartland AEA 11 | C31: =SUMIFS(INDEX(Breakdown[],0,MATCH(C$25,Breakdown[#Headers],0)),Breakdown[AEA],$A31) -> 9430082 | D31: =SUMIFS(INDEX(Breakdown[],0,MATCH(D$25,Breakdown[#Headers],0)),Breakdown[AEA],$A31) -> 10358799 | E31: =SUMIFS(INDEX(Breakdown[],0,MATCH(E$25,Breakdown[#Headers],0)),Breakdown[AEA],$A31) -> 70628446 | F31: =SUMIFS(INDEX(Breakdown[],0,MATCH(F$25,Breakdown[#Headers],0)),Breakdown[AEA],$A31) -> 40838071 | G31: =SUMIFS(INDEX(Breakdown[],0,MATCH(G$25,Breakdown[#Headers],0)),Breakdown[AEA],$A31) -> 29790375
A32: =A20 -> 12 | B32: =B20 -> Northwest AEA | C32: =SUMIFS(INDEX(Breakdown[],0,MATCH(C$25,Breakdown[#Headers],0)),Breakdown[AEA],$A32) -> 2825990 | D32: =SUMIFS(INDEX(Breakdown[],0,MATCH(D$25,Breakdown[#Headers],0)),Breakdown[AEA],$A32) -> 3164474 | E32: =SUMIFS(INDEX(Breakdown[],0,MATCH(E$25,Breakdown[#Headers],0)),Breakdown[AEA],$A32) -> 20859983 | F32: =SUMIFS(INDEX(Breakdown[],0,MATCH(F$25,Breakdown[#Headers],0)),Breakdown[AEA],$A32) -> 11329342 | G32: =SUMIFS(INDEX(Breakdown[],0,MATCH(G$25,Breakdown[#Headers],0)),Breakdown[AEA],$A32) -> 9530641
A33: =A21 -> 13 | B33: =B21 -> Green Hills AEA 13 | C33: =SUMIFS(INDEX(Breakdown[],0,MATCH(C$25,Breakdown[#Headers],0)),Breakdown[AEA],$A33) -> 2353258 | D33: =SUMIFS(INDEX(Breakdown[],0,MATCH(D$25,Breakdown[#Headers],0)),Breakdown[AEA],$A33) -> 2601568 | E33: =SUMIFS(INDEX(Breakdown[],0,MATCH(E$25,Breakdown[#Headers],0)),Breakdown[AEA],$A33) -> 18403029 | F33: =SUMIFS(INDEX(Breakdown[],0,MATCH(F$25,Breakdown[#Headers],0)),Breakdown[AEA],$A33) -> 10395097 | G33: =SUMIFS(INDEX(Breakdown[],0,MATCH(G$25,Breakdown[#Headers],0)),Breakdown[AEA],$A33) -> 8007932
A34: =A22 -> 15 | B34: =B22 -> Great Prairie AEA 15 | C34: =SUMIFS(INDEX(Breakdown[],0,MATCH(C$25,Breakdown[#Headers],0)),Breakdown[AEA],$A34) -> 2175147 | D34: =SUMIFS(INDEX(Breakdown[],0,MATCH(D$25,Breakdown[#Headers],0)),Breakdown[AEA],$A34) -> 2390777 | E34: =SUMIFS(INDEX(Breakdown[],0,MATCH(E$25,Breakdown[#Headers],0)),Breakdown[AEA],$A34) -> 16509513 | F34: =SUMIFS(INDEX(Breakdown[],0,MATCH(F$25,Breakdown[#Headers],0)),Breakdown[AEA],$A34) -> 9252847 | G34: =SUMIFS(INDEX(Breakdown[],0,MATCH(G$25,Breakdown[#Headers],0)),Breakdown[AEA],$A34) -> 7256666
C35: =SUM(C26:C34) -> 32345038 | D35: =SUM(D26:D34) -> 35735170 | E35: =SUM(E26:E34) -> 244857014 | F35: =SUM(F26:F34) -> 137427339 | G35: =SUM(G26:G34) -> 107429675

Sheet Breakdown
A1: AEA | B1: AEA Name | C1: Dist | D1: District | E1: AEA Special Ed Support District Cost Formula Generated | F1: State Aid Portion Special Ed | G1: AEA Statewide State Aid Reduction | H1: State Aid Special Ed Minus Reduction | I1: Special Education Property Tax Portion | J1: AEA Special Ed Support Adjustment | K1: Total Special Ed Funding Removing Reduction Including Adjustment | L1: State Aid Portion Sharing Operations | M1: Sharing Operations Property Tax | N1: Total AEA Sharing Operations | O1: AEA Teacher Salary Supplement District Cost | P1: AEA Professional Development Supplement District Cost | Q1: AEA Media Services District Cost | R1: AEA Ed Services District Cost | S1: Total Budget | T1: State Aid Portion | U1: Property Tax Portion
A2: 01 | B2: Keystone AEA 1 | C2: 0135 | D2: Allamakee | E2: 434569 | F2: 329541 | G2: 96613 | H2: 232928 | I2: 105028 | J2: 0 | K2: 337956 | L2: 882 | M2: 281 | N2: 1163 | O2: 43028 | P2: 4668 | Q2: 77426 | R2: 86254 | S2: 550495 | T2: 281505 | U2: 268990
A3: 01 | B3: Keystone AEA 1 | C3: 1080 | D3: Central Clayton | E3: 179034 | F3: 135765 | G3: 39301 | H3: 96464 | I3: 43269 | J3: 0 | K3: 139733 | L3: 364 | M3: 116 | N3: 480 | O3: 17727 | P3: 1923 | Q3: 28223 | R3: 31441 | S3: 219527 | T3: 116478 | U3: 103049
A4: 01 | B4: Keystone AEA 1 | C4: 2763 | D4: Clayton Ridge | E4: 249376 | F4: 189106 | G4: 51624 | H4: 137482 | I4: 60270 | J4: 0 | K4: 197752 | L4: 507 | M4: 161 | N4: 668 | O4: 24691 | P4: 2679 | Q4: 40711 | R4: 45353 | S4: 311854 | T4: 165359 | U4: 146495
A5: 01 | B5: Keystone AEA 1 | C5: 1638 | D5: Decorah | E5: 591354 | F5: 448433 | G5: 121901 | H5: 326532 | I5: 142921 | J5: 0 | K5: 469453 | L5: 1199 | M5: 382 | N5: 1581 | O5: 58551 | P5: 6353 | Q5: 103276 | R5: 115052 | S5: 754266 | T5: 392635 | U5: 361631
A6: 01 | B6: Keystone AEA 1 | C6: 1863 | D6: Dubuque | E6: 4180852 | F6: 3170405 | G6: 675758 | H6: 2494647 | I6: 1010447 | J6: 0 | K6: 3505094 | L6: 8480 | M6: 2702 | N6: 11182 | O6: 413954 | P6: 44914 | Q6: 733046 | R6: 816634 | S6: 5524824 | T6: 2961995 | U6: 2562829
A7: 01 | B7: Keystone AEA 1 | C7: 1972 | D7: Eastern Allamakee | E7: 131322 | F7: 99583 | G7: 31180 | H7: 68403 | I7: 31739 | J7: 0 | K7: 100142 | L7: 267 | M7: 85 | N7: 352 | O7: 13002 | P7: 1411 | Q7: 21042 | R7: 23442 | S7: 159391 | T7: 83083 | U7: 76308
A8: 01 | B8: Keystone AEA 1 | C8: 1989 | D8: Edgewood-Colesburg | E8: 148833 | F8: 112863 | G8: 35520 | H8: 77343 | I8: 35970 | J8: 0 | K8: 113313 | L8: 301 | M8: 96 | N8: 397 | O8: 14736 | P8: 1599 | Q8: 26412 | R8: 29424 | S8: 185881 | T8: 93979 | U8: 91902
A9: 01 | B9: Keystone AEA 1 | C9: 3029 | D9: Howard-Winneshiek | E9: 456575 | F9: 346228 | G9: 98287 | H9: 247941 | I9: 110347 | J9: 0 | K9: 358288 | L9: 927 | M9: 295 | N9: 1222 | O9: 45206 | P9: 4905 | Q9: 81172 | R9: 90428 | S9: 581221 | T9: 298979 | U9: 282242
A10: 01 | B10: Keystone AEA 1 | C10: 4419 | D10: MFL Mar Mac | E10: 312880 | F10: 237262 | G10: 64253 | H10: 173009 | I10: 75618 | J10: 0 | K10: 248627 | L10: 634 | M10: 202 | N10: 836 | O10: 30979 | P10: 3361 | Q10: 50514 | R10: 56274 | S10: 390591 | T10: 207983 | U10: 182608
A11: 01 | B11: Keystone AEA 1 | C11: 4043 | D11: Maquoketa Valley | E11: 259552 | F11: 196823 | G11: 59234 | H11: 137589 | I11: 62729 | J11: 0 | K11: 200318 | L11: 525 | M11: 168 | N11: 693 | O11: 25699 | P11: 2788 | Q11: 43521 | R11: 48483 | S11: 321502 | T11: 166601 | U11: 154901
A12: 01 | B12: Keystone AEA 1 | C12: 4662 | D12: New Hampton | E12: 361905 | F12: 274439 | G12: 76047 | H12: 198392 | I12: 87466 | J12: 0 | K12: 285858 | L12: 734 | M12: 234 | N12: 968 | O12: 35833 | P12: 3888 | Q12: 63377 | R12: 70603 | S12: 460527 | T12: 238846 | U12: 221681
A13: 01 | B13: Keystone AEA 1 | C13: 4774 | D13: North Fayette Valley | E13: 467284 | F13: 354349 | G13: 105989 | H13: 248360 | I13: 112935 | J13: 0 | K13: 361295 | L13: 948 | M13: 302 | N13: 1250 | O13: 46267 | P13: 5020 | Q13: 71244 | R13: 79368 | S13: 564444 | T13: 300594 | U13: 263850
... A326: 15 | B326: Great Prairie AEA 15 | C326: 7047 | D326: Winfield-Mt Union | E326: 112841 | F326: 89918 | G326: 23945 | H326: 65973 | I326: 22923 | J326: 2887 | K326: 91783 | L326: 211 | M326: 54 | N326: 265 | O326: 11342 | P326: 1243 | Q326: 19015 | R326: 20900 | S326: 144548 | T326: 78770 | U326: 65778

Sheet Detail
A1: FY 2024 AEA Weights and Costs Detail
A2: AEA | B2: AEA Name | C2: Dist | D2: District | E2: Total Special Ed Weighting in Addition to 1.0 | F2: Budget Enrollment | G2: AEA Weighted Enrollment | H2: AEA Supplementary Weight for Sharing | I2: Resident Accredited Nonpublic Students | J2: Shared-Time Nonpublic Pupils Counted in Line 1.1 | K2: Total Enrollment Served - AEA Media and Ed Services | L2: AEA Special Ed Support Cost Per Pupil | M2: AEA Media Cost Per Pupil | N2: AEA Ed Services Cost Per Pupil | O2: AEA Teacher Salary Supplement District Cost Per Pupil | P2: Professional Development Supplement District Cost Per Pupil | Q2: AEA Special Ed Support District Cost without Adjustment | R2: AEA Special Ed Support Adjustment | S2: Special Education Total Cost | T2: AEA Media Services District Cost | U2: AEA Ed Services District Cost | V2: AEA Sharing District Cost | W2: AEA Teacher Salary Supplement District Cost | X2: AEA Professional Development Supplement District Cost | Y2: Subtotal Budget | Z2: AEA Statewide State Aid Reduction | AA2: Total Budget | AB2: State Aid Portion | AC2: Property Tax Portion
A3: 01 | B3: Keystone AEA 1 | C3: 0135 | D3: Allamakee | E3: 160.86 | F3: 1087.4 | G3: 1248.26 | H3: 3.34 | I3: 154 | J3: 1.3 | K3: 1240 | L3: 348.14 | M3: 62.44 | N3: 69.56 | O3: 34.47 | P3: 3.74 | Q3: 434569 | R3: 0 | S3: 434569 | T3: 77426 | U3: 86254 | V3: 1163 | W3: 43028 | X3: 4668 | Y3: 647108 | Z3: 96613 | AA3: 550495 | AB3: 281505 | AC3: 268990
A4: 01 | B4: Keystone AEA 1 | C4: 1080 | D4: Central Clayton | E4: 62.56 | F4: 451.7 | G4: 514.26 | H4: 1.38 | I4: 0 | J4: 0 | K4: 452 | L4: 348.14 | M4: 62.44 | N4: 69.56 | O4: 34.47 | P4: 3.74 | Q4: 179034 | R4: 0 | S4: 179034 | T4: 28223 | U4: 31441 | V4: 480 | W4: 17727 | X4: 1923 | Y4: 258828 | Z4: 39301 | AA4: 219527 | AB4: 116478 | AC4: 103049
A5: 01 | B5: Keystone AEA 1 | C5: 2763 | D5: Clayton Ridge | E5: 74.41 | F5: 641.9 | G5: 716.31 | H5: 1.92 | I5: 10 | J5: 0 | K5: 652 | L5: 348.14 | M5: 62.44 | N5: 69.56 | O5: 34.47 | P5: 3.74 | Q5: 249376 | R5: 0 | S5: 249376 | T5: 40711 | U5: 45353 | V5: 668 | W5: 24691 | X5: 2679 | Y5: 363478 | Z5: 51624 | AA5: 311854 | AB5: 165359 | AC5: 146495
A6: 01 | B6: Keystone AEA 1 | C6: 1638 | D6: Decorah | E6: 176.01 | F6: 1522.6 | G6: 1698.61 | H6: 4.54 | I6: 132 | J6: 0.2 | K6: 1654 | L6: 348.14 | M6: 62.44 | N6: 69.56 | O6: 34.47 | P6: 3.74 | Q6: 591354 | R6: 0 | S6: 591354 | T6: 103276 | U6: 115052 | V6: 1581 | W6: 58551 | X6: 6353 | Y6: 876167 | Z6: 121901 | AA6: 754266 | AB6: 392635 | AC6: 361631
A7: 01 | B7: Keystone AEA 1 | C7: 1863 | D7: Dubuque | E7: 1945.01 | F7: 10064.1 | G7: 12009.11 | H7: 32.12 | I7: 1680 | J7: 4.2 | K7: 11740 | L7: 348.14 | M7: 62.44 | N7: 69.56 | O7: 34.47 | P7: 3.74 | Q7: 4180852 | R7: 0 | S7: 4180852 | T7: 733046 | U7: 816634 | V7: 11182 | W7: 413954 | X7: 44914 | Y7: 6200582 | Z7: 675758 | AA7: 5524824 | AB7: 2961995 | AC7: 2562829
A8: 01 | B8: Keystone AEA 1 | C8: 1972 | D8: Eastern Allamakee | E8: 45.91 | F8: 331.3 | G8: 377.21 | H8: 1.01 | I8: 6 | J8: 0 | K8: 337 | L8: 348.14 | M8: 62.44 | N8: 69.56 | O8: 34.47 | P8: 3.74 | Q8: 131322 | R8: 0 | S8: 131322 | T8: 21042 | U8: 23442 | V8: 352 | W8: 13002 | X8: 1411 | Y8: 190571 | Z8: 31180 | AA8: 159391 | AB8: 83083 | AC8: 76308
A9: 01 | B9: Keystone AEA 1 | C9: 1989 | D9: Edgewood-Colesburg | E9: 26.51 | F9: 401 | G9: 427.51 | H9: 1.14 | I9: 22 | J9: 0 | K9: 423 | L9: 348.14 | M9: 62.44 | N9: 69.56 | O9: 34.47 | P9: 3.74 | Q9: 148833 | R9: 0 | S9: 148833 | T9: 26412 | U9: 29424 | V9: 397 | W9: 14736 | X9: 1599 | Y9: 221401 | Z9: 35520 | AA9: 185881 | AB9: 93979 | AC9: 91902
A10: 01 | B10: Keystone AEA 1 | C10: 3029 | D10: Howard-Winneshiek | E10: 159.77 | F10: 1151.7 | G10: 1311.47 | H10: 3.51 | I10: 149 | J10: 0.7 | K10: 1300 | L10: 348.14 | M10: 62.44 | N10: 69.56 | O10: 34.47 | P10: 3.74 | Q10: 456575 | R10: 0 | S10: 456575 | T10: 81172 | U10: 90428 | V10: 1222 | W10: 45206 | X10: 4905 | Y10: 679508 | Z10: 98287 | AA10: 581221 | AB10: 298979 | AC10: 282242
A11: 01 | B11: Keystone AEA 1 | C11: 4419 | D11: MFL Mar Mac | E11: 92.22 | F11: 806.5 | G11: 898.72 | H11: 2.4 | I11: 2 | J11: 0 | K11: 809 | L11: 348.14 | M11: 62.44 | N11: 69.56 | O11: 34.47 | P11: 3.74 | Q11: 312880 | R11: 0 | S11: 312880 | T11: 50514 | U11: 56274 | V11: 836 | W11: 30979 | X11: 3361 | Y11: 454844 | Z11: 64253 | AA11: 390591 | AB11: 207983 | AC11: 182608
A12: 01 | B12: Keystone AEA 1 | C12: 4043 | D12: Maquoketa Valley | E12: 82.44 | F12: 663.1 | G12: 745.54 | H12: 1.99 | I12: 34 | J12: 0 | K12: 697 | L12: 348.14 | M12: 62.44 | N12: 69.56 | O12: 34.47 | P12: 3.74 | Q12: 259552 | R12: 0 | S12: 259552 | T12: 43521 | U12: 48483 | V12: 693 | W12: 25699 | X12: 2788 | Y12: 380736 | Z12: 59234 | AA12: 321502 | AB12: 166601 | AC12: 154901
A13: 01 | B13: Keystone AEA 1 | C13: 4662 | D13: New Hampton | E13: 109.54 | F13: 930 | G13: 1039.54 | H13: 2.78 | I13: 85 | J13: 0.3 | K13: 1015 | L13: 348.14 | M13: 62.44 | N13: 69.56 | O13: 34.47 | P13: 3.74 | Q13: 361905 | R13: 0 | S13: 361905 | T13: 63377 | U13: 70603 | V13: 968 | W13: 35833 | X13: 3888 | Y13: 536574 | Z13: 76047 | AA13: 460527 | AB13: 238846 | AC13: 221681
A14: 01 | B14: Keystone AEA 1 | C14: 4774 | D14: North Fayette Valley | E14: 204.23 | F14: 1138 | G14: 1342.23 | H14: 3.59 | I14: 3 | J14: 0 | K14: 1141 | L14: 348.14 | M14: 62.44 | N14: 69.56 | O14: 34.47 | P14: 3.74 | Q14: 467284 | R14: 0 | S14: 467284 | T14: 71244 | U14: 79368 | V14: 1250 | W14: 46267 | X14: 5020 | Y14: 670433 | Z14: 105989 | AA14: 564444 | AB14: 300594 | AC14: 263850
... A327: 15 | B327: Great Prairie AEA 15 | C327: 7047 | D327: Winfield-Mt Union | E327: 34.4 | F327: 306.2 | G327: 340.6 | H327: 0.8 | I327: 0 | J327: 0 | K327: 306 | L327: 331.3 | M327: 62.14 | N327: 68.3 | O327: 33.3 | P327: 3.65 | Q327: 112841 | R327: 2887 | S327: 115728 | T327: 19015 | U327: 20900 | V327: 265 | W327: 11342 | X327: 1243 | Y327: 168493 | Z327: 23945 | AA327: 144548 | AB327: 78770 | AC327: 65778

Sheet Detail By AEA
B1: =CONCATENATE(INDEX(Detail[],MATCH(A5,Detail[Dist],0),2)," Detail by School District") -> Central Rivers Detail by School District
A4: Dist | B4: District | C4: Total Special Ed Weighting | D4: Budget Enrollment | E4: AEA Weighted Enrollment | F4: AEA Supplementary Weight for Sharing | G4: Resident Accredited Nonpublic Students | H4: Shared-Time Nonpublic Pupils | I4: Total Enrollment Served - AEA Media and Ed Services | J4: AEA Special Ed Support District Cost without Adjustment | K4: AEA Special Ed Support Adjustment | L4: Special Education Total Cost | M4: AEA Media Services District Cost | N4: AEA Ed Services District Cost | O4: AEA Sharing District Cost | P4: AEA Teacher Salary Supplement District Cost | Q4: AEA Professional Development Supplement District Cost | R4: Subtotal Budget | S4: AEA State Aid Reduction | T4: Total Budget | U4: State Aid Portion | V4: Property Tax Portion
A5: 0009 | B5: AGWSR | C5: 106.87 | D5: 686.4 | E5: 793.27 | F5: 1 | G5: 16 | H5: 0 | I5: 702 | J5: 267538 | K5: 0 | L5: 267538 | M5: 43854 | N5: 48894 | O5: 337 | P5: 33079 | Q5: 3808 | R5: 397510 | S5: 54162 | T5: 343348 | U5: 192412 | V5: 150936
A6: 0018 | B6: Adair-Casey | C6: 48.64 | D6: 306.3 | E6: 354.94 | F6: 0 | G6: 0 | H6: 0 | I6: 306 | J6: 115668 | K6: 0 | L6: 115668 | M6: 18984 | N6: 20854 | O6: 0 | P6: 9850 | Q6: 1235 | R6: 166591 | S6: 22203 | T6: 144388 | U6: 82586 | V6: 61802
A7: 0027 | B7: Adel-Desoto-Minburn | C7: 238.28 | D7: 2130.9 | E7: 2369.18 | F7: 0 | G7: 28 | H7: 0 | I7: 2159 | J7: 772068 | K7: 0 | L7: 772068 | M7: 133944 | N7: 147136 | O7: 0 | P7: 65745 | Q7: 8245 | R7: 1127138 | S7: 82599 | T7: 1044539 | U7: 616855 | V7: 427684
A8: 0063 | B8: Akron-Westfield | C8: 77.09 | D8: 555.2 | E8: 632.29 | F8: 1.22 | G8: 14 | H8: 0 | I8: 569 | J8: 215307 | K8: 0 | L8: 215307 | M8: 35534 | N8: 39790 | O8: 415 | P8: 21694 | Q8: 2586 | R8: 315326 | S8: 35284 | T8: 280042 | U8: 156243 | V8: 123799
A9: 0072 | B9: Albert City-Truesdale | C9: 26.19 | D9: 209.6 | E9: 235.79 | F9: 0 | G9: 0 | H9: 0 | I9: 210 | J9: 81086 | K9: 0 | L9: 81086 | M9: 13129 | N9: 14706 | O9: 0 | P9: 8590 | Q9: 1021 | R9: 118532 | S9: 18549 | T9: 99983 | U9: 53311 | V9: 46672
A10: 0081 | B10: Albia | C10: 135.1 | D10: 1099.4 | E10: 1234.5 | F10: 2.89 | G10: 3 | H10: 0 | I10: 1102 | J10: 408990 | K10: 986 | L10: 409976 | M10: 68478 | N10: 75267 | O10: 957 | P10: 41179 | Q10: 4506 | R10: 600363 | S10: 76124 | T10: 524239 | U10: 296232 | V10: 228007
A11: 0099 | B11: Alburnett | C11: 35.62 | D11: 526.5 | E11: 562.12 | F11: 0.65 | G11: 22 | H11: 0 | I11: 549 | J11: 187175 | K11: 0 | L11: 187175 | M11: 34126 | N11: 37513 | O11: 216 | P11: 17718 | Q11: 2063 | R11: 278811 | S11: 37096 | T11: 241715 | U11: 131256 | V11: 110459
