Workbook
Name AEA_Name: #REF!

Sheet Description of Tabs
B1: Click on the Tab name and you will go directly to the tab in the workbook
B3: AEA Payment Summary
B4: Breakdown of the Actual Payment from the State to Each AEA
B5: Includes the share of how much your nonpublic students generate for Media and Ed Services.
B6: SF 659 (section 6) (2025 Legislative Session) authorizes DOM to pay the nonpublic share directly to AEAs.
B8: DetailByDistrict
B9: Includes the Detail by school district for Enrollment data, Cost Per Pupil Amounts, and the Total amounts generated for the program areas
B11: DetailByAEA
B12: Has the same information as the “DetailByDistrict” just summed by AEA.
B14: Special Education Breakdown
B15: Includes the 90% and 10% split and amount district must pay to the AEAs
B16: You can change the AEA number in Column C – “AEA District Chose to Receive Services From” if you have an agreement with a district to provide services to that district. The totals on the tab “Special Education By AEA” will automatically update.
... B28: Has the Nonpublic allocation for Media and Ed services by Nonpublic School

Sheet AEA Payment Summary
C6: AEA | D6: AEA Name | E6: State Aid Portion Sharing Operations | F6: Sharing Operations Property Tax | G6: Total AEA Sharing Operations | H6: AEA Teacher Salary Supplement District Cost | I6: AEA Media Services Nonpublic Portion | J6: AEA Educational Services Nonpublic Portion | K6: Total AEA Payment | L6: AEA Payment State Aid Portion | M6: AEA Payment Property Tax Portion | R6: Check | S6: State Aid Check | T6: Property Tax Check
C7: 01 | D7: Keystone AEA 1 | E7: =SUMIF(Breakdown[AEA],$C7,Breakdown[State Aid Portion Sharing Operations]) -> 22789 | F7: =SUMIF(Breakdown[AEA],$C7,Breakdown[Sharing Operations Property Tax]) -> 7211 | G7: =SUMIF(Breakdown[AEA],$C7,Breakdown[Total AEA Sharing Operations]) -> 30000 | H7: =SUMIF(Breakdown[AEA],$C7,Breakdown[AEA Teacher Salary Supplement District Cost]) -> 1151859 | I7: =SUMIF(Breakdown[AEA],$C7,Breakdown[AEA Media Services Nonpublic Portion]) -> 262085 | J7: =SUMIF(Breakdown[AEA],$C7,Breakdown[AEA Educational Services Nonpublic Portion]) -> 291923 | K7: =SUMIF(Breakdown[AEA],$C7,Breakdown[Total AEA Payment]) -> 1735867 | L7: =SUMIF(Breakdown[AEA],$C7,Breakdown[AEA Payment State Aid Portion]) -> 1174648 | M7: =SUMIF(Breakdown[AEA],$C7,Breakdown[AEA Payment Property Tax Portion]) -> 561219 | R7: =K7-J7-I7-H7-G7 -> 0 | S7: =L7-H7-E7 -> 0 | T7: =M7-J7-I7-F7 -> 0
C8: 05 | D8: Prairie Lakes AEA 8 | E8: =SUMIF(Breakdown[AEA],$C8,Breakdown[State Aid Portion Sharing Operations]) -> 0 | F8: =SUMIF(Breakdown[AEA],$C8,Breakdown[Sharing Operations Property Tax]) -> 0 | G8: =SUMIF(Breakdown[AEA],$C8,Breakdown[Total AEA Sharing Operations]) -> 0 | H8: =SUMIF(Breakdown[AEA],$C8,Breakdown[AEA Teacher Salary Supplement District Cost]) -> 1276124 | I8: =SUMIF(Breakdown[AEA],$C8,Breakdown[AEA Media Services Nonpublic Portion]) -> 150479 | J8: =SUMIF(Breakdown[AEA],$C8,Breakdown[AEA Educational Services Nonpublic Portion]) -> 168486 | K8: =SUMIF(Breakdown[AEA],$C8,Breakdown[Total AEA Payment]) -> 1595089 | L8: =SUMIF(Breakdown[AEA],$C8,Breakdown[AEA Payment State Aid Portion]) -> 1276124 | M8: =SUMIF(Breakdown[AEA],$C8,Breakdown[AEA Payment Property Tax Portion]) -> 318965 | R8: =K8-J8-I8-H8-G8 -> 0 | S8: =L8-H8-E8 -> 0 | T8: =M8-J8-I8-F8 -> 0
C9: 07 | D9: Central Rivers | E9: =SUMIF(Breakdown[AEA],$C9,Breakdown[State Aid Portion Sharing Operations]) -> 23488 | F9: =SUMIF(Breakdown[AEA],$C9,Breakdown[Sharing Operations Property Tax]) -> 6512 | G9: =SUMIF(Breakdown[AEA],$C9,Breakdown[Total AEA Sharing Operations]) -> 30000 | H9: =SUMIF(Breakdown[AEA],$C9,Breakdown[AEA Teacher Salary Supplement District Cost]) -> 3032137 | I9: =SUMIF(Breakdown[AEA],$C9,Breakdown[AEA Media Services Nonpublic Portion]) -> 253193 | J9: =SUMIF(Breakdown[AEA],$C9,Breakdown[AEA Educational Services Nonpublic Portion]) -> 282243 | K9: =SUMIF(Breakdown[AEA],$C9,Breakdown[Total AEA Payment]) -> 3597573 | L9: =SUMIF(Breakdown[AEA],$C9,Breakdown[AEA Payment State Aid Portion]) -> 3055625 | M9: =SUMIF(Breakdown[AEA],$C9,Breakdown[AEA Payment Property Tax Portion]) -> 541948 | R9: =K9-J9-I9-H9-G9 -> 0 | S9: =L9-H9-E9 -> 0 | T9: =M9-J9-I9-F9 -> 0
C10: 09 | D10: Mississippi Bend AEA 9 | E10: =SUMIF(Breakdown[AEA],$C10,Breakdown[State Aid Portion Sharing Operations]) -> 23650 | F10: =SUMIF(Breakdown[AEA],$C10,Breakdown[Sharing Operations Property Tax]) -> 6350 | G10: =SUMIF(Breakdown[AEA],$C10,Breakdown[Total AEA Sharing Operations]) -> 30000 | H10: =SUMIF(Breakdown[AEA],$C10,Breakdown[AEA Teacher Salary Supplement District Cost]) -> 1634071 | I10: =SUMIF(Breakdown[AEA],$C10,Breakdown[AEA Media Services Nonpublic Portion]) -> 245851 | J10: =SUMIF(Breakdown[AEA],$C10,Breakdown[AEA Educational Services Nonpublic Portion]) -> 268841 | K10: =SUMIF(Breakdown[AEA],$C10,Breakdown[Total AEA Payment]) -> 2178763 | L10: =SUMIF(Breakdown[AEA],$C10,Breakdown[AEA Payment State Aid Portion]) -> 1657721 | M10: =SUMIF(Breakdown[AEA],$C10,Breakdown[AEA Payment Property Tax Portion]) -> 521042 | R10: =K10-J10-I10-H10-G10 -> 0 | S10: =L10-H10-E10 -> 0 | T10: =M10-J10-I10-F10 -> 0
C11: 10 | D11: Grant Wood AEA 10 | E11: =SUMIF(Breakdown[AEA],$C11,Breakdown[State Aid Portion Sharing Operations]) -> 23785 | F11: =SUMIF(Breakdown[AEA],$C11,Breakdown[Sharing Operations Property Tax]) -> 6216 | G11: =SUMIF(Breakdown[AEA],$C11,Breakdown[Total AEA Sharing Operations]) -> 30001 | H11: =SUMIF(Breakdown[AEA],$C11,Breakdown[AEA Teacher Salary Supplement District Cost]) -> 2570057 | I11: =SUMIF(Breakdown[AEA],$C11,Breakdown[AEA Media Services Nonpublic Portion]) -> 344008 | J11: =SUMIF(Breakdown[AEA],$C11,Breakdown[AEA Educational Services Nonpublic Portion]) -> 378309 | K11: =SUMIF(Breakdown[AEA],$C11,Breakdown[Total AEA Payment]) -> 3322375 | L11: =SUMIF(Breakdown[AEA],$C11,Breakdown[AEA Payment State Aid Portion]) -> 2593842 | M11: =SUMIF(Breakdown[AEA],$C11,Breakdown[AEA Payment Property Tax Portion]) -> 728533 | R11: =K11-J11-I11-H11-G11 -> 0 | S11: =L11-H11-E11 -> 0 | T11: =M11-J11-I11-F11 -> 0
C12: 11 | D12: Heartland AEA 11 | E12: =SUMIF(Breakdown[AEA],$C12,Breakdown[State Aid Portion Sharing Operations]) -> 0 | F12: =SUMIF(Breakdown[AEA],$C12,Breakdown[Sharing Operations Property Tax]) -> 0 | G12: =SUMIF(Breakdown[AEA],$C12,Breakdown[Total AEA Sharing Operations]) -> 0 | H12: =SUMIF(Breakdown[AEA],$C12,Breakdown[AEA Teacher Salary Supplement District Cost]) -> 4753653 | I12: =SUMIF(Breakdown[AEA],$C12,Breakdown[AEA Media Services Nonpublic Portion]) -> 752248 | J12: =SUMIF(Breakdown[AEA],$C12,Breakdown[AEA Educational Services Nonpublic Portion]) -> 826706 | K12: =SUMIF(Breakdown[AEA],$C12,Breakdown[Total AEA Payment]) -> 6332607 | L12: =SUMIF(Breakdown[AEA],$C12,Breakdown[AEA Payment State Aid Portion]) -> 4753653 | M12: =SUMIF(Breakdown[AEA],$C12,Breakdown[AEA Payment Property Tax Portion]) -> 1578954 | R12: =K12-J12-I12-H12-G12 -> 0 | S12: =L12-H12-E12 -> 0 | T12: =M12-J12-I12-F12 -> 0
C13: 12 | D13: Northwest AEA | E13: =SUMIF(Breakdown[AEA],$C13,Breakdown[State Aid Portion Sharing Operations]) -> 23274 | F13: =SUMIF(Breakdown[AEA],$C13,Breakdown[Sharing Operations Property Tax]) -> 6726 | G13: =SUMIF(Breakdown[AEA],$C13,Breakdown[Total AEA Sharing Operations]) -> 30000 | H13: =SUMIF(Breakdown[AEA],$C13,Breakdown[AEA Teacher Salary Supplement District Cost]) -> 1619590 | I13: =SUMIF(Breakdown[AEA],$C13,Breakdown[AEA Media Services Nonpublic Portion]) -> 377069 | J13: =SUMIF(Breakdown[AEA],$C13,Breakdown[AEA Educational Services Nonpublic Portion]) -> 422065 | K13: =SUMIF(Breakdown[AEA],$C13,Breakdown[Total AEA Payment]) -> 2448724 | L13: =SUMIF(Breakdown[AEA],$C13,Breakdown[AEA Payment State Aid Portion]) -> 1642864 | M13: =SUMIF(Breakdown[AEA],$C13,Breakdown[AEA Payment Property Tax Portion]) -> 805860 | R13: =K13-J13-I13-H13-G13 -> 0 | S13: =L13-H13-E13 -> 0 | T13: =M13-J13-I13-F13 -> 0
C14: 13 | D14: Green Hills AEA 13 | E14: =SUMIF(Breakdown[AEA],$C14,Breakdown[State Aid Portion Sharing Operations]) -> 23715 | F14: =SUMIF(Breakdown[AEA],$C14,Breakdown[Sharing Operations Property Tax]) -> 6285 | G14: =SUMIF(Breakdown[AEA],$C14,Breakdown[Total AEA Sharing Operations]) -> 30000 | H14: =SUMIF(Breakdown[AEA],$C14,Breakdown[AEA Teacher Salary Supplement District Cost]) -> 1519471 | I14: =SUMIF(Breakdown[AEA],$C14,Breakdown[AEA Media Services Nonpublic Portion]) -> 79679 | J14: =SUMIF(Breakdown[AEA],$C14,Breakdown[AEA Educational Services Nonpublic Portion]) -> 88100 | K14: =SUMIF(Breakdown[AEA],$C14,Breakdown[Total AEA Payment]) -> 1717250 | L14: =SUMIF(Breakdown[AEA],$C14,Breakdown[AEA Payment State Aid Portion]) -> 1543186 | M14: =SUMIF(Breakdown[AEA],$C14,Breakdown[AEA Payment Property Tax Portion]) -> 174064 | R14: =K14-J14-I14-H14-G14 -> 0 | S14: =L14-H14-E14 -> 0 | T14: =M14-J14-I14-F14 -> 0
C15: 15 | D15: Great Prairie AEA 15 | E15: =SUMIF(Breakdown[AEA],$C15,Breakdown[State Aid Portion Sharing Operations]) -> 23898 | F15: =SUMIF(Breakdown[AEA],$C15,Breakdown[Sharing Operations Property Tax]) -> 6104 | G15: =SUMIF(Breakdown[AEA],$C15,Breakdown[Total AEA Sharing Operations]) -> 30002 | H15: =SUMIF(Breakdown[AEA],$C15,Breakdown[AEA Teacher Salary Supplement District Cost]) -> 1327569 | I15: =SUMIF(Breakdown[AEA],$C15,Breakdown[AEA Media Services Nonpublic Portion]) -> 95494 | J15: =SUMIF(Breakdown[AEA],$C15,Breakdown[AEA Educational Services Nonpublic Portion]) -> 105003 | K15: =SUMIF(Breakdown[AEA],$C15,Breakdown[Total AEA Payment]) -> 1558068 | L15: =SUMIF(Breakdown[AEA],$C15,Breakdown[AEA Payment State Aid Portion]) -> 1351467 | M15: =SUMIF(Breakdown[AEA],$C15,Breakdown[AEA Payment Property Tax Portion]) -> 206601 | R15: =K15-J15-I15-H15-G15 -> 0 | S15: =L15-H15-E15 -> 0 | T15: =M15-J15-I15-F15 -> 0
E16: =SUM(E7:E15) -> 164599 | F16: =SUM(F7:F15) -> 45404 | G16: =SUM(G7:G15) -> 210003 | H16: =SUM(H7:H15) -> 18884531 | I16: =SUM(I7:I15) -> 2560106 | J16: =SUM(J7:J15) -> 2831676 | K16: =SUM(K7:K15) -> 24486316 | L16: =SUM(L7:L15) -> 19049130 | M16: =SUM(M7:M15) -> 5437186 | R16: =K16-J16-I16-H16-G16 -> 0 | S16: =L16-H16-E16 -> 0 | T16: =M16-J16-I16-F16 -> 0

Sheet DetailByDistrict
A1: AEA | B1: AEA Name | C1: Dist | D1: District | E1: Total Special Ed Weighting in Addition to 1.0 | F1: Budget Enrollment | G1: AEA Weighted Enrollment | H1: AEA Supplementary Weight for Sharing | I1: Resident Accredited Nonpublic Students | J1: Shared-Time Nonpublic Pupils Counted in Line 1.1 | K1: Total Enrollment Served - Media and Ed Services | L1: AEA Special Ed Support Cost Per Pupil | M1: AEA Media Cost Per Pupil | N1: AEA Ed Services Cost Per Pupil | O1: AEA Teacher Salary Supplement District Cost Per Pupil | P1: AEA Special Ed Support District Cost without Adjustment | Q1: AEA Special Ed Support Adjustment | R1: Special Education Total Cost | S1: District/AEA Statewide State Aid Reduction | T1: AEA Media Services Nonpublic Portion | U1: District Media Services | V1: Total Media Services | W1: AEA Educational Services Nonpublic Portion | X1: District Educational Services | Y1: Total Educational Services | Z1: AEA Sharing District Cost | AA1: AEA Teacher Salary Supplement District Cost
A2: 01 | B2: Keystone AEA 1 | C2: 0135 | D2: Allamakee | E2: 170.28 | F2: 1104.7 | G2: 1274.98 | H2: 3.3 | I2: 155 | J2: 1.8 | K2: 1258 | L2: 363.32 | M2: 65.26 | N2: 72.69 | O2: 36.03 | P2: 463226 | Q2: 0 | R2: 463226 | S2: 75370 | T2: 10115 | U2: 71982 | V2: 82097 | W2: 11267 | X2: 80177 | Y2: 91444 | Z2: 1199 | AA2: 45938
A3: 01 | B3: Keystone AEA 1 | C3: 1080 | D3: Central Clayton | E3: 66.67 | F3: 456.1 | G3: 522.77 | H3: 1.35 | I3: 0 | J3: 0 | K3: 456 | L3: 363.32 | M3: 65.26 | N3: 72.69 | O3: 36.03 | P3: 189933 | Q3: 1572 | R3: 191505 | S3: 30904 | T3: 0 | U3: 29759 | V3: 29759 | W3: 0 | X3: 33147 | Y3: 33147 | Z3: 490 | AA3: 18980
A4: 01 | B4: Keystone AEA 1 | C4: 2763 | D4: Clayton Ridge | E4: 79.93 | F4: 638 | G4: 717.93 | H4: 1.86 | I4: 11 | J4: 0 | K4: 649 | L4: 363.32 | M4: 65.26 | N4: 72.69 | O4: 36.03 | P4: 260838 | Q4: 0 | R4: 260838 | S4: 42440 | T4: 718 | U4: 41636 | V4: 42354 | W4: 800 | X4: 46376 | Y4: 47176 | Z4: 676 | AA4: 25867
A5: 01 | B5: Keystone AEA 1 | C5: 1638 | D5: Decorah | E5: 184.18 | F5: 1450.4 | G5: 1634.58 | H5: 4.24 | I5: 170 | J5: 0.8 | K5: 1620 | L5: 363.32 | M5: 65.26 | N5: 72.69 | O5: 36.03 | P5: 593876 | Q5: 10511 | R5: 604387 | S5: 96628 | T5: 11094 | U5: 94627 | V5: 105721 | W5: 12357 | X5: 105401 | Y5: 117758 | Z5: 1540 | AA5: 59900
A6: 01 | B6: Keystone AEA 1 | C6: 1863 | D6: Dubuque | E6: 1892.58 | F6: 9862.9 | G6: 11755.48 | H6: 30.46 | I6: 1933 | J6: 12.5 | K6: 11783 | L6: 363.32 | M6: 65.26 | N6: 72.69 | O6: 36.03 | P6: 4271001 | Q6: 0 | R6: 4271001 | S6: 694923 | T6: 126148 | U6: 642811 | V6: 768959 | W6: 140510 | X6: 715996 | Y6: 856506 | Z6: 11067 | AA6: 423550
A7: 01 | B7: Keystone AEA 1 | C7: 1972 | D7: Eastern Allamakee | E7: 41.27 | F7: 307 | G7: 348.27 | H7: 0.9 | I7: 10 | J7: 0 | K7: 317 | L7: 363.32 | M7: 65.26 | N7: 72.69 | O7: 36.03 | P7: 126533 | Q7: 4789 | R7: 131322 | S7: 20588 | T7: 653 | U7: 20034 | V7: 20687 | W7: 727 | X7: 22316 | Y7: 23043 | Z7: 327 | AA7: 12548
A8: 01 | B8: Keystone AEA 1 | C8: 1989 | D8: Edgewood-Colesburg | E8: 35.81 | F8: 378 | G8: 413.81 | H8: 1.07 | I8: 21 | J8: 0 | K8: 399 | L8: 363.32 | M8: 65.26 | N8: 72.69 | O8: 36.03 | P8: 150345 | Q8: 0 | R8: 150345 | S8: 24462 | T8: 1370 | U8: 24669 | V8: 26039 | W8: 1526 | X8: 27477 | Y8: 29003 | Z8: 389 | AA8: 14910
A9: 01 | B9: Keystone AEA 1 | C9: 3029 | D9: Howard-Winneshiek | E9: 161.42 | F9: 1147 | G9: 1308.42 | H9: 3.39 | I9: 120 | J9: 1.1 | K9: 1266 | L9: 363.32 | M9: 65.26 | N9: 72.69 | O9: 36.03 | P9: 475375 | Q9: 0 | R9: 475375 | S9: 77347 | T9: 7831 | U9: 74788 | V9: 82619 | W9: 8723 | X9: 83303 | Y9: 92026 | Z9: 1232 | AA9: 47142
A10: 01 | B10: Keystone AEA 1 | C10: 4419 | D10: MFL Mar Mac | E10: 100.57 | F10: 794.9 | G10: 895.47 | H10: 2.32 | I10: 6 | J10: 0 | K10: 801 | L10: 363.32 | M10: 65.26 | N10: 72.69 | O10: 36.03 | P10: 325342 | Q10: 570 | R10: 325912 | S10: 52936 | T10: 392 | U10: 51881 | V10: 52273 | W10: 436 | X10: 57789 | Y10: 58225 | Z10: 843 | AA10: 32300
A11: 01 | B11: Keystone AEA 1 | C11: 4043 | D11: Maquoketa Valley | E11: 77.63 | F11: 671.9 | G11: 749.53 | H11: 1.94 | I11: 40 | J11: 0 | K11: 712 | L11: 363.32 | M11: 65.26 | N11: 72.69 | O11: 36.03 | P11: 272319 | Q11: 0 | R11: 272319 | S11: 44308 | T11: 2610 | U11: 43855 | V11: 46465 | W11: 2908 | X11: 48847 | Y11: 51755 | Z11: 705 | AA11: 27006
A12: 01 | B12: Keystone AEA 1 | C12: 4662 | D12: New Hampton | E12: 101.49 | F12: 992.8 | G12: 1094.29 | H12: 2.83 | I12: 71 | J12: 0.6 | K12: 1063 | L12: 363.32 | M12: 65.26 | N12: 72.69 | O12: 36.03 | P12: 397577 | Q12: 0 | R12: 397577 | S12: 64689 | T12: 4633 | U12: 64738 | V12: 69371 | W12: 5161 | X12: 72108 | Y12: 77269 | Z12: 1028 | AA12: 39427
A13: 01 | B13: Keystone AEA 1 | C13: 4774 | D13: North Fayette Valley | E13: 213.57 | F13: 1108.4 | G13: 1321.97 | H13: 3.43 | I13: 2 | J13: 0 | K13: 1110 | L13: 363.32 | M13: 65.26 | N13: 72.69 | O13: 36.03 | P13: 480298 | Q13: 0 | R13: 480298 | S13: 78148 | T13: 131 | U13: 72308 | V13: 72439 | W13: 145 | X13: 80541 | Y13: 80686 | Z13: 1246 | AA13: 47631
... A132: 09 | B132: Mississippi Bend AEA 9 | C132: 7038 | D132: Wilton | E132: 81.58 | F132: 815.4 | G132: 896.98 | H132: 1.52 | I132: 0 | J132: 0 | K132: 815 | L132: 350.08 | M132: 64.8 | N132: 70.86 | O132: 32.33 | P132: 314015 | Q132: 8267 | R132: 322282 | S132: 53024 | T132: 0 | U132: 52812 | V132: 52812 | W132: 0 | X132: 57751 | Y132: 57751 | Z132: 532 | AA132: 29699
A133: 10 | B133: Grant Wood AEA 10 | C133: 0099 | D133: Alburnett | E133: 44.3 | F133: 541.5 | G133: 585.8 | H133: 0.65 | I133: 21 | J133: 0 | K133: 563 | L133: 348.16 | M133: 64.98 | N133: 71.46 | O133: 33.08 | P133: 203952 | Q133: 0 | R133: 203952 | S133: 34629 | T133: 1365 | U133: 35219 | V133: 36584 | W133: 1501 | X133: 38731 | Y133: 40232 | Z133: 226 | AA133: 19378
A134: 10 | B134: Grant Wood AEA 10 | C134: 0234 | D134: Anamosa | E134: 114.19 | F134: 1202.2 | G134: 1316.39 | H134: 1.46 | I134: 68 | J134: 0 | K134: 1270 | L134: 348.16 | M134: 64.98 | N134: 71.46 | O134: 33.08 | P134: 458314 | Q134: 15810 | R134: 474124 | S134: 77818 | T134: 4419 | U134: 78106 | V134: 82525 | W134: 4859 | X134: 85895 | Y134: 90754 | Z134: 508 | AA134: 44979
A135: 10 | B135: Grant Wood AEA 10 | C135: 0576 | D135: Belle Plaine | E135: 58.41 | F135: 466.6 | G135: 525.01 | H135: 0.58 | I135: 7 | J135: 0 | K135: 474 | L135: 348.16 | M135: 64.98 | N135: 71.46 | O135: 33.08 | P135: 182787 | Q135: 0 | R135: 182787 | S135: 31036 | T135: 455 | U135: 30346 | V135: 30801 | W135: 500 | X135: 33372 | Y135: 33872 | Z135: 202 | AA135: 17367
A136: 10 | B136: Grant Wood AEA 10 | C136: 0609 | D136: Benton | E136: 138.17 | F136: 1475.6 | G136: 1613.77 | H136: 1.8 | I136: 140 | J136: 0.3 | K136: 1615 | L136: 348.16 | M136: 64.98 | N136: 71.46 | O136: 33.08 | P136: 561850 | Q136: 443 | R136: 562293 | S136: 95398 | T136: 9097 | U136: 95846 | V136: 104943 | W136: 10004 | X136: 105404 | Y136: 115408 | Z136: 627 | AA136: 53384
A137: 10 | B137: Grant Wood AEA 10 | C137: 1053 | D137: Cedar Rapids | E137: 2496.41 | F137: 16120.7 | G137: 18617.11 | H137: 20.69 | I137: 2073 | J137: 9.2 | K137: 18185 | L137: 348.16 | M137: 64.98 | N137: 71.46 | O137: 33.08 | P137: 6481733 | Q137: 0 | R137: 6481733 | S137: 1100546 | T137: 134704 | U137: 1046957 | V137: 1181661 | W137: 148137 | X137: 1151363 | Y137: 1299500 | Z137: 7203 | AA137: 615854
A138: 10 | B138: Grant Wood AEA 10 | C138: 1062 | D138: Center Point-Urbana | E138: 90.75 | F138: 1131.2 | G138: 1221.95 | H138: 1.36 | I138: 9 | J138: 0 | K138: 1140 | L138: 348.16 | M138: 64.98 | N138: 71.46 | O138: 33.08 | P138: 425434 | Q138: 36359 | R138: 461793 | S138: 72236 | T138: 585 | U138: 73492 | V138: 74077 | W138: 643 | X138: 80821 | Y138: 81464 | Z138: 473 | AA138: 41321
A139: 10 | B139: Grant Wood AEA 10 | C139: 1089 | D139: Central City | E139: 38.55 | F139: 411.3 | G139: 449.85 | H139: 0.5 | I139: 11 | J139: 0 | K139: 422 | L139: 348.16 | M139: 64.98 | N139: 71.46 | O139: 33.08 | P139: 156620 | Q139: 8288 | R139: 164908 | S139: 26593 | T139: 715 | U139: 26707 | V139: 27422 | W139: 786 | X139: 29370 | Y139: 30156 | Z139: 174 | AA139: 14881
A140: 10 | B140: Grant Wood AEA 10 | C140: 1221 | D140: Clear Creek-Amana | E140: 400.49 | F140: 3122.5 | G140: 3522.99 | H140: 3.91 | I140: 71 | J140: 0 | K140: 3194 | L140: 348.16 | M140: 64.98 | N140: 71.46 | O140: 33.08 | P140: 1226564 | Q140: 0 | R140: 1226564 | S140: 208261 | T140: 4614 | U140: 202932 | V140: 207546 | W140: 5074 | X140: 223169 | Y140: 228243 | Z140: 1361 | AA140: 116541
A141: 10 | B141: Grant Wood AEA 10 | C141: 1337 | D141: College Community | E141: 582.63 | F141: 5113.8 | G141: 5696.43 | H141: 6.33 | I141: 168 | J141: 0 | K141: 5282 | L141: 348.16 | M141: 64.98 | N141: 71.46 | O141: 33.08 | P141: 1983269 | Q141: 0 | R141: 1983269 | S141: 336743 | T141: 10917 | U141: 332307 | V141: 343224 | W141: 12005 | X141: 365447 | Y141: 377452 | Z141: 2204 | AA141: 188438
A142: 10 | B142: Grant Wood AEA 10 | C142: 2097 | D142: English Valleys | E142: 49.59 | F142: 443.4 | G142: 492.99 | H142: 0.55 | I142: 7 | J142: 0 | K142: 450 | L142: 348.16 | M142: 64.98 | N142: 71.46 | O142: 33.08 | P142: 171639 | Q142: 3547 | R142: 175186 | S142: 29143 | T142: 455 | U142: 28786 | V142: 29241 | W142: 500 | X142: 31657 | Y142: 32157 | Z142: 191 | AA142: 16308
A143: 10 | B143: Grant Wood AEA 10 | C143: 2766 | D143: HLV | E143: 29.8 | F143: 308 | G143: 337.8 | H143: 0.38 | I143: 5 | J143: 0 | K143: 313 | L143: 348.16 | M143: 64.98 | N143: 71.46 | O143: 33.08 | P143: 117608 | Q143: 3088 | R143: 120696 | S143: 19969 | T143: 325 | U143: 20014 | V143: 20339 | W143: 357 | X143: 22010 | Y143: 22367 | Z143: 132 | AA143: 11359
A144: 10 | B144: Grant Wood AEA 10 | C144: 2977 | D144: Highland | E144: 67.56 | F144: 553.8 | G144: 621.36 | H144: 0.69 | I144: 19 | J144: 0 | K144: 573 | L144: 348.16 | M144: 64.98 | N144: 71.46 | O144: 33.08 | P144: 216333 | Q144: 6569 | R144: 222902 | S144: 36732 | T144: 1235 | U144: 35999 | V144: 37234 | W144: 1358 | X144: 39589 | Y144: 40947 | Z144: 240 | AA144: 21146
... A326: 15 | B326: Great Prairie AEA 15 | C326: 7047 | D326: Winfield-Mt Union | E326: 40.36 | F326: 302.6 | G326: 342.96 | H326: 0.78 | I326: 0 | J326: 0 | K326: 303 | L326: 346.48 | M326: 64.96 | N326: 71.43 | O326: 34.86 | P326: 118829 | Q326: 2392 | R326: 121221 | S326: 20274 | T326: 0 | U326: 19683 | V326: 19683 | W326: 0 | X326: 21643 | Y326: 21643 | Z326: 270 | AA326: 12192

Sheet DetailByAEA
B4: AEA | C4: AEA Name | D4: Total Special Ed Weighting in Addition to 1.0 | E4: Budget Enrollment | F4: AEA Weighted Enrollment | G4: AEA Supplementary Weight for Sharing | H4: Resident Accredited Nonpublic Students | I4: Shared-Time Nonpublic Pupils Counted in Line 1.1 | J4: Total Enrollment Served - Media and Ed Services
B5: 01 | C5: Keystone AEA 1 | D5: =SUMIF(DetailByDistrict[AEA],DetailByAEA!$B5,DetailByDistrict[Total Special Ed Weighting in Addition to 1.0]) -> 4372.45 | E5: =SUMIF(DetailByDistrict[AEA],DetailByAEA!$B5,DetailByDistrict[Budget Enrollment]) -> 27489.7 | F5: =SUMIF(DetailByDistrict[AEA],DetailByAEA!$B5,DetailByDistrict[AEA Weighted Enrollment]) -> 31862.15 | G5: =SUMIF(DetailByDistrict[AEA],DetailByAEA!$B5,DetailByDistrict[AEA Supplementary Weight for Sharing]) -> 82.57 | H5: =SUMIF(DetailByDistrict[AEA],DetailByAEA!$B5,DetailByDistrict[Resident Accredited Nonpublic Students]) -> 4016 | I5: =SUMIF(DetailByDistrict[AEA],DetailByAEA!$B5,DetailByDistrict[Shared-Time Nonpublic Pupils Counted in Line 1.1]) -> 22.5 | J5: =SUMIF(DetailByDistrict[AEA],DetailByAEA!$B5,DetailByDistrict[Total Enrollment Served - Media and Ed Services]) -> 31484
B6: 05 | C6: Prairie Lakes AEA 8 | D6: =SUMIF(DetailByDistrict[AEA],DetailByAEA!$B6,DetailByDistrict[Total Special Ed Weighting in Addition to 1.0]) -> 3767.36 | E6: =SUMIF(DetailByDistrict[AEA],DetailByAEA!$B6,DetailByDistrict[Budget Enrollment]) -> 29544.2 | F6: =SUMIF(DetailByDistrict[AEA],DetailByAEA!$B6,DetailByDistrict[AEA Weighted Enrollment]) -> 33311.56 | G6: =SUMIF(DetailByDistrict[AEA],DetailByAEA!$B6,DetailByDistrict[AEA Supplementary Weight for Sharing]) -> 0 | H6: =SUMIF(DetailByDistrict[AEA],DetailByAEA!$B6,DetailByDistrict[Resident Accredited Nonpublic Students]) -> 2303 | I6: =SUMIF(DetailByDistrict[AEA],DetailByAEA!$B6,DetailByDistrict[Shared-Time Nonpublic Pupils Counted in Line 1.1]) -> 31.2 | J6: =SUMIF(DetailByDistrict[AEA],DetailByAEA!$B6,DetailByDistrict[Total Enrollment Served - Media and Ed Services]) -> 31817
B7: 07 | C7: Central Rivers | D7: =SUMIF(DetailByDistrict[AEA],DetailByAEA!$B7,DetailByDistrict[Total Special Ed Weighting in Addition to 1.0]) -> 9429.69 | E7: =SUMIF(DetailByDistrict[AEA],DetailByAEA!$B7,DetailByDistrict[Budget Enrollment]) -> 60257.5 | F7: =SUMIF(DetailByDistrict[AEA],DetailByAEA!$B7,DetailByDistrict[AEA Weighted Enrollment]) -> 69687.19 | G7: =SUMIF(DetailByDistrict[AEA],DetailByAEA!$B7,DetailByDistrict[AEA Supplementary Weight for Sharing]) -> 85.12 | H7: =SUMIF(DetailByDistrict[AEA],DetailByAEA!$B7,DetailByDistrict[Resident Accredited Nonpublic Students]) -> 3878 | I7: =SUMIF(DetailByDistrict[AEA],DetailByAEA!$B7,DetailByDistrict[Shared-Time Nonpublic Pupils Counted in Line 1.1]) -> 48.5 | J7: =SUMIF(DetailByDistrict[AEA],DetailByAEA!$B7,DetailByDistrict[Total Enrollment Served - Media and Ed Services]) -> 64088
B8: 09 | C8: Mississippi Bend AEA 9 | D8: =SUMIF(DetailByDistrict[AEA],DetailByAEA!$B8,DetailByDistrict[Total Special Ed Weighting in Addition to 1.0]) -> 6726.71 | E8: =SUMIF(DetailByDistrict[AEA],DetailByAEA!$B8,DetailByDistrict[Budget Enrollment]) -> 43736.3 | F8: =SUMIF(DetailByDistrict[AEA],DetailByAEA!$B8,DetailByDistrict[AEA Weighted Enrollment]) -> 50463.01 | G8: =SUMIF(DetailByDistrict[AEA],DetailByAEA!$B8,DetailByDistrict[AEA Supplementary Weight for Sharing]) -> 85.69 | H8: =SUMIF(DetailByDistrict[AEA],DetailByAEA!$B8,DetailByDistrict[Resident Accredited Nonpublic Students]) -> 3794 | I8: =SUMIF(DetailByDistrict[AEA],DetailByAEA!$B8,DetailByDistrict[Shared-Time Nonpublic Pupils Counted in Line 1.1]) -> 7.1 | J8: =SUMIF(DetailByDistrict[AEA],DetailByAEA!$B8,DetailByDistrict[Total Enrollment Served - Media and Ed Services]) -> 47523
B9: 10 | C9: Grant Wood AEA 10 | D9: =SUMIF(DetailByDistrict[AEA],DetailByAEA!$B9,DetailByDistrict[Total Special Ed Weighting in Addition to 1.0]) -> 8534.33 | E9: =SUMIF(DetailByDistrict[AEA],DetailByAEA!$B9,DetailByDistrict[Budget Enrollment]) -> 68981 | F9: =SUMIF(DetailByDistrict[AEA],DetailByAEA!$B9,DetailByDistrict[AEA Weighted Enrollment]) -> 77515.33 | G9: =SUMIF(DetailByDistrict[AEA],DetailByAEA!$B9,DetailByDistrict[AEA Supplementary Weight for Sharing]) -> 86.18 | H9: =SUMIF(DetailByDistrict[AEA],DetailByAEA!$B9,DetailByDistrict[Resident Accredited Nonpublic Students]) -> 5294 | I9: =SUMIF(DetailByDistrict[AEA],DetailByAEA!$B9,DetailByDistrict[Shared-Time Nonpublic Pupils Counted in Line 1.1]) -> 25 | J9: =SUMIF(DetailByDistrict[AEA],DetailByAEA!$B9,DetailByDistrict[Total Enrollment Served - Media and Ed Services]) -> 74252
B10: 11 | C10: Heartland AEA 11 | D10: =SUMIF(DetailByDistrict[AEA],DetailByAEA!$B10,DetailByDistrict[Total Special Ed Weighting in Addition to 1.0]) -> 19560.83 | E10: =SUMIF(DetailByDistrict[AEA],DetailByAEA!$B10,DetailByDistrict[Budget Enrollment]) -> 142402.9 | F10: =SUMIF(DetailByDistrict[AEA],DetailByAEA!$B10,DetailByDistrict[AEA Weighted Enrollment]) -> 161963.73 | G10: =SUMIF(DetailByDistrict[AEA],DetailByAEA!$B10,DetailByDistrict[AEA Supplementary Weight for Sharing]) -> 0 | H10: =SUMIF(DetailByDistrict[AEA],DetailByAEA!$B10,DetailByDistrict[Resident Accredited Nonpublic Students]) -> 11598 | I10: =SUMIF(DetailByDistrict[AEA],DetailByAEA!$B10,DetailByDistrict[Shared-Time Nonpublic Pupils Counted in Line 1.1]) -> 100.2 | J10: =SUMIF(DetailByDistrict[AEA],DetailByAEA!$B10,DetailByDistrict[Total Enrollment Served - Media and Ed Services]) -> 153903
B11: 12 | C11: Northwest AEA | D11: =SUMIF(DetailByDistrict[AEA],DetailByAEA!$B11,DetailByDistrict[Total Special Ed Weighting in Addition to 1.0]) -> 5909.5 | E11: =SUMIF(DetailByDistrict[AEA],DetailByAEA!$B11,DetailByDistrict[Budget Enrollment]) -> 39080.5 | F11: =SUMIF(DetailByDistrict[AEA],DetailByAEA!$B11,DetailByDistrict[AEA Weighted Enrollment]) -> 44990 | G11: =SUMIF(DetailByDistrict[AEA],DetailByAEA!$B11,DetailByDistrict[AEA Supplementary Weight for Sharing]) -> 84.33 | H11: =SUMIF(DetailByDistrict[AEA],DetailByAEA!$B11,DetailByDistrict[Resident Accredited Nonpublic Students]) -> 5777 | I11: =SUMIF(DetailByDistrict[AEA],DetailByAEA!$B11,DetailByDistrict[Shared-Time Nonpublic Pupils Counted in Line 1.1]) -> 45.8 | J11: =SUMIF(DetailByDistrict[AEA],DetailByAEA!$B11,DetailByDistrict[Total Enrollment Served - Media and Ed Services]) -> 44808
B12: 13 | C12: Green Hills AEA 13 | D12: =SUMIF(DetailByDistrict[AEA],DetailByAEA!$B12,DetailByDistrict[Total Special Ed Weighting in Addition to 1.0]) -> 6007.66 | E12: =SUMIF(DetailByDistrict[AEA],DetailByAEA!$B12,DetailByDistrict[Budget Enrollment]) -> 36065.8 | F12: =SUMIF(DetailByDistrict[AEA],DetailByAEA!$B12,DetailByDistrict[AEA Weighted Enrollment]) -> 42073.46 | G12: =SUMIF(DetailByDistrict[AEA],DetailByAEA!$B12,DetailByDistrict[AEA Supplementary Weight for Sharing]) -> 85.93 | H12: =SUMIF(DetailByDistrict[AEA],DetailByAEA!$B12,DetailByDistrict[Resident Accredited Nonpublic Students]) -> 1226 | I12: =SUMIF(DetailByDistrict[AEA],DetailByAEA!$B12,DetailByDistrict[Shared-Time Nonpublic Pupils Counted in Line 1.1]) -> 4 | J12: =SUMIF(DetailByDistrict[AEA],DetailByAEA!$B12,DetailByDistrict[Total Enrollment Served - Media and Ed Services]) -> 37286
B13: 15 | C13: Great Prairie AEA 15 | D13: =SUMIF(DetailByDistrict[AEA],DetailByAEA!$B13,DetailByDistrict[Total Special Ed Weighting in Addition to 1.0]) -> 4803.81 | E13: =SUMIF(DetailByDistrict[AEA],DetailByAEA!$B13,DetailByDistrict[Budget Enrollment]) -> 33107.5 | F13: =SUMIF(DetailByDistrict[AEA],DetailByAEA!$B13,DetailByDistrict[AEA Weighted Enrollment]) -> 37911.31 | G13: =SUMIF(DetailByDistrict[AEA],DetailByAEA!$B13,DetailByDistrict[AEA Supplementary Weight for Sharing]) -> 86.59 | H13: =SUMIF(DetailByDistrict[AEA],DetailByAEA!$B13,DetailByDistrict[Resident Accredited Nonpublic Students]) -> 1470 | I13: =SUMIF(DetailByDistrict[AEA],DetailByAEA!$B13,DetailByDistrict[Shared-Time Nonpublic Pupils Counted in Line 1.1]) -> 9.2 | J13: =SUMIF(DetailByDistrict[AEA],DetailByAEA!$B13,DetailByDistrict[Total Enrollment Served - Media and Ed Services]) -> 34570
D14: =SUM(D5:D13) -> 69112.34 | E14: =SUM(E5:E13) -> 480665.4 | F14: =SUM(F5:F13) -> 549777.74 | G14: =SUM(G5:G13) -> 596.41 | H14: =SUM(H5:H13) -> 39356 | I14: =SUM(I5:I13) -> 293.5 | J14: =SUM(J5:J13) -> 519731
B16: AEA | C16: AEA Name | D16: AEA Special Ed Support Cost Per Pupil | E16: AEA Media Cost Per Pupil | F16: AEA Ed Services Cost Per Pupil | G16: AEA Teacher Salary Supplement District Cost Per Pupil
B17: 01 | C17: Keystone AEA 1 | D17: =_xlfn.MINIFS(DetailByDistrict[AEA Special Ed Support Cost Per Pupil],DetailByDistrict[AEA],$B17) -> 363.32 | E17: =_xlfn.MINIFS(DetailByDistrict[AEA Media Cost Per Pupil],DetailByDistrict[AEA],$B17) -> 65.26 | F17: =_xlfn.MINIFS(DetailByDistrict[AEA Ed Services Cost Per Pupil],DetailByDistrict[AEA],$B17) -> 72.69 | G17: =_xlfn.MINIFS(DetailByDistrict[AEA Teacher Salary Supplement District Cost Per Pupil],DetailByDistrict[AEA],$B17) -> 36.03
B18: 05 | C18: Prairie Lakes AEA 8 | D18: =_xlfn.MINIFS(DetailByDistrict[AEA Special Ed Support Cost Per Pupil],DetailByDistrict[AEA],$B18) -> 359.07 | E18: =_xlfn.MINIFS(DetailByDistrict[AEA Media Cost Per Pupil],DetailByDistrict[AEA],$B18) -> 65.34 | F18: =_xlfn.MINIFS(DetailByDistrict[AEA Ed Services Cost Per Pupil],DetailByDistrict[AEA],$B18) -> 73.16 | G18: =_xlfn.MINIFS(DetailByDistrict[AEA Teacher Salary Supplement District Cost Per Pupil],DetailByDistrict[AEA],$B18) -> 37.99
B19: 07 | C19: Central Rivers | D19: =_xlfn.MINIFS(DetailByDistrict[AEA Special Ed Support Cost Per Pupil],DetailByDistrict[AEA],$B19) -> 352.44 | E19: =_xlfn.MINIFS(DetailByDistrict[AEA Media Cost Per Pupil],DetailByDistrict[AEA],$B19) -> 65.29 | F19: =_xlfn.MINIFS(DetailByDistrict[AEA Ed Services Cost Per Pupil],DetailByDistrict[AEA],$B19) -> 72.78 | G19: =_xlfn.MINIFS(DetailByDistrict[AEA Teacher Salary Supplement District Cost Per Pupil],DetailByDistrict[AEA],$B19) -> 43.26
B20: 09 | C20: Mississippi Bend AEA 9 | D20: =_xlfn.MINIFS(DetailByDistrict[AEA Special Ed Support Cost Per Pupil],DetailByDistrict[AEA],$B20) -> 350.08 | E20: =_xlfn.MINIFS(DetailByDistrict[AEA Media Cost Per Pupil],DetailByDistrict[AEA],$B20) -> 64.8 | F20: =_xlfn.MINIFS(DetailByDistrict[AEA Ed Services Cost Per Pupil],DetailByDistrict[AEA],$B20) -> 70.86 | G20: =_xlfn.MINIFS(DetailByDistrict[AEA Teacher Salary Supplement District Cost Per Pupil],DetailByDistrict[AEA],$B20) -> 32.33
B21: 10 | C21: Grant Wood AEA 10 | D21: =_xlfn.MINIFS(DetailByDistrict[AEA Special Ed Support Cost Per Pupil],DetailByDistrict[AEA],$B21) -> 348.16 | E21: =_xlfn.MINIFS(DetailByDistrict[AEA Media Cost Per Pupil],DetailByDistrict[AEA],$B21) -> 64.98 | F21: =_xlfn.MINIFS(DetailByDistrict[AEA Ed Services Cost Per Pupil],DetailByDistrict[AEA],$B21) -> 71.46 | G21: =_xlfn.MINIFS(DetailByDistrict[AEA Teacher Salary Supplement District Cost Per Pupil],DetailByDistrict[AEA],$B21) -> 33.08
B22: 11 | C22: Heartland AEA 11 | D22: =_xlfn.MINIFS(DetailByDistrict[AEA Special Ed Support Cost Per Pupil],DetailByDistrict[AEA],$B22) -> 341.06 | E22: =_xlfn.MINIFS(DetailByDistrict[AEA Media Cost Per Pupil],DetailByDistrict[AEA],$B22) -> 64.86 | F22: =_xlfn.MINIFS(DetailByDistrict[AEA Ed Services Cost Per Pupil],DetailByDistrict[AEA],$B22) -> 71.28 | G22: =_xlfn.MINIFS(DetailByDistrict[AEA Teacher Salary Supplement District Cost Per Pupil],DetailByDistrict[AEA],$B22) -> 29.31
B23: 12 | C23: Northwest AEA | D23: =_xlfn.MINIFS(DetailByDistrict[AEA Special Ed Support Cost Per Pupil],DetailByDistrict[AEA],$B23) -> 355.7 | E23: =_xlfn.MINIFS(DetailByDistrict[AEA Media Cost Per Pupil],DetailByDistrict[AEA],$B23) -> 65.27 | F23: =_xlfn.MINIFS(DetailByDistrict[AEA Ed Services Cost Per Pupil],DetailByDistrict[AEA],$B23) -> 73.06 | G23: =_xlfn.MINIFS(DetailByDistrict[AEA Teacher Salary Supplement District Cost Per Pupil],DetailByDistrict[AEA],$B23) -> 35.87
B24: 13 | C24: Green Hills AEA 13 | D24: =_xlfn.MINIFS(DetailByDistrict[AEA Special Ed Support Cost Per Pupil],DetailByDistrict[AEA],$B24) -> 349.12 | E24: =_xlfn.MINIFS(DetailByDistrict[AEA Media Cost Per Pupil],DetailByDistrict[AEA],$B24) -> 64.99 | F24: =_xlfn.MINIFS(DetailByDistrict[AEA Ed Services Cost Per Pupil],DetailByDistrict[AEA],$B24) -> 71.86 | G24: =_xlfn.MINIFS(DetailByDistrict[AEA Teacher Salary Supplement District Cost Per Pupil],DetailByDistrict[AEA],$B24) -> 35.85
B25: 15 | C25: Great Prairie AEA 15 | D25: =_xlfn.MINIFS(DetailByDistrict[AEA Special Ed Support Cost Per Pupil],DetailByDistrict[AEA],$B25) -> 346.48 | E25: =_xlfn.MINIFS(DetailByDistrict[AEA Media Cost Per Pupil],DetailByDistrict[AEA],$B25) -> 64.96 | F25: =_xlfn.MINIFS(DetailByDistrict[AEA Ed Services Cost Per Pupil],DetailByDistrict[AEA],$B25) -> 71.43 | G25: =_xlfn.MINIFS(DetailByDistrict[AEA Teacher Salary Supplement District Cost Per Pupil],DetailByDistrict[AEA],$B25) -> 34.86
B27: AEA | C27: AEA Name | D27: AEA Special Ed Support District Cost without Adjustment | E27: AEA Special Ed Support Adjustment | F27: Special Education Total Cost | G27: District/AEA Statewide State Aid Reduction | H27: Total Special Ed Funding Removing Reduction Including Adjustment
B28: 01 | C28: Keystone AEA 1 | D28: =SUMIF(DetailByDistrict[AEA],DetailByAEA!$B28,DetailByDistrict[AEA Special Ed Support District Cost without Adjustment]) -> 11576155 | E28: =SUMIF(DetailByDistrict[AEA],DetailByAEA!$B28,DetailByDistrict[AEA Special Ed Support Adjustment]) -> 47018 | F28: =SUMIF(DetailByDistrict[AEA],DetailByAEA!$B28,DetailByDistrict[Special Education Total Cost]) -> 11623173 | G28: =SUMIF(DetailByDistrict[AEA],DetailByAEA!$B28,DetailByDistrict[District/AEA Statewide State Aid Reduction]) -> 1883523 | H28: =F28-G28 -> 9739650
B29: 05 | C29: Prairie Lakes AEA 8 | D29: =SUMIF(DetailByDistrict[AEA],DetailByAEA!$B29,DetailByDistrict[AEA Special Ed Support District Cost without Adjustment]) -> 11961182 | E29: =SUMIF(DetailByDistrict[AEA],DetailByAEA!$B29,DetailByDistrict[AEA Special Ed Support Adjustment]) -> 167396 | F29: =SUMIF(DetailByDistrict[AEA],DetailByAEA!$B29,DetailByDistrict[Special Education Total Cost]) -> 12128578 | G29: =SUMIF(DetailByDistrict[AEA],DetailByAEA!$B29,DetailByDistrict[District/AEA Statewide State Aid Reduction]) -> 1969206 | H29: =F29-G29 -> 10159372
B30: 07 | C30: Central Rivers | D30: =SUMIF(DetailByDistrict[AEA],DetailByAEA!$B30,DetailByDistrict[AEA Special Ed Support District Cost without Adjustment]) -> 24560553 | E30: =SUMIF(DetailByDistrict[AEA],DetailByAEA!$B30,DetailByDistrict[AEA Special Ed Support Adjustment]) -> 206737 | F30: =SUMIF(DetailByDistrict[AEA],DetailByAEA!$B30,DetailByDistrict[Special Education Total Cost]) -> 24767290 | G30: =SUMIF(DetailByDistrict[AEA],DetailByAEA!$B30,DetailByDistrict[District/AEA Statewide State Aid Reduction]) -> 4119546 | H30: =F30-G30 -> 20647744
B31: 09 | C31: Mississippi Bend AEA 9 | D31: =SUMIF(DetailByDistrict[AEA],DetailByAEA!$B31,DetailByDistrict[AEA Special Ed Support District Cost without Adjustment]) -> 17666093 | E31: =SUMIF(DetailByDistrict[AEA],DetailByAEA!$B31,DetailByDistrict[AEA Special Ed Support Adjustment]) -> 84238 | F31: =SUMIF(DetailByDistrict[AEA],DetailByAEA!$B31,DetailByDistrict[Special Education Total Cost]) -> 17750331 | G31: =SUMIF(DetailByDistrict[AEA],DetailByAEA!$B31,DetailByDistrict[District/AEA Statewide State Aid Reduction]) -> 2983110 | H31: =F31-G31 -> 14767221
B32: 10 | C32: Grant Wood AEA 10 | D32: =SUMIF(DetailByDistrict[AEA],DetailByAEA!$B32,DetailByDistrict[AEA Special Ed Support District Cost without Adjustment]) -> 26987736 | E32: =SUMIF(DetailByDistrict[AEA],DetailByAEA!$B32,DetailByDistrict[AEA Special Ed Support Adjustment]) -> 140219 | F32: =SUMIF(DetailByDistrict[AEA],DetailByAEA!$B32,DetailByDistrict[Special Education Total Cost]) -> 27127955 | G32: =SUMIF(DetailByDistrict[AEA],DetailByAEA!$B32,DetailByDistrict[District/AEA Statewide State Aid Reduction]) -> 4582301 | H32: =F32-G32 -> 22545654
B33: 11 | C33: Heartland AEA 11 | D33: =SUMIF(DetailByDistrict[AEA],DetailByAEA!$B33,DetailByDistrict[AEA Special Ed Support District Cost without Adjustment]) -> 55239348 | E33: =SUMIF(DetailByDistrict[AEA],DetailByAEA!$B33,DetailByDistrict[AEA Special Ed Support Adjustment]) -> 116312 | F33: =SUMIF(DetailByDistrict[AEA],DetailByAEA!$B33,DetailByDistrict[Special Education Total Cost]) -> 55355660 | G33: =SUMIF(DetailByDistrict[AEA],DetailByAEA!$B33,DetailByDistrict[District/AEA Statewide State Aid Reduction]) -> 9574454 | H33: =F33-G33 -> 45781206
B34: 12 | C34: Northwest AEA | D34: =SUMIF(DetailByDistrict[AEA],DetailByAEA!$B34,DetailByDistrict[AEA Special Ed Support District Cost without Adjustment]) -> 16002942 | E34: =SUMIF(DetailByDistrict[AEA],DetailByAEA!$B34,DetailByDistrict[AEA Special Ed Support Adjustment]) -> 106969 | F34: =SUMIF(DetailByDistrict[AEA],DetailByAEA!$B34,DetailByDistrict[Special Education Total Cost]) -> 16109911 | G34: =SUMIF(DetailByDistrict[AEA],DetailByAEA!$B34,DetailByDistrict[District/AEA Statewide State Aid Reduction]) -> 2659575 | H34: =F34-G34 -> 13450336
B35: 13 | C35: Green Hills AEA 13 | D35: =SUMIF(DetailByDistrict[AEA],DetailByAEA!$B35,DetailByDistrict[AEA Special Ed Support District Cost without Adjustment]) -> 14688682 | E35: =SUMIF(DetailByDistrict[AEA],DetailByAEA!$B35,DetailByDistrict[AEA Special Ed Support Adjustment]) -> 172236 | F35: =SUMIF(DetailByDistrict[AEA],DetailByAEA!$B35,DetailByDistrict[Special Education Total Cost]) -> 14860918 | G35: =SUMIF(DetailByDistrict[AEA],DetailByAEA!$B35,DetailByDistrict[District/AEA Statewide State Aid Reduction]) -> 2487165 | H35: =F35-G35 -> 12373753
B36: 15 | C36: Great Prairie AEA 15 | D36: =SUMIF(DetailByDistrict[AEA],DetailByAEA!$B36,DetailByDistrict[AEA Special Ed Support District Cost without Adjustment]) -> 13135510 | E36: =SUMIF(DetailByDistrict[AEA],DetailByAEA!$B36,DetailByDistrict[AEA Special Ed Support Adjustment]) -> 131165 | F36: =SUMIF(DetailByDistrict[AEA],DetailByAEA!$B36,DetailByDistrict[Special Education Total Cost]) -> 13266675 | G36: =SUMIF(DetailByDistrict[AEA],DetailByAEA!$B36,DetailByDistrict[District/AEA Statewide State Aid Reduction]) -> 2241120 | H36: =F36-G36 -> 11025555
D37: =SUM(D28:D36) -> 191818201 | E37: =SUM(E28:E36) -> 1172290 | F37: =SUM(F28:F36) -> 192990491 | G37: =SUM(G28:G36) -> 32500000 | H37: =SUM(H28:H36) -> 160490491
B39: AEA | C39: AEA Name | D39: AEA Media Services Nonpublic Portion | E39: District Media Services | F39: Total Media Services | G39: AEA Educational Services Nonpublic Portion | H39: District Educational Services | I39: Total Educational Services
B40: 01 | C40: Keystone AEA 1 | D40: =SUMIF(DetailByDistrict[AEA],DetailByAEA!$B40,DetailByDistrict[AEA Media Services Nonpublic Portion]) -> 262085 | E40: =SUMIF(DetailByDistrict[AEA],DetailByAEA!$B40,DetailByDistrict[District Media Services]) -> 1792562 | F40: =SUMIF(DetailByDistrict[AEA],DetailByAEA!$B40,DetailByDistrict[Total Media Services]) -> 2054647 | G40: =SUMIF(DetailByDistrict[AEA],DetailByAEA!$B40,DetailByDistrict[AEA Educational Services Nonpublic Portion]) -> 291923 | H40: =SUMIF(DetailByDistrict[AEA],DetailByAEA!$B40,DetailByDistrict[District Educational Services]) -> 1996651 | I40: =SUMIF(DetailByDistrict[AEA],DetailByAEA!$B40,DetailByDistrict[Total Educational Services]) -> 2288574
B41: 05 | C41: Prairie Lakes AEA 8 | D41: =SUMIF(DetailByDistrict[AEA],DetailByAEA!$B41,DetailByDistrict[AEA Media Services Nonpublic Portion]) -> 150479 | E41: =SUMIF(DetailByDistrict[AEA],DetailByAEA!$B41,DetailByDistrict[District Media Services]) -> 1928444 | F41: =SUMIF(DetailByDistrict[AEA],DetailByAEA!$B41,DetailByDistrict[Total Media Services]) -> 2078923 | G41: =SUMIF(DetailByDistrict[AEA],DetailByAEA!$B41,DetailByDistrict[AEA Educational Services Nonpublic Portion]) -> 168486 | H41: =SUMIF(DetailByDistrict[AEA],DetailByAEA!$B41,DetailByDistrict[District Educational Services]) -> 2159246 | I41: =SUMIF(DetailByDistrict[AEA],DetailByAEA!$B41,DetailByDistrict[Total Educational Services]) -> 2327732
B42: 07 | C42: Central Rivers | D42: =SUMIF(DetailByDistrict[AEA],DetailByAEA!$B42,DetailByDistrict[AEA Media Services Nonpublic Portion]) -> 253193 | E42: =SUMIF(DetailByDistrict[AEA],DetailByAEA!$B42,DetailByDistrict[District Media Services]) -> 3931114 | F42: =SUMIF(DetailByDistrict[AEA],DetailByAEA!$B42,DetailByDistrict[Total Media Services]) -> 4184307 | G42: =SUMIF(DetailByDistrict[AEA],DetailByAEA!$B42,DetailByDistrict[AEA Educational Services Nonpublic Portion]) -> 282243 | H42: =SUMIF(DetailByDistrict[AEA],DetailByAEA!$B42,DetailByDistrict[District Educational Services]) -> 4382083 | I42: =SUMIF(DetailByDistrict[AEA],DetailByAEA!$B42,DetailByDistrict[Total Educational Services]) -> 4664326
B43: 09 | C43: Mississippi Bend AEA 9 | D43: =SUMIF(DetailByDistrict[AEA],DetailByAEA!$B43,DetailByDistrict[AEA Media Services Nonpublic Portion]) -> 245851 | E43: =SUMIF(DetailByDistrict[AEA],DetailByAEA!$B43,DetailByDistrict[District Media Services]) -> 2833641 | F43: =SUMIF(DetailByDistrict[AEA],DetailByAEA!$B43,DetailByDistrict[Total Media Services]) -> 3079492 | G43: =SUMIF(DetailByDistrict[AEA],DetailByAEA!$B43,DetailByDistrict[AEA Educational Services Nonpublic Portion]) -> 268841 | H43: =SUMIF(DetailByDistrict[AEA],DetailByAEA!$B43,DetailByDistrict[District Educational Services]) -> 3098639 | I43: =SUMIF(DetailByDistrict[AEA],DetailByAEA!$B43,DetailByDistrict[Total Educational Services]) -> 3367480
B44: 10 | C44: Grant Wood AEA 10 | D44: =SUMIF(DetailByDistrict[AEA],DetailByAEA!$B44,DetailByDistrict[AEA Media Services Nonpublic Portion]) -> 344008 | E44: =SUMIF(DetailByDistrict[AEA],DetailByAEA!$B44,DetailByDistrict[District Media Services]) -> 4480891 | F44: =SUMIF(DetailByDistrict[AEA],DetailByAEA!$B44,DetailByDistrict[Total Media Services]) -> 4824899 | G44: =SUMIF(DetailByDistrict[AEA],DetailByAEA!$B44,DetailByDistrict[AEA Educational Services Nonpublic Portion]) -> 378309 | H44: =SUMIF(DetailByDistrict[AEA],DetailByAEA!$B44,DetailByDistrict[District Educational Services]) -> 4927738 | I44: =SUMIF(DetailByDistrict[AEA],DetailByAEA!$B44,DetailByDistrict[Total Educational Services]) -> 5306047
B45: 11 | C45: Heartland AEA 11 | D45: =SUMIF(DetailByDistrict[AEA],DetailByAEA!$B45,DetailByDistrict[AEA Media Services Nonpublic Portion]) -> 752248 | E45: =SUMIF(DetailByDistrict[AEA],DetailByAEA!$B45,DetailByDistrict[District Media Services]) -> 9229904 | F45: =SUMIF(DetailByDistrict[AEA],DetailByAEA!$B45,DetailByDistrict[Total Media Services]) -> 9982152 | G45: =SUMIF(DetailByDistrict[AEA],DetailByAEA!$B45,DetailByDistrict[AEA Educational Services Nonpublic Portion]) -> 826706 | H45: =SUMIF(DetailByDistrict[AEA],DetailByAEA!$B45,DetailByDistrict[District Educational Services]) -> 10143500 | I45: =SUMIF(DetailByDistrict[AEA],DetailByAEA!$B45,DetailByDistrict[Total Educational Services]) -> 10970206
B46: 12 | C46: Northwest AEA | D46: =SUMIF(DetailByDistrict[AEA],DetailByAEA!$B46,DetailByDistrict[AEA Media Services Nonpublic Portion]) -> 377069 | E46: =SUMIF(DetailByDistrict[AEA],DetailByAEA!$B46,DetailByDistrict[District Media Services]) -> 2547549 | F46: =SUMIF(DetailByDistrict[AEA],DetailByAEA!$B46,DetailByDistrict[Total Media Services]) -> 2924618 | G46: =SUMIF(DetailByDistrict[AEA],DetailByAEA!$B46,DetailByDistrict[AEA Educational Services Nonpublic Portion]) -> 422065 | H46: =SUMIF(DetailByDistrict[AEA],DetailByAEA!$B46,DetailByDistrict[District Educational Services]) -> 2851607 | I46: =SUMIF(DetailByDistrict[AEA],DetailByAEA!$B46,DetailByDistrict[Total Educational Services]) -> 3273672
...

Sheet Special Education Breakdown
I1: Line 4.49 A&L | J1: Calculated | K1: Line 5.16 A&L | L1: Calculated | M1: Line 4.54 A&L | N1: Calculated | O1: Calculated | Q1: Calculated | R1: Line 4.54 A&L | S1: Calculated | T1: Calculated | U1: Calculated | W1: Calculated | X1: Calculated
I2: Column A | J2: Column B | K2: Column C | L2: Column D | M2: Column E | N2: Column F | O2: Column G | Q2: Column H | R2: Column I | S2: Column J | T2: Column K | U2: Column L | W2: Column M | X2: Column N
L3: B-C | N3: A-C+E | O3: A-C+E *10% | S3: H+I | T3: D-G | U3: J+K | W3: G/F | X3: L/F
A4: FiscalYear | B4: AEA To Generate Funds | C4: AEA District Chose to Receive Services From | D4: Dist | E4: DistSub1 | F4: DistSub2 | G4: DistrictNumber | H4: Label | I4: AEA Special Ed Support District Cost Formula Generated | J4: State Aid Portion Special Ed | K4: AEA Statewide State Aid Reduction | L4: State Aid Special Ed Minus Reduction | M4: AEA Special Ed Support Adjustment | N4: Total Special Ed Funding Removing Reduction Including Adjustment | O4: 10% Portion District Can Keep from State Aid portion | Q4: =Breakdown[[#Headers],[Special Education Property Tax Portion]] -> Special Education Property Tax Portion | R4: =Breakdown[[#Headers],[AEA Special Ed Support Adjustment]] -> AEA Special Ed Support Adjustment | S4: Total Property Tax Portion District Pays AEA | T4: State Aid Portion District Sends to AEA | U4: Total Payment from District to AEA | W4: District Percentage ability to Retain | X4: District Percentage to Pay to AEAs
A5: 2026 | B5: 11 | C5: 11 | D5: 0018 | G5: 0018 | H5: Adair-Casey | I5: =INDEX(Breakdown[],MATCH($D5,Breakdown[Dist],0),MATCH(I$4,Breakdown[#Headers],0)) -> 113866 | J5: =INDEX(Breakdown[],MATCH($D5,Breakdown[Dist],0),MATCH(J$4,Breakdown[#Headers],0)) -> 92145 | K5: =INDEX(Breakdown[],MATCH($D5,Breakdown[Dist],0),MATCH(K$4,Breakdown[#Headers],0)) -> 19736 | L5: =INDEX(Breakdown[],MATCH($D5,Breakdown[Dist],0),MATCH(L$4,Breakdown[#Headers],0)) -> 72409 | M5: =INDEX(Breakdown[],MATCH($D5,Breakdown[Dist],0),MATCH(M$4,Breakdown[#Headers],0)) -> 1802 | N5: =I5-K5+M5 -> 95932 | O5: =ROUND(N5*0.1,0) -> 9593 | Q5: =INDEX(Breakdown[],MATCH($D5,Breakdown[Dist],0),MATCH(Q$4,Breakdown[#Headers],0)) -> 21721 | R5: =INDEX(Breakdown[],MATCH($D5,Breakdown[Dist],0),MATCH(R$4,Breakdown[#Headers],0)) -> 1802 | S5: =SUM(Q5:R5) -> 23523 | T5: =L5-O5 -> 62816 | U5: =SUM(S5:T5) -> 86339 | W5: =O5/N5 -> 0.099997915 | X5: =U5/N5 -> 0.90000208
A6: 2026 | B6: 11 | C6: 11 | D6: 0027 | G6: 0027 | H6: Adel-Desoto-Minburn | I6: =INDEX(Breakdown[],MATCH($D6,Breakdown[Dist],0),MATCH(I$4,Breakdown[#Headers],0)) -> 828554 | J6: =INDEX(Breakdown[],MATCH($D6,Breakdown[Dist],0),MATCH(J$4,Breakdown[#Headers],0)) -> 670501 | K6: =INDEX(Breakdown[],MATCH($D6,Breakdown[Dist],0),MATCH(K$4,Breakdown[#Headers],0)) -> 143611 | L6: =INDEX(Breakdown[],MATCH($D6,Breakdown[Dist],0),MATCH(L$4,Breakdown[#Headers],0)) -> 526890 | M6: =INDEX(Breakdown[],MATCH($D6,Breakdown[Dist],0),MATCH(M$4,Breakdown[#Headers],0)) -> 0 | N6: =I6-K6+M6 -> 684943 | O6: =ROUND(N6*0.1,0) -> 68494 | Q6: =INDEX(Breakdown[],MATCH($D6,Breakdown[Dist],0),MATCH(Q$4,Breakdown[#Headers],0)) -> 158053 | R6: =INDEX(Breakdown[],MATCH($D6,Breakdown[Dist],0),MATCH(R$4,Breakdown[#Headers],0)) -> 0 | S6: =SUM(Q6:R6) -> 158053 | T6: =L6-O6 -> 458396 | U6: =SUM(S6:T6) -> 616449 | W6: =O6/N6 -> 0.099999562 | X6: =U6/N6 -> 0.90000044
A7: 2026 | B7: 07 | C7: 07 | D7: 0009 | G7: 0009 | H7: AGWSR | I7: =INDEX(Breakdown[],MATCH($D7,Breakdown[Dist],0),MATCH(I$4,Breakdown[#Headers],0)) -> 281388 | J7: =INDEX(Breakdown[],MATCH($D7,Breakdown[Dist],0),MATCH(J$4,Breakdown[#Headers],0)) -> 220358 | K7: =INDEX(Breakdown[],MATCH($D7,Breakdown[Dist],0),MATCH(K$4,Breakdown[#Headers],0)) -> 47198 | L7: =INDEX(Breakdown[],MATCH($D7,Breakdown[Dist],0),MATCH(L$4,Breakdown[#Headers],0)) -> 173160 | M7: =INDEX(Breakdown[],MATCH($D7,Breakdown[Dist],0),MATCH(M$4,Breakdown[#Headers],0)) -> 4081 | N7: =I7-K7+M7 -> 238271 | O7: =ROUND(N7*0.1,0) -> 23827 | Q7: =INDEX(Breakdown[],MATCH($D7,Breakdown[Dist],0),MATCH(Q$4,Breakdown[#Headers],0)) -> 61030 | R7: =INDEX(Breakdown[],MATCH($D7,Breakdown[Dist],0),MATCH(R$4,Breakdown[#Headers],0)) -> 4081 | S7: =SUM(Q7:R7) -> 65111 | T7: =L7-O7 -> 149333 | U7: =SUM(S7:T7) -> 214444 | W7: =O7/N7 -> 0.09999958 | X7: =U7/N7 -> 0.90000042
A8: 2026 | B8: 13 | C8: 13 | D8: 0441 | G8: 0441 | H8: AHSTW | I8: =INDEX(Breakdown[],MATCH($D8,Breakdown[Dist],0),MATCH(I$4,Breakdown[#Headers],0)) -> 311331 | J8: =INDEX(Breakdown[],MATCH($D8,Breakdown[Dist],0),MATCH(J$4,Breakdown[#Headers],0)) -> 246126 | K8: =INDEX(Breakdown[],MATCH($D8,Breakdown[Dist],0),MATCH(K$4,Breakdown[#Headers],0)) -> 52716 | L8: =INDEX(Breakdown[],MATCH($D8,Breakdown[Dist],0),MATCH(L$4,Breakdown[#Headers],0)) -> 193410 | M8: =INDEX(Breakdown[],MATCH($D8,Breakdown[Dist],0),MATCH(M$4,Breakdown[#Headers],0)) -> 0 | N8: =I8-K8+M8 -> 258615 | O8: =ROUND(N8*0.1,0) -> 25862 | Q8: =INDEX(Breakdown[],MATCH($D8,Breakdown[Dist],0),MATCH(Q$4,Breakdown[#Headers],0)) -> 65205 | R8: =INDEX(Breakdown[],MATCH($D8,Breakdown[Dist],0),MATCH(R$4,Breakdown[#Headers],0)) -> 0 | S8: =SUM(Q8:R8) -> 65205 | T8: =L8-O8 -> 167548 | U8: =SUM(S8:T8) -> 232753 | W8: =O8/N8 -> 0.10000193 | X8: =U8/N8 -> 0.89999807
A9: 2026 | B9: 12 | C9: 12 | D9: 0063 | G9: 0063 | H9: Akron-Westfield | I9: =INDEX(Breakdown[],MATCH($D9,Breakdown[Dist],0),MATCH(I$4,Breakdown[#Headers],0)) -> 214092 | J9: =INDEX(Breakdown[],MATCH($D9,Breakdown[Dist],0),MATCH(J$4,Breakdown[#Headers],0)) -> 166122 | K9: =INDEX(Breakdown[],MATCH($D9,Breakdown[Dist],0),MATCH(K$4,Breakdown[#Headers],0)) -> 35581 | L9: =INDEX(Breakdown[],MATCH($D9,Breakdown[Dist],0),MATCH(L$4,Breakdown[#Headers],0)) -> 130541 | M9: =INDEX(Breakdown[],MATCH($D9,Breakdown[Dist],0),MATCH(M$4,Breakdown[#Headers],0)) -> 1215 | N9: =I9-K9+M9 -> 179726 | O9: =ROUND(N9*0.1,0) -> 17973 | Q9: =INDEX(Breakdown[],MATCH($D9,Breakdown[Dist],0),MATCH(Q$4,Breakdown[#Headers],0)) -> 47970 | R9: =INDEX(Breakdown[],MATCH($D9,Breakdown[Dist],0),MATCH(R$4,Breakdown[#Headers],0)) -> 1215 | S9: =SUM(Q9:R9) -> 49185 | T9: =L9-O9 -> 112568 | U9: =SUM(S9:T9) -> 161753 | W9: =O9/N9 -> 0.10000223 | X9: =U9/N9 -> 0.89999777
A10: 2026 | B10: 05 | C10: 05 | D10: 0072 | G10: 0072 | H10: Albert City-Truesdale | I10: =INDEX(Breakdown[],MATCH($D10,Breakdown[Dist],0),MATCH(I$4,Breakdown[#Headers],0)) -> 82726 | J10: =INDEX(Breakdown[],MATCH($D10,Breakdown[Dist],0),MATCH(J$4,Breakdown[#Headers],0)) -> 63588 | K10: =INDEX(Breakdown[],MATCH($D10,Breakdown[Dist],0),MATCH(K$4,Breakdown[#Headers],0)) -> 13620 | L10: =INDEX(Breakdown[],MATCH($D10,Breakdown[Dist],0),MATCH(L$4,Breakdown[#Headers],0)) -> 49968 | M10: =INDEX(Breakdown[],MATCH($D10,Breakdown[Dist],0),MATCH(M$4,Breakdown[#Headers],0)) -> 0 | N10: =I10-K10+M10 -> 69106 | O10: =ROUND(N10*0.1,0) -> 6911 | Q10: =INDEX(Breakdown[],MATCH($D10,Breakdown[Dist],0),MATCH(Q$4,Breakdown[#Headers],0)) -> 19138 | R10: =INDEX(Breakdown[],MATCH($D10,Breakdown[Dist],0),MATCH(R$4,Breakdown[#Headers],0)) -> 0 | S10: =SUM(Q10:R10) -> 19138 | T10: =L10-O10 -> 43057 | U10: =SUM(S10:T10) -> 62195 | W10: =O10/N10 -> 0.10000579 | X10: =U10/N10 -> 0.89999421
A11: 2026 | B11: 15 | C11: 15 | D11: 0081 | G11: 0081 | H11: Albia | I11: =INDEX(Breakdown[],MATCH($D11,Breakdown[Dist],0),MATCH(I$4,Breakdown[#Headers],0)) -> 419878 | J11: =INDEX(Breakdown[],MATCH($D11,Breakdown[Dist],0),MATCH(J$4,Breakdown[#Headers],0)) -> 334468 | K11: =INDEX(Breakdown[],MATCH($D11,Breakdown[Dist],0),MATCH(K$4,Breakdown[#Headers],0)) -> 71638 | L11: =INDEX(Breakdown[],MATCH($D11,Breakdown[Dist],0),MATCH(L$4,Breakdown[#Headers],0)) -> 262830 | M11: =INDEX(Breakdown[],MATCH($D11,Breakdown[Dist],0),MATCH(M$4,Breakdown[#Headers],0)) -> 0 | N11: =I11-K11+M11 -> 348240 | O11: =ROUND(N11*0.1,0) -> 34824 | Q11: =INDEX(Breakdown[],MATCH($D11,Breakdown[Dist],0),MATCH(Q$4,Breakdown[#Headers],0)) -> 85410 | R11: =INDEX(Breakdown[],MATCH($D11,Breakdown[Dist],0),MATCH(R$4,Breakdown[#Headers],0)) -> 0 | S11: =SUM(Q11:R11) -> 85410 | T11: =L11-O11 -> 228006 | U11: =SUM(S11:T11) -> 313416 | W11: =O11/N11 -> 0.1 | X11: =U11/N11 -> 0.9
A12: 2026 | B12: 10 | C12: 10 | D12: 0099 | G12: 0099 | H12: Alburnett | I12: =INDEX(Breakdown[],MATCH($D12,Breakdown[Dist],0),MATCH(I$4,Breakdown[#Headers],0)) -> 203952 | J12: =INDEX(Breakdown[],MATCH($D12,Breakdown[Dist],0),MATCH(J$4,Breakdown[#Headers],0)) -> 161681 | K12: =INDEX(Breakdown[],MATCH($D12,Breakdown[Dist],0),MATCH(K$4,Breakdown[#Headers],0)) -> 34629 | L12: =INDEX(Breakdown[],MATCH($D12,Breakdown[Dist],0),MATCH(L$4,Breakdown[#Headers],0)) -> 127052 | M12: =INDEX(Breakdown[],MATCH($D12,Breakdown[Dist],0),MATCH(M$4,Breakdown[#Headers],0)) -> 0 | N12: =I12-K12+M12 -> 169323 | O12: =ROUND(N12*0.1,0) -> 16932 | Q12: =INDEX(Breakdown[],MATCH($D12,Breakdown[Dist],0),MATCH(Q$4,Breakdown[#Headers],0)) -> 42271 | R12: =INDEX(Breakdown[],MATCH($D12,Breakdown[Dist],0),MATCH(R$4,Breakdown[#Headers],0)) -> 0 | S12: =SUM(Q12:R12) -> 42271 | T12: =L12-O12 -> 110120 | U12: =SUM(S12:T12) -> 152391 | W12: =O12/N12 -> 0.099998228 | X12: =U12/N12 -> 0.90000177
A13: 2026 | B13: 07 | C13: 07 | D13: 0108 | G13: 0108 | H13: Alden | I13: =INDEX(Breakdown[],MATCH($D13,Breakdown[Dist],0),MATCH(I$4,Breakdown[#Headers],0)) -> 94422 | J13: =INDEX(Breakdown[],MATCH($D13,Breakdown[Dist],0),MATCH(J$4,Breakdown[#Headers],0)) -> 73943 | K13: =INDEX(Breakdown[],MATCH($D13,Breakdown[Dist],0),MATCH(K$4,Breakdown[#Headers],0)) -> 15838 | L13: =INDEX(Breakdown[],MATCH($D13,Breakdown[Dist],0),MATCH(L$4,Breakdown[#Headers],0)) -> 58105 | M13: =INDEX(Breakdown[],MATCH($D13,Breakdown[Dist],0),MATCH(M$4,Breakdown[#Headers],0)) -> 5533 | N13: =I13-K13+M13 -> 84117 | O13: =ROUND(N13*0.1,0) -> 8412 | Q13: =INDEX(Breakdown[],MATCH($D13,Breakdown[Dist],0),MATCH(Q$4,Breakdown[#Headers],0)) -> 20479 | R13: =INDEX(Breakdown[],MATCH($D13,Breakdown[Dist],0),MATCH(R$4,Breakdown[#Headers],0)) -> 5533 | S13: =SUM(Q13:R13) -> 26012 | T13: =L13-O13 -> 49693 | U13: =SUM(S13:T13) -> 75705 | W13: =O13/N13 -> 0.10000357 | X13: =U13/N13 -> 0.89999643
A14: 2026 | B14: 05 | C14: 05 | D14: 0126 | E14: 6417 | F14: 3897 | G14: 0126 | H14: Algona | I14: =INDEX(Breakdown[],MATCH($D14,Breakdown[Dist],0),MATCH(I$4,Breakdown[#Headers],0)) -> 587022 | J14: =INDEX(Breakdown[],MATCH($D14,Breakdown[Dist],0),MATCH(J$4,Breakdown[#Headers],0)) -> 451216 | K14: =INDEX(Breakdown[],MATCH($D14,Breakdown[Dist],0),MATCH(K$4,Breakdown[#Headers],0)) -> 96643 | L14: =INDEX(Breakdown[],MATCH($D14,Breakdown[Dist],0),MATCH(L$4,Breakdown[#Headers],0)) -> 354573 | M14: =INDEX(Breakdown[],MATCH($D14,Breakdown[Dist],0),MATCH(M$4,Breakdown[#Headers],0)) -> 0 | N14: =I14-K14+M14 -> 490379 | O14: =ROUND(N14*0.1,0) -> 49038 | Q14: =INDEX(Breakdown[],MATCH($D14,Breakdown[Dist],0),MATCH(Q$4,Breakdown[#Headers],0)) -> 135806 | R14: =INDEX(Breakdown[],MATCH($D14,Breakdown[Dist],0),MATCH(R$4,Breakdown[#Headers],0)) -> 0 | S14: =SUM(Q14:R14) -> 135806 | T14: =L14-O14 -> 305535 | U14: =SUM(S14:T14) -> 441341 | W14: =O14/N14 -> 0.1000002 | X14: =U14/N14 -> 0.8999998
A15: 2026 | B15: 01 | C15: 01 | D15: 0135 | G15: 0135 | H15: Allamakee | I15: =INDEX(Breakdown[],MATCH($D15,Breakdown[Dist],0),MATCH(I$4,Breakdown[#Headers],0)) -> 463226 | J15: =INDEX(Breakdown[],MATCH($D15,Breakdown[Dist],0),MATCH(J$4,Breakdown[#Headers],0)) -> 351894 | K15: =INDEX(Breakdown[],MATCH($D15,Breakdown[Dist],0),MATCH(K$4,Breakdown[#Headers],0)) -> 75370 | L15: =INDEX(Breakdown[],MATCH($D15,Breakdown[Dist],0),MATCH(L$4,Breakdown[#Headers],0)) -> 276524 | M15: =INDEX(Breakdown[],MATCH($D15,Breakdown[Dist],0),MATCH(M$4,Breakdown[#Headers],0)) -> 0 | N15: =I15-K15+M15 -> 387856 | O15: =ROUND(N15*0.1,0) -> 38786 | Q15: =INDEX(Breakdown[],MATCH($D15,Breakdown[Dist],0),MATCH(Q$4,Breakdown[#Headers],0)) -> 111332 | R15: =INDEX(Breakdown[],MATCH($D15,Breakdown[Dist],0),MATCH(R$4,Breakdown[#Headers],0)) -> 0 | S15: =SUM(Q15:R15) -> 111332 | T15: =L15-O15 -> 237738 | U15: =SUM(S15:T15) -> 349070 | W15: =O15/N15 -> 0.10000103 | X15: =U15/N15 -> 0.89999897
A16: 2026 | B16: 05 | C16: 05 | D16: 0171 | G16: 0171 | H16: Alta-Aurelia | I16: =INDEX(Breakdown[],MATCH($D16,Breakdown[Dist],0),MATCH(I$4,Breakdown[#Headers],0)) -> 334438 | J16: =INDEX(Breakdown[],MATCH($D16,Breakdown[Dist],0),MATCH(J$4,Breakdown[#Headers],0)) -> 257066 | K16: =INDEX(Breakdown[],MATCH($D16,Breakdown[Dist],0),MATCH(K$4,Breakdown[#Headers],0)) -> 55059 | L16: =INDEX(Breakdown[],MATCH($D16,Breakdown[Dist],0),MATCH(L$4,Breakdown[#Headers],0)) -> 202007 | M16: =INDEX(Breakdown[],MATCH($D16,Breakdown[Dist],0),MATCH(M$4,Breakdown[#Headers],0)) -> 0 | N16: =I16-K16+M16 -> 279379 | O16: =ROUND(N16*0.1,0) -> 27938 | Q16: =INDEX(Breakdown[],MATCH($D16,Breakdown[Dist],0),MATCH(Q$4,Breakdown[#Headers],0)) -> 77372 | R16: =INDEX(Breakdown[],MATCH($D16,Breakdown[Dist],0),MATCH(R$4,Breakdown[#Headers],0)) -> 0 | S16: =SUM(Q16:R16) -> 77372 | T16: =L16-O16 -> 174069 | U16: =SUM(S16:T16) -> 251441 | W16: =O16/N16 -> 0.10000036 | X16: =U16/N16 -> 0.89999964
A17: 2026 | B17: 11 | C17: 11 | D17: 0225 | G17: 0225 | H17: Ames | I17: =INDEX(Breakdown[],MATCH($D17,Breakdown[Dist],0),MATCH(I$4,Breakdown[#Headers],0)) -> 1767659 | J17: =INDEX(Breakdown[],MATCH($D17,Breakdown[Dist],0),MATCH(J$4,Breakdown[#Headers],0)) -> 1430464 | K17: =INDEX(Breakdown[],MATCH($D17,Breakdown[Dist],0),MATCH(K$4,Breakdown[#Headers],0)) -> 306383 | L17: =INDEX(Breakdown[],MATCH($D17,Breakdown[Dist],0),MATCH(L$4,Breakdown[#Headers],0)) -> 1124081 | M17: =INDEX(Breakdown[],MATCH($D17,Breakdown[Dist],0),MATCH(M$4,Breakdown[#Headers],0)) -> 0 | N17: =I17-K17+M17 -> 1461276 | O17: =ROUND(N17*0.1,0) -> 146128 | Q17: =INDEX(Breakdown[],MATCH($D17,Breakdown[Dist],0),MATCH(Q$4,Breakdown[#Headers],0)) -> 337195 | R17: =INDEX(Breakdown[],MATCH($D17,Breakdown[Dist],0),MATCH(R$4,Breakdown[#Headers],0)) -> 0 | S17: =SUM(Q17:R17) -> 337195 | T17: =L17-O17 -> 977953 | U17: =SUM(S17:T17) -> 1315148 | W17: =O17/N17 -> 0.10000027 | X17: =U17/N17 -> 0.89999973
A18: 2026 | B18: 10 | C18: 10 | D18: 0234 | G18: 0234 | H18: Anamosa | I18: =INDEX(Breakdown[],MATCH($D18,Breakdown[Dist],0),MATCH(I$4,Breakdown[#Headers],0)) -> 458314 | J18: =INDEX(Breakdown[],MATCH($D18,Breakdown[Dist],0),MATCH(J$4,Breakdown[#Headers],0)) -> 363324 | K18: =INDEX(Breakdown[],MATCH($D18,Breakdown[Dist],0),MATCH(K$4,Breakdown[#Headers],0)) -> 77818 | L18: =INDEX(Breakdown[],MATCH($D18,Breakdown[Dist],0),MATCH(L$4,Breakdown[#Headers],0)) -> 285506 | M18: =INDEX(Breakdown[],MATCH($D18,Breakdown[Dist],0),MATCH(M$4,Breakdown[#Headers],0)) -> 15810 | N18: =I18-K18+M18 -> 396306 | O18: =ROUND(N18*0.1,0) -> 39631 | Q18: =INDEX(Breakdown[],MATCH($D18,Breakdown[Dist],0),MATCH(Q$4,Breakdown[#Headers],0)) -> 94990 | R18: =INDEX(Breakdown[],MATCH($D18,Breakdown[Dist],0),MATCH(R$4,Breakdown[#Headers],0)) -> 15810 | S18: =SUM(Q18:R18) -> 110800 | T18: =L18-O18 -> 245875 | U18: =SUM(S18:T18) -> 356675 | W18: =O18/N18 -> 0.10000101 | X18: =U18/N18 -> 0.89999899
