Workbook
Name IDX: Final!$A$1

Sheet CashReserveLevy
C1: =_xlfn.CONCAT("SBRC FY ",A3," Final Cash Reserve Levy Limitations Source: FY ",A3-2," Certified Annual Report") -> SBRC FY 2024 Final Cash Reserve Levy Limitations Source: FY 2022 Certified Annual Report
A2: FiscalYear | B2: AEA | C2: Dist | D2: DistSub1 | E2: DistSub2 | F2: DistrictNumber | G2: Label | H2: Expenditures | I2: 20% of Expenditures | J2: Assigned and Unassigned Fund Balance | K2: Final Maximum Cash Reserve Levy | L2: Final Cash Reserve Levy | M2: Levying Maximum Cash Reserve | Q2: Check for Negative | U2: Preliminary Maximum Cash Reserve Levy - Initial Posting
A3: 2024 | B3: 11 | C3: 0018 | F3: 0018 | G3: Adair-Casey | H3: =ROUND(SUMPRODUCT(SUMIF(Final!$G$4:$G$330,CashReserveLevy!D3:F3,Final!$C$4:$C$330)),0) -> 4593649 | I3: =ROUND(H3*0.2,0) -> 918730 | J3: =ROUND(SUMPRODUCT(SUMIF(Final!$G$4:$G$330,CashReserveLevy!D3:F3,Final!$E$4:$E$330)),0) -> 1435067 | K3: =IF(I3>J3,I3-J3,0) -> 0 | L3: =INDEX(ActualCRLevy_SAS!$A$2:$D$326,MATCH(CashReserveLevy!$C3,ActualCRLevy_SAS!$B$2:$B$326,0),4) -> 0 | M3: =IF(AND(L3=K3,K3>0),"Max","") | N3: =IF(AND(L3<K3,L3=0),"No Levy but have Capacity","") | O3: =IF(L3>K3,"Exceedes Maximum Limit","") | Q3: =K3-L3 -> 0 | U3: 0 | V3: =K3-U3 -> 0
A4: 2024 | B4: 11 | C4: 0027 | F4: 0027 | G4: Adel-Desoto-Minburn | H4: =ROUND(SUMPRODUCT(SUMIF(Final!$G$4:$G$330,CashReserveLevy!D4:F4,Final!$C$4:$C$330)),0) -> 24295219 | I4: =ROUND(H4*0.2,0) -> 4859044 | J4: =ROUND(SUMPRODUCT(SUMIF(Final!$G$4:$G$330,CashReserveLevy!D4:F4,Final!$E$4:$E$330)),0) -> 5188022 | K4: =IF(I4>J4,I4-J4,0) -> 0 | L4: =INDEX(ActualCRLevy_SAS!$A$2:$D$326,MATCH(CashReserveLevy!$C4,ActualCRLevy_SAS!$B$2:$B$326,0),4) -> 0 | M4: =IF(AND(L4=K4,K4>0),"Max","") | N4: =IF(AND(L4<K4,L4=0),"No Levy but have Capacity","") | O4: =IF(L4>K4,"Exceedes Maximum Limit","") | Q4: =K4-L4 -> 0 | U4: 0 | V4: =K4-U4 -> 0
A5: 2024 | B5: 07 | C5: 0009 | F5: 0009 | G5: AGWSR | H5: =ROUND(SUMPRODUCT(SUMIF(Final!$G$4:$G$330,CashReserveLevy!D5:F5,Final!$C$4:$C$330)),0) -> 9940867 | I5: =ROUND(H5*0.2,0) -> 1988173 | J5: =ROUND(SUMPRODUCT(SUMIF(Final!$G$4:$G$330,CashReserveLevy!D5:F5,Final!$E$4:$E$330)),0) -> 1221374 | K5: =IF(I5>J5,I5-J5,0) -> 766799 | L5: =INDEX(ActualCRLevy_SAS!$A$2:$D$326,MATCH(CashReserveLevy!$C5,ActualCRLevy_SAS!$B$2:$B$326,0),4) -> 370000 | M5: =IF(AND(L5=K5,K5>0),"Max","") | N5: =IF(AND(L5<K5,L5=0),"No Levy but have Capacity","") | O5: =IF(L5>K5,"Exceedes Maximum Limit","") | Q5: =K5-L5 -> 396799 | U5: 766799 | V5: =K5-U5 -> 0
A6: 2024 | B6: 13 | C6: 0441 | F6: 0441 | G6: AHSTW | H6: =ROUND(SUMPRODUCT(SUMIF(Final!$G$4:$G$330,CashReserveLevy!D6:F6,Final!$C$4:$C$330)),0) -> 10025049 | I6: =ROUND(H6*0.2,0) -> 2005010 | J6: =ROUND(SUMPRODUCT(SUMIF(Final!$G$4:$G$330,CashReserveLevy!D6:F6,Final!$E$4:$E$330)),0) -> 2869593 | K6: =IF(I6>J6,I6-J6,0) -> 0 | L6: =INDEX(ActualCRLevy_SAS!$A$2:$D$326,MATCH(CashReserveLevy!$C6,ActualCRLevy_SAS!$B$2:$B$326,0),4) -> 0 | M6: =IF(AND(L6=K6,K6>0),"Max","") | N6: =IF(AND(L6<K6,L6=0),"No Levy but have Capacity","") | O6: =IF(L6>K6,"Exceedes Maximum Limit","") | Q6: =K6-L6 -> 0 | U6: 0 | V6: =K6-U6 -> 0
A7: 2024 | B7: 12 | C7: 0063 | F7: 0063 | G7: Akron-Westfield | H7: =ROUND(SUMPRODUCT(SUMIF(Final!$G$4:$G$330,CashReserveLevy!D7:F7,Final!$C$4:$C$330)),0) -> 8004281 | I7: =ROUND(H7*0.2,0) -> 1600856 | J7: =ROUND(SUMPRODUCT(SUMIF(Final!$G$4:$G$330,CashReserveLevy!D7:F7,Final!$E$4:$E$330)),0) -> 1785712 | K7: =IF(I7>J7,I7-J7,0) -> 0 | L7: =INDEX(ActualCRLevy_SAS!$A$2:$D$326,MATCH(CashReserveLevy!$C7,ActualCRLevy_SAS!$B$2:$B$326,0),4) -> 0 | M7: =IF(AND(L7=K7,K7>0),"Max","") | N7: =IF(AND(L7<K7,L7=0),"No Levy but have Capacity","") | O7: =IF(L7>K7,"Exceedes Maximum Limit","") | Q7: =K7-L7 -> 0 | U7: 0 | V7: =K7-U7 -> 0
A8: 2024 | B8: 05 | C8: 0072 | F8: 0072 | G8: Albert City-Truesdale | H8: =ROUND(SUMPRODUCT(SUMIF(Final!$G$4:$G$330,CashReserveLevy!D8:F8,Final!$C$4:$C$330)),0) -> 2809844 | I8: =ROUND(H8*0.2,0) -> 561969 | J8: =ROUND(SUMPRODUCT(SUMIF(Final!$G$4:$G$330,CashReserveLevy!D8:F8,Final!$E$4:$E$330)),0) -> 1134405 | K8: =IF(I8>J8,I8-J8,0) -> 0 | L8: =INDEX(ActualCRLevy_SAS!$A$2:$D$326,MATCH(CashReserveLevy!$C8,ActualCRLevy_SAS!$B$2:$B$326,0),4) -> 0 | M8: =IF(AND(L8=K8,K8>0),"Max","") | N8: =IF(AND(L8<K8,L8=0),"No Levy but have Capacity","") | O8: =IF(L8>K8,"Exceedes Maximum Limit","") | Q8: =K8-L8 -> 0 | U8: 0 | V8: =K8-U8 -> 0
A9: 2024 | B9: 15 | C9: 0081 | F9: 0081 | G9: Albia | H9: =ROUND(SUMPRODUCT(SUMIF(Final!$G$4:$G$330,CashReserveLevy!D9:F9,Final!$C$4:$C$330)),0) -> 14271156 | I9: =ROUND(H9*0.2,0) -> 2854231 | J9: =ROUND(SUMPRODUCT(SUMIF(Final!$G$4:$G$330,CashReserveLevy!D9:F9,Final!$E$4:$E$330)),0) -> 4071860 | K9: =IF(I9>J9,I9-J9,0) -> 0 | L9: =INDEX(ActualCRLevy_SAS!$A$2:$D$326,MATCH(CashReserveLevy!$C9,ActualCRLevy_SAS!$B$2:$B$326,0),4) -> 0 | M9: =IF(AND(L9=K9,K9>0),"Max","") | N9: =IF(AND(L9<K9,L9=0),"No Levy but have Capacity","") | O9: =IF(L9>K9,"Exceedes Maximum Limit","") | Q9: =K9-L9 -> 0 | U9: 0 | V9: =K9-U9 -> 0
A10: 2024 | B10: 10 | C10: 0099 | F10: 0099 | G10: Alburnett | H10: =ROUND(SUMPRODUCT(SUMIF(Final!$G$4:$G$330,CashReserveLevy!D10:F10,Final!$C$4:$C$330)),0) -> 8476603 | I10: =ROUND(H10*0.2,0) -> 1695321 | J10: =ROUND(SUMPRODUCT(SUMIF(Final!$G$4:$G$330,CashReserveLevy!D10:F10,Final!$E$4:$E$330)),0) -> 1952462 | K10: =IF(I10>J10,I10-J10,0) -> 0 | L10: =INDEX(ActualCRLevy_SAS!$A$2:$D$326,MATCH(CashReserveLevy!$C10,ActualCRLevy_SAS!$B$2:$B$326,0),4) -> 0 | M10: =IF(AND(L10=K10,K10>0),"Max","") | N10: =IF(AND(L10<K10,L10=0),"No Levy but have Capacity","") | O10: =IF(L10>K10,"Exceedes Maximum Limit","") | Q10: =K10-L10 -> 0 | U10: 0 | V10: =K10-U10 -> 0
A11: 2024 | B11: 07 | C11: 0108 | F11: 0108 | G11: Alden | H11: =ROUND(SUMPRODUCT(SUMIF(Final!$G$4:$G$330,CashReserveLevy!D11:F11,Final!$C$4:$C$330)),0) -> 3876814 | I11: =ROUND(H11*0.2,0) -> 775363 | J11: =ROUND(SUMPRODUCT(SUMIF(Final!$G$4:$G$330,CashReserveLevy!D11:F11,Final!$E$4:$E$330)),0) -> 127457 | K11: =IF(I11>J11,I11-J11,0) -> 647906 | L11: =INDEX(ActualCRLevy_SAS!$A$2:$D$326,MATCH(CashReserveLevy!$C11,ActualCRLevy_SAS!$B$2:$B$326,0),4) -> 400000 | M11: =IF(AND(L11=K11,K11>0),"Max","") | N11: =IF(AND(L11<K11,L11=0),"No Levy but have Capacity","") | O11: =IF(L11>K11,"Exceedes Maximum Limit","") | Q11: =K11-L11 -> 247906 | U11: 647906 | V11: =K11-U11 -> 0
A12: 2024 | B12: 05 | C12: 0126 | D12: 6417 | E12: 3897 | F12: 0126 | G12: Algona | H12: =ROUND(SUMPRODUCT(SUMIF(Final!$G$4:$G$330,CashReserveLevy!D12:F12,Final!$C$4:$C$330)),0) -> 22878245 | I12: =ROUND(H12*0.2,0) -> 4575649 | J12: =ROUND(SUMPRODUCT(SUMIF(Final!$G$4:$G$330,CashReserveLevy!D12:F12,Final!$E$4:$E$330)),0) -> 3679749 | K12: =IF(I12>J12,I12-J12,0) -> 895900 | L12: =INDEX(ActualCRLevy_SAS!$A$2:$D$326,MATCH(CashReserveLevy!$C12,ActualCRLevy_SAS!$B$2:$B$326,0),4) -> 895900 | M12: =IF(AND(L12=K12,K12>0),"Max","") -> Max | N12: =IF(AND(L12<K12,L12=0),"No Levy but have Capacity","") | O12: =IF(L12>K12,"Exceedes Maximum Limit","") | Q12: =K12-L12 -> 0 | U12: 895900 | V12: =K12-U12 -> 0
A13: 2024 | B13: 01 | C13: 0135 | F13: 0135 | G13: Allamakee | H13: =ROUND(SUMPRODUCT(SUMIF(Final!$G$4:$G$330,CashReserveLevy!D13:F13,Final!$C$4:$C$330)),0) -> 14603162 | I13: =ROUND(H13*0.2,0) -> 2920632 | J13: =ROUND(SUMPRODUCT(SUMIF(Final!$G$4:$G$330,CashReserveLevy!D13:F13,Final!$E$4:$E$330)),0) -> 3081424 | K13: =IF(I13>J13,I13-J13,0) -> 0 | L13: =INDEX(ActualCRLevy_SAS!$A$2:$D$326,MATCH(CashReserveLevy!$C13,ActualCRLevy_SAS!$B$2:$B$326,0),4) -> 0 | M13: =IF(AND(L13=K13,K13>0),"Max","") | N13: =IF(AND(L13<K13,L13=0),"No Levy but have Capacity","") | O13: =IF(L13>K13,"Exceedes Maximum Limit","") | Q13: =K13-L13 -> 0 | U13: 0 | V13: =K13-U13 -> 0
A14: 2024 | B14: 05 | C14: 0171 | F14: 0171 | G14: Alta-Aurelia | H14: =ROUND(SUMPRODUCT(SUMIF(Final!$G$4:$G$330,CashReserveLevy!D14:F14,Final!$C$4:$C$330)),0) -> 11385819 | I14: =ROUND(H14*0.2,0) -> 2277164 | J14: =ROUND(SUMPRODUCT(SUMIF(Final!$G$4:$G$330,CashReserveLevy!D14:F14,Final!$E$4:$E$330)),0) -> 1634402 | K14: =IF(I14>J14,I14-J14,0) -> 642762 | L14: =INDEX(ActualCRLevy_SAS!$A$2:$D$326,MATCH(CashReserveLevy!$C14,ActualCRLevy_SAS!$B$2:$B$326,0),4) -> 350000 | M14: =IF(AND(L14=K14,K14>0),"Max","") | N14: =IF(AND(L14<K14,L14=0),"No Levy but have Capacity","") | O14: =IF(L14>K14,"Exceedes Maximum Limit","") | Q14: =K14-L14 -> 292762 | U14: 642762 | V14: =K14-U14 -> 0
A15: 2024 | B15: 11 | C15: 0225 | F15: 0225 | G15: Ames | H15: =ROUND(SUMPRODUCT(SUMIF(Final!$G$4:$G$330,CashReserveLevy!D15:F15,Final!$C$4:$C$330)),0) -> 61294605 | I15: =ROUND(H15*0.2,0) -> 12258921 | J15: =ROUND(SUMPRODUCT(SUMIF(Final!$G$4:$G$330,CashReserveLevy!D15:F15,Final!$E$4:$E$330)),0) -> 12577895 | K15: =IF(I15>J15,I15-J15,0) -> 0 | L15: =INDEX(ActualCRLevy_SAS!$A$2:$D$326,MATCH(CashReserveLevy!$C15,ActualCRLevy_SAS!$B$2:$B$326,0),4) -> 0 | M15: =IF(AND(L15=K15,K15>0),"Max","") | N15: =IF(AND(L15<K15,L15=0),"No Levy but have Capacity","") | O15: =IF(L15>K15,"Exceedes Maximum Limit","") | Q15: =K15-L15 -> 0 | U15: 0 | V15: =K15-U15 -> 0
A16: 2024 | B16: 10 | C16: 0234 | F16: 0234 | G16: Anamosa | H16: =ROUND(SUMPRODUCT(SUMIF(Final!$G$4:$G$330,CashReserveLevy!D16:F16,Final!$C$4:$C$330)),0) -> 16741535 | I16: =ROUND(H16*0.2,0) -> 3348307 | J16: =ROUND(SUMPRODUCT(SUMIF(Final!$G$4:$G$330,CashReserveLevy!D16:F16,Final!$E$4:$E$330)),0) -> 4432442 | K16: =IF(I16>J16,I16-J16,0) -> 0 | L16: =INDEX(ActualCRLevy_SAS!$A$2:$D$326,MATCH(CashReserveLevy!$C16,ActualCRLevy_SAS!$B$2:$B$326,0),4) -> 0 | M16: =IF(AND(L16=K16,K16>0),"Max","") | N16: =IF(AND(L16<K16,L16=0),"No Levy but have Capacity","") | O16: =IF(L16>K16,"Exceedes Maximum Limit","") | Q16: =K16-L16 -> 0 | U16: 0 | V16: =K16-U16 -> 0
A17: 2024 | B17: 09 | C17: 0243 | F17: 0243 | G17: Andrew | H17: =ROUND(SUMPRODUCT(SUMIF(Final!$G$4:$G$330,CashReserveLevy!D17:F17,Final!$C$4:$C$330)),0) -> 3748758 | I17: =ROUND(H17*0.2,0) -> 749752 | J17: =ROUND(SUMPRODUCT(SUMIF(Final!$G$4:$G$330,CashReserveLevy!D17:F17,Final!$E$4:$E$330)),0) -> 538148 | K17: =IF(I17>J17,I17-J17,0) -> 211604 | L17: =INDEX(ActualCRLevy_SAS!$A$2:$D$326,MATCH(CashReserveLevy!$C17,ActualCRLevy_SAS!$B$2:$B$326,0),4) -> 170000 | M17: =IF(AND(L17=K17,K17>0),"Max","") | N17: =IF(AND(L17<K17,L17=0),"No Levy but have Capacity","") | O17: =IF(L17>K17,"Exceedes Maximum Limit","") | Q17: =K17-L17 -> 41604 | U17: 211604 | V17: =K17-U17 -> 0
A18: 2024 | B18: 11 | C18: 0261 | F18: 0261 | G18: Ankeny | H18: =ROUND(SUMPRODUCT(SUMIF(Final!$G$4:$G$330,CashReserveLevy!D18:F18,Final!$C$4:$C$330)),0) -> 148362662 | I18: =ROUND(H18*0.2,0) -> 29672532 | J18: =ROUND(SUMPRODUCT(SUMIF(Final!$G$4:$G$330,CashReserveLevy!D18:F18,Final!$E$4:$E$330)),0) -> 16727252 | K18: =IF(I18>J18,I18-J18,0) -> 12945280 | L18: =INDEX(ActualCRLevy_SAS!$A$2:$D$326,MATCH(CashReserveLevy!$C18,ActualCRLevy_SAS!$B$2:$B$326,0),4) -> 11047397 | M18: =IF(AND(L18=K18,K18>0),"Max","") | N18: =IF(AND(L18<K18,L18=0),"No Levy but have Capacity","") | O18: =IF(L18>K18,"Exceedes Maximum Limit","") | Q18: =K18-L18 -> 1897883 | U18: 12945280 | V18: =K18-U18 -> 0
A19: 2024 | B19: 07 | C19: 0279 | F19: 0279 | G19: Aplington-Parkersburg | H19: =ROUND(SUMPRODUCT(SUMIF(Final!$G$4:$G$330,CashReserveLevy!D19:F19,Final!$C$4:$C$330)),0) -> 10125203 | I19: =ROUND(H19*0.2,0) -> 2025041 | J19: =ROUND(SUMPRODUCT(SUMIF(Final!$G$4:$G$330,CashReserveLevy!D19:F19,Final!$E$4:$E$330)),0) -> 2610572 | K19: =IF(I19>J19,I19-J19,0) -> 0 | L19: =INDEX(ActualCRLevy_SAS!$A$2:$D$326,MATCH(CashReserveLevy!$C19,ActualCRLevy_SAS!$B$2:$B$326,0),4) -> 0 | M19: =IF(AND(L19=K19,K19>0),"Max","") | N19: =IF(AND(L19<K19,L19=0),"No Levy but have Capacity","") | O19: =IF(L19>K19,"Exceedes Maximum Limit","") | Q19: =K19-L19 -> 0 | U19: 0 | V19: =K19-U19 -> 0
A20: 2024 | B20: 12 | C20: 0355 | F20: 0355 | G20: Ar-We-Va | H20: =ROUND(SUMPRODUCT(SUMIF(Final!$G$4:$G$330,CashReserveLevy!D20:F20,Final!$C$4:$C$330)),0) -> 3717537 | I20: =ROUND(H20*0.2,0) -> 743507 | J20: =ROUND(SUMPRODUCT(SUMIF(Final!$G$4:$G$330,CashReserveLevy!D20:F20,Final!$E$4:$E$330)),0) -> 1925063 | K20: =IF(I20>J20,I20-J20,0) -> 0 | L20: =INDEX(ActualCRLevy_SAS!$A$2:$D$326,MATCH(CashReserveLevy!$C20,ActualCRLevy_SAS!$B$2:$B$326,0),4) -> 0 | M20: =IF(AND(L20=K20,K20>0),"Max","") | N20: =IF(AND(L20<K20,L20=0),"No Levy but have Capacity","") | O20: =IF(L20>K20,"Exceedes Maximum Limit","") | Q20: =K20-L20 -> 0 | U20: 0 | V20: =K20-U20 -> 0
A21: 2024 | B21: 13 | C21: 0387 | F21: 0387 | G21: Atlantic | H21: =ROUND(SUMPRODUCT(SUMIF(Final!$G$4:$G$330,CashReserveLevy!D21:F21,Final!$C$4:$C$330)),0) -> 18916816 | I21: =ROUND(H21*0.2,0) -> 3783363 | J21: =ROUND(SUMPRODUCT(SUMIF(Final!$G$4:$G$330,CashReserveLevy!D21:F21,Final!$E$4:$E$330)),0) -> 3124645 | K21: =IF(I21>J21,I21-J21,0) -> 658718 | L21: =INDEX(ActualCRLevy_SAS!$A$2:$D$326,MATCH(CashReserveLevy!$C21,ActualCRLevy_SAS!$B$2:$B$326,0),4) -> 658718 | M21: =IF(AND(L21=K21,K21>0),"Max","") -> Max | N21: =IF(AND(L21<K21,L21=0),"No Levy but have Capacity","") | O21: =IF(L21>K21,"Exceedes Maximum Limit","") | Q21: =K21-L21 -> 0 | U21: 658718 | V21: =K21-U21 -> 0
A22: 2024 | B22: 11 | C22: 0414 | F22: 0414 | G22: Audubon | H22: =ROUND(SUMPRODUCT(SUMIF(Final!$G$4:$G$330,CashReserveLevy!D22:F22,Final!$C$4:$C$330)),0) -> 7272865 | I22: =ROUND(H22*0.2,0) -> 1454573 | J22: =ROUND(SUMPRODUCT(SUMIF(Final!$G$4:$G$330,CashReserveLevy!D22:F22,Final!$E$4:$E$330)),0) -> 1314102 | K22: =IF(I22>J22,I22-J22,0) -> 140471 | L22: =INDEX(ActualCRLevy_SAS!$A$2:$D$326,MATCH(CashReserveLevy!$C22,ActualCRLevy_SAS!$B$2:$B$326,0),4) -> 140471 | M22: =IF(AND(L22=K22,K22>0),"Max","") -> Max | N22: =IF(AND(L22<K22,L22=0),"No Levy but have Capacity","") | O22: =IF(L22>K22,"Exceedes Maximum Limit","") | Q22: =K22-L22 -> 0 | U22: 140471 | V22: =K22-U22 -> 0
A23: 2024 | B23: 11 | C23: 0472 | F23: 0472 | G23: Ballard | H23: =ROUND(SUMPRODUCT(SUMIF(Final!$G$4:$G$330,CashReserveLevy!D23:F23,Final!$C$4:$C$330)),0) -> 21737477 | I23: =ROUND(H23*0.2,0) -> 4347495 | J23: =ROUND(SUMPRODUCT(SUMIF(Final!$G$4:$G$330,CashReserveLevy!D23:F23,Final!$E$4:$E$330)),0) -> 3088911 | K23: =IF(I23>J23,I23-J23,0) -> 1258584 | L23: =INDEX(ActualCRLevy_SAS!$A$2:$D$326,MATCH(CashReserveLevy!$C23,ActualCRLevy_SAS!$B$2:$B$326,0),4) -> 1258584 | M23: =IF(AND(L23=K23,K23>0),"Max","") -> Max | N23: =IF(AND(L23<K23,L23=0),"No Levy but have Capacity","") | O23: =IF(L23>K23,"Exceedes Maximum Limit","") | Q23: =K23-L23 -> 0 | U23: 1258584 | V23: =K23-U23 -> 0
A24: 2024 | B24: 11 | C24: 0513 | F24: 0513 | G24: Baxter | H24: =ROUND(SUMPRODUCT(SUMIF(Final!$G$4:$G$330,CashReserveLevy!D24:F24,Final!$C$4:$C$330)),0) -> 5668120 | I24: =ROUND(H24*0.2,0) -> 1133624 | J24: =ROUND(SUMPRODUCT(SUMIF(Final!$G$4:$G$330,CashReserveLevy!D24:F24,Final!$E$4:$E$330)),0) -> 92318 | K24: =IF(I24>J24,I24-J24,0) -> 1041306 | L24: =INDEX(ActualCRLevy_SAS!$A$2:$D$326,MATCH(CashReserveLevy!$C24,ActualCRLevy_SAS!$B$2:$B$326,0),4) -> 495487 | M24: =IF(AND(L24=K24,K24>0),"Max","") | N24: =IF(AND(L24<K24,L24=0),"No Levy but have Capacity","") | O24: =IF(L24>K24,"Exceedes Maximum Limit","") | Q24: =K24-L24 -> 545819 | U24: 1041306 | V24: =K24-U24 -> 0
... A61: 2024 | B61: 13 | C61: 1197 | F61: 1197 | G61: Clarinda | H61: =ROUND(SUMPRODUCT(SUMIF(Final!$G$4:$G$330,CashReserveLevy!D61:F61,Final!$C$4:$C$330)),0) -> 12694281 | I61: =ROUND(H61*0.2,0) -> 2538856 | J61: =ROUND(SUMPRODUCT(SUMIF(Final!$G$4:$G$330,CashReserveLevy!D61:F61,Final!$E$4:$E$330)),0) -> 2733409 | K61: =IF(I61>J61,I61-J61,0) -> 0 | L61: =INDEX(ActualCRLevy_SAS!$A$2:$D$326,MATCH(CashReserveLevy!$C61,ActualCRLevy_SAS!$B$2:$B$326,0),4) -> 0 | M61: =IF(AND(L61=K61,K61>0),"Max","") | N61: =IF(AND(L61<K61,L61=0),"No Levy but have Capacity","") | O61: =IF(L61>K61,"Exceedes Maximum Limit","") | Q61: =K61-L61 -> 0 | U61: 0 | V61: =K61-U61 -> 0
A62: 2024 | B62: 05 | C62: 1206 | D62: 1854 | F62: 1206 | G62: Clarion-Goldfield-Dows | H62: =ROUND(SUMPRODUCT(SUMIF(Final!$G$4:$G$330,CashReserveLevy!D62:F62,Final!$C$4:$C$330)),0) -> 14308808 | I62: =ROUND(H62*0.2,0) -> 2861762 | J62: =ROUND(SUMPRODUCT(SUMIF(Final!$G$4:$G$330,CashReserveLevy!D62:F62,Final!$E$4:$E$330)),0) -> 893256 | K62: =IF(I62>J62,I62-J62,0) -> 1968506 | L62: =INDEX(ActualCRLevy_SAS!$A$2:$D$326,MATCH(CashReserveLevy!$C62,ActualCRLevy_SAS!$B$2:$B$326,0),4) -> 1300000 | M62: =IF(AND(L62=K62,K62>0),"Max","") | N62: =IF(AND(L62<K62,L62=0),"No Levy but have Capacity","") | O62: =IF(L62>K62,"Exceedes Maximum Limit","") | Q62: =K62-L62 -> 668506 | U62: 1968506 | V62: =K62-U62 -> 0
A63: 2024 | B63: 13 | C63: 1211 | F63: 1211 | G63: Clarke | H63: =ROUND(SUMPRODUCT(SUMIF(Final!$G$4:$G$330,CashReserveLevy!D63:F63,Final!$C$4:$C$330)),0) -> 18287515 | I63: =ROUND(H63*0.2,0) -> 3657503 | J63: =ROUND(SUMPRODUCT(SUMIF(Final!$G$4:$G$330,CashReserveLevy!D63:F63,Final!$E$4:$E$330)),0) -> 504151 | K63: =IF(I63>J63,I63-J63,0) -> 3153352 | L63: =INDEX(ActualCRLevy_SAS!$A$2:$D$326,MATCH(CashReserveLevy!$C63,ActualCRLevy_SAS!$B$2:$B$326,0),4) -> 1211348 | M63: =IF(AND(L63=K63,K63>0),"Max","") | N63: =IF(AND(L63<K63,L63=0),"No Levy but have Capacity","") | O63: =IF(L63>K63,"Exceedes Maximum Limit","") | Q63: =K63-L63 -> 1942004 | U63: 3153352 | V63: =K63-U63 -> 0
A64: 2024 | B64: 07 | C64: 1215 | F64: 1215 | G64: Clarksville | H64: =ROUND(SUMPRODUCT(SUMIF(Final!$G$4:$G$330,CashReserveLevy!D64:F64,Final!$C$4:$C$330)),0) -> 4228077 | I64: =ROUND(H64*0.2,0) -> 845615 | J64: =ROUND(SUMPRODUCT(SUMIF(Final!$G$4:$G$330,CashReserveLevy!D64:F64,Final!$E$4:$E$330)),0) -> 960661 | K64: =IF(I64>J64,I64-J64,0) -> 0 | L64: =INDEX(ActualCRLevy_SAS!$A$2:$D$326,MATCH(CashReserveLevy!$C64,ActualCRLevy_SAS!$B$2:$B$326,0),4) -> 0 | M64: =IF(AND(L64=K64,K64>0),"Max","") | N64: =IF(AND(L64<K64,L64=0),"No Levy but have Capacity","") | O64: =IF(L64>K64,"Exceedes Maximum Limit","") | Q64: =K64-L64 -> 0 | U64: 0 | V64: =K64-U64 -> 0
A65: 2024 | B65: 05 | C65: 1218 | F65: 1218 | G65: Clay Central-Everly | H65: =ROUND(SUMPRODUCT(SUMIF(Final!$G$4:$G$330,CashReserveLevy!D65:F65,Final!$C$4:$C$330)),0) -> 3992568 | I65: =ROUND(H65*0.2,0) -> 798514 | J65: =ROUND(SUMPRODUCT(SUMIF(Final!$G$4:$G$330,CashReserveLevy!D65:F65,Final!$E$4:$E$330)),0) -> 1379301 | K65: =IF(I65>J65,I65-J65,0) -> 0 | L65: =INDEX(ActualCRLevy_SAS!$A$2:$D$326,MATCH(CashReserveLevy!$C65,ActualCRLevy_SAS!$B$2:$B$326,0),4) -> 0 | M65: =IF(AND(L65=K65,K65>0),"Max","") | N65: =IF(AND(L65<K65,L65=0),"No Levy but have Capacity","") | O65: =IF(L65>K65,"Exceedes Maximum Limit","") | Q65: =K65-L65 -> 0 | U65: 0 | V65: =K65-U65 -> 0
A66: 2024 | B66: 01 | C66: 2763 | F66: 2763 | G66: Clayton Ridge | H66: =ROUND(SUMPRODUCT(SUMIF(Final!$G$4:$G$330,CashReserveLevy!D66:F66,Final!$C$4:$C$330)),0) -> 13064172 | I66: =ROUND(H66*0.2,0) -> 2612834 | J66: =ROUND(SUMPRODUCT(SUMIF(Final!$G$4:$G$330,CashReserveLevy!D66:F66,Final!$E$4:$E$330)),0) -> 944483 | K66: =IF(I66>J66,I66-J66,0) -> 1668351 | L66: =INDEX(ActualCRLevy_SAS!$A$2:$D$326,MATCH(CashReserveLevy!$C66,ActualCRLevy_SAS!$B$2:$B$326,0),4) -> 100000 | M66: =IF(AND(L66=K66,K66>0),"Max","") | N66: =IF(AND(L66<K66,L66=0),"No Levy but have Capacity","") | O66: =IF(L66>K66,"Exceedes Maximum Limit","") | Q66: =K66-L66 -> 1568351 | U66: 1668351 | V66: =K66-U66 -> 0
A67: 2024 | B67: 10 | C67: 1221 | D67: 0216 | F67: 1221 | G67: Clear Creek-Amana | H67: =ROUND(SUMPRODUCT(SUMIF(Final!$G$4:$G$330,CashReserveLevy!D67:F67,Final!$C$4:$C$330)),0) -> 37470438 | I67: =ROUND(H67*0.2,0) -> 7494088 | J67: =ROUND(SUMPRODUCT(SUMIF(Final!$G$4:$G$330,CashReserveLevy!D67:F67,Final!$E$4:$E$330)),0) -> -909136 | K67: =IF(I67>J67,I67-J67,0) -> 8403224 | L67: =INDEX(ActualCRLevy_SAS!$A$2:$D$326,MATCH(CashReserveLevy!$C67,ActualCRLevy_SAS!$B$2:$B$326,0),4) -> 4007958 | M67: =IF(AND(L67=K67,K67>0),"Max","") | N67: =IF(AND(L67<K67,L67=0),"No Levy but have Capacity","") | O67: =IF(L67>K67,"Exceedes Maximum Limit","") | Q67: =K67-L67 -> 4395266 | U67: 8403224 | V67: =K67-U67 -> 0
A68: 2024 | B68: 07 | C68: 1233 | F68: 1233 | G68: Clear Lake | H68: =ROUND(SUMPRODUCT(SUMIF(Final!$G$4:$G$330,CashReserveLevy!D68:F68,Final!$C$4:$C$330)),0) -> 17352833 | I68: =ROUND(H68*0.2,0) -> 3470567 | J68: =ROUND(SUMPRODUCT(SUMIF(Final!$G$4:$G$330,CashReserveLevy!D68:F68,Final!$E$4:$E$330)),0) -> 4677478 | K68: =IF(I68>J68,I68-J68,0) -> 0 | L68: =INDEX(ActualCRLevy_SAS!$A$2:$D$326,MATCH(CashReserveLevy!$C68,ActualCRLevy_SAS!$B$2:$B$326,0),4) -> 0 | M68: =IF(AND(L68=K68,K68>0),"Max","") | N68: =IF(AND(L68<K68,L68=0),"No Levy but have Capacity","") | O68: =IF(L68>K68,"Exceedes Maximum Limit","") | Q68: =K68-L68 -> 0 | U68: 0 | V68: =K68-U68 -> 0
A69: 2024 | B69: 09 | C69: 1278 | F69: 1278 | G69: Clinton | H69: =ROUND(SUMPRODUCT(SUMIF(Final!$G$4:$G$330,CashReserveLevy!D69:F69,Final!$C$4:$C$330)),0) -> 49310052 | I69: =ROUND(H69*0.2,0) -> 9862010 | J69: =ROUND(SUMPRODUCT(SUMIF(Final!$G$4:$G$330,CashReserveLevy!D69:F69,Final!$E$4:$E$330)),0) -> 12196354 | K69: =IF(I69>J69,I69-J69,0) -> 0 | L69: =INDEX(ActualCRLevy_SAS!$A$2:$D$326,MATCH(CashReserveLevy!$C69,ActualCRLevy_SAS!$B$2:$B$326,0),4) -> 0 | M69: =IF(AND(L69=K69,K69>0),"Max","") | N69: =IF(AND(L69<K69,L69=0),"No Levy but have Capacity","") | O69: =IF(L69>K69,"Exceedes Maximum Limit","") | Q69: =K69-L69 -> 0 | U69: 0 | V69: =K69-U69 -> 0
A70: 2024 | B70: 11 | C70: 1332 | F70: 1332 | G70: Colfax-Mingo | H70: =ROUND(SUMPRODUCT(SUMIF(Final!$G$4:$G$330,CashReserveLevy!D70:F70,Final!$C$4:$C$330)),0) -> 10365807 | I70: =ROUND(H70*0.2,0) -> 2073161 | J70: =ROUND(SUMPRODUCT(SUMIF(Final!$G$4:$G$330,CashReserveLevy!D70:F70,Final!$E$4:$E$330)),0) -> 1293951 | K70: =IF(I70>J70,I70-J70,0) -> 779210 | L70: =INDEX(ActualCRLevy_SAS!$A$2:$D$326,MATCH(CashReserveLevy!$C70,ActualCRLevy_SAS!$B$2:$B$326,0),4) -> 779210 | M70: =IF(AND(L70=K70,K70>0),"Max","") -> Max | N70: =IF(AND(L70<K70,L70=0),"No Levy but have Capacity","") | O70: =IF(L70>K70,"Exceedes Maximum Limit","") | Q70: =K70-L70 -> 0 | U70: 779210 | V70: =K70-U70 -> 0
A71: 2024 | B71: 10 | C71: 1337 | F71: 1337 | G71: College Community | H71: =ROUND(SUMPRODUCT(SUMIF(Final!$G$4:$G$330,CashReserveLevy!D71:F71,Final!$C$4:$C$330)),0) -> 69631304 | I71: =ROUND(H71*0.2,0) -> 13926261 | J71: =ROUND(SUMPRODUCT(SUMIF(Final!$G$4:$G$330,CashReserveLevy!D71:F71,Final!$E$4:$E$330)),0) -> 13147650 | K71: =IF(I71>J71,I71-J71,0) -> 778611 | L71: =INDEX(ActualCRLevy_SAS!$A$2:$D$326,MATCH(CashReserveLevy!$C71,ActualCRLevy_SAS!$B$2:$B$326,0),4) -> 778611 | M71: =IF(AND(L71=K71,K71>0),"Max","") -> Max | N71: =IF(AND(L71<K71,L71=0),"No Levy but have Capacity","") | O71: =IF(L71>K71,"Exceedes Maximum Limit","") | Q71: =K71-L71 -> 0 | U71: 778611 | V71: =K71-U71 -> 0
A72: 2024 | B72: 11 | C72: 1350 | F72: 1350 | G72: Collins-Maxwell | H72: =ROUND(SUMPRODUCT(SUMIF(Final!$G$4:$G$330,CashReserveLevy!D72:F72,Final!$C$4:$C$330)),0) -> 6112293 | I72: =ROUND(H72*0.2,0) -> 1222459 | J72: =ROUND(SUMPRODUCT(SUMIF(Final!$G$4:$G$330,CashReserveLevy!D72:F72,Final!$E$4:$E$330)),0) -> 2298467 | K72: =IF(I72>J72,I72-J72,0) -> 0 | L72: =INDEX(ActualCRLevy_SAS!$A$2:$D$326,MATCH(CashReserveLevy!$C72,ActualCRLevy_SAS!$B$2:$B$326,0),4) -> 0 | M72: =IF(AND(L72=K72,K72>0),"Max","") | N72: =IF(AND(L72<K72,L72=0),"No Levy but have Capacity","") | O72: =IF(L72>K72,"Exceedes Maximum Limit","") | Q72: =K72-L72 -> 0 | U72: 0 | V72: =K72-U72 -> 0
A73: 2024 | B73: 11 | C73: 1359 | F73: 1359 | G73: Colo-Nesco | H73: =ROUND(SUMPRODUCT(SUMIF(Final!$G$4:$G$330,CashReserveLevy!D73:F73,Final!$C$4:$C$330)),0) -> 6342919 | I73: =ROUND(H73*0.2,0) -> 1268584 | J73: =ROUND(SUMPRODUCT(SUMIF(Final!$G$4:$G$330,CashReserveLevy!D73:F73,Final!$E$4:$E$330)),0) -> 578100 | K73: =IF(I73>J73,I73-J73,0) -> 690484 | L73: =INDEX(ActualCRLevy_SAS!$A$2:$D$326,MATCH(CashReserveLevy!$C73,ActualCRLevy_SAS!$B$2:$B$326,0),4) -> 460000 | M73: =IF(AND(L73=K73,K73>0),"Max","") | N73: =IF(AND(L73<K73,L73=0),"No Levy but have Capacity","") | O73: =IF(L73>K73,"Exceedes Maximum Limit","") | Q73: =K73-L73 -> 230484 | U73: 690484 | V73: =K73-U73 -> 0
A74: 2024 | B74: 09 | C74: 1368 | F74: 1368 | G74: Columbus | H74: =ROUND(SUMPRODUCT(SUMIF(Final!$G$4:$G$330,CashReserveLevy!D74:F74,Final!$C$4:$C$330)),0) -> 9396307 | I74: =ROUND(H74*0.2,0) -> 1879261 | J74: =ROUND(SUMPRODUCT(SUMIF(Final!$G$4:$G$330,CashReserveLevy!D74:F74,Final!$E$4:$E$330)),0) -> 4529087 | K74: =IF(I74>J74,I74-J74,0) -> 0 | L74: =INDEX(ActualCRLevy_SAS!$A$2:$D$326,MATCH(CashReserveLevy!$C74,ActualCRLevy_SAS!$B$2:$B$326,0),4) -> 0 | M74: =IF(AND(L74=K74,K74>0),"Max","") | N74: =IF(AND(L74<K74,L74=0),"No Levy but have Capacity","") | O74: =IF(L74>K74,"Exceedes Maximum Limit","") | Q74: =K74-L74 -> 0 | U74: 0 | V74: =K74-U74 -> 0
A75: 2024 | B75: 11 | C75: 1413 | F75: 1413 | G75: Coon Rapids-Bayard | H75: =ROUND(SUMPRODUCT(SUMIF(Final!$G$4:$G$330,CashReserveLevy!D75:F75,Final!$C$4:$C$330)),0) -> 5915096 | I75: =ROUND(H75*0.2,0) -> 1183019 | J75: =ROUND(SUMPRODUCT(SUMIF(Final!$G$4:$G$330,CashReserveLevy!D75:F75,Final!$E$4:$E$330)),0) -> 1991908 | K75: =IF(I75>J75,I75-J75,0) -> 0 | L75: =INDEX(ActualCRLevy_SAS!$A$2:$D$326,MATCH(CashReserveLevy!$C75,ActualCRLevy_SAS!$B$2:$B$326,0),4) -> 0 | M75: =IF(AND(L75=K75,K75>0),"Max","") | N75: =IF(AND(L75<K75,L75=0),"No Levy but have Capacity","") | O75: =IF(L75>K75,"Exceedes Maximum Limit","") | Q75: =K75-L75 -> 0 | U75: 0 | V75: =K75-U75 -> 0
A76: 2024 | B76: 13 | C76: 1431 | F76: 1431 | G76: Corning | H76: =ROUND(SUMPRODUCT(SUMIF(Final!$G$4:$G$330,CashReserveLevy!D76:F76,Final!$C$4:$C$330)),0) -> 6982419 | I76: =ROUND(H76*0.2,0) -> 1396484 | J76: =ROUND(SUMPRODUCT(SUMIF(Final!$G$4:$G$330,CashReserveLevy!D76:F76,Final!$E$4:$E$330)),0) -> 1929198 | K76: =IF(I76>J76,I76-J76,0) -> 0 | L76: =INDEX(ActualCRLevy_SAS!$A$2:$D$326,MATCH(CashReserveLevy!$C76,ActualCRLevy_SAS!$B$2:$B$326,0),4) -> 0 | M76: =IF(AND(L76=K76,K76>0),"Max","") | N76: =IF(AND(L76<K76,L76=0),"No Levy but have Capacity","") | O76: =IF(L76>K76,"Exceedes Maximum Limit","") | Q76: =K76-L76 -> 0 | U76: 0 | V76: =K76-U76 -> 0
...

Sheet Final
A1: FY22 Expenditures, Miscellaneous Income, Assigned/Unassigned Fund Balace, Total Fund Balance
A3: District Number | B3: District Name | C3: Expenditures | D3: Miscellaneous Income | E3: Assigned & Unassigned Fund Balance | F3: Total Fund Balance
A4: 9 | B4: AGWSR Comm School District | C4: 9940866.8 | D4: 1692562.9 | E4: 1221374.1 | F4: 1752298.7 | G4: 0009
A5: 18 | B5: Adair-Casey Comm School District | C5: 4593649.2 | D5: 1307082.4 | E5: 1435066.7 | F5: 1586394.9 | G5: 0018
A6: 27 | B6: Adel DeSoto Minburn Comm School District | C6: 24295219 | D6: 3671226.2 | E6: 5188021.8 | F6: 5815698.4 | G6: 0027
A7: 63 | B7: Akron Westfield Comm School District | C7: 8004280.8 | D7: 1613684.4 | E7: 1785711.7 | F7: 2097711.8 | G7: 0063
A8: 72 | B8: Albert City-Truesdale Comm School District | C8: 2809844.1 | D8: 487922.24 | E8: 1134405.5 | F8: 1314319 | G8: 0072
A9: 81 | B9: Albia Comm School District | C9: 14271156 | D9: 1853512.3 | E9: 4071860 | F9: 4458548.5 | G9: 0081
A10: 99 | B10: Alburnett Comm School District | C10: 8476602.7 | D10: 2566129.1 | E10: 1952461.9 | F10: 2003283.3 | G10: 0099
A11: 108 | B11: Alden Comm School District | C11: 3876813.6 | D11: 663383.29 | E11: 127456.8 | F11: 258367.39 | G11: 0108
A12: 126 | B12: Algona Comm School District | C12: 20353072 | D12: 4375610.9 | E12: 2697748.5 | F12: 3199103.3 | G12: 0126
A13: 135 | B13: Allamakee Comm School District | C13: 14603162 | D13: 2488267.8 | E13: 3081423.9 | F13: 3830037.7 | G13: 0135
A14: 153 | B14: North Butler Comm School District | C14: 8290295.9 | D14: 1769662.3 | E14: 1385554.1 | F14: 1627013.1 | G14: 0153
A15: 171 | B15: Alta-Aurelia Comm School District | C15: 11385819 | D15: 1873321.4 | E15: 1634401.8 | F15: 2327576.6 | G15: 0171
... A330: 7110 | B330: Woodward-Granger Comm School District | C330: 16694725 | D330: 5780303.8 | E330: 3166774.6 | F330: 3524464.9 | G330: 7110
C331: =SUM(C4:C330) -> 6.676211e+09 | D331: =SUM(D4:D330) -> 1.2068638e+09 | E331: =SUM(E4:E330) -> 1.3591158e+09 | F331: =SUM(F4:F330) -> 1.5855201e+09

Sheet ActualCRLevy_SAS
A1: FiscalYear | B1: Dist | C1: Label | D1: Final Cash Reserve Levy | E1: Final 6-15-2023
A2: 2024 | B2: 0009 | C2: AGWSR | D2: 370000
A3: 2024 | B3: 0441 | C3: AHSTW | D3: 0
A4: 2024 | B4: 0018 | C4: Adair-Casey | D4: 0
A5: 2024 | B5: 0027 | C5: Adel-Desoto-Minburn | D5: 0
A6: 2024 | B6: 0063 | C6: Akron-Westfield | D6: 0
A7: 2024 | B7: 0072 | C7: Albert City-Truesdale | D7: 0
A8: 2024 | B8: 0081 | C8: Albia | D8: 0
A9: 2024 | B9: 0099 | C9: Alburnett | D9: 0
A10: 2024 | B10: 0108 | C10: Alden | D10: 400000
A11: 2024 | B11: 0126 | C11: Algona | D11: 895900
A12: 2024 | B12: 0135 | C12: Allamakee | D12: 0
A13: 2024 | B13: 0171 | C13: Alta-Aurelia | D13: 350000
... A326: 2024 | B326: 7110 | C326: Woodward-Granger | D326: 172170
