Workbook
Name IDX: Final!$A$1

Sheet CashReserveLevy
G1: =_xlfn.CONCAT("SBRC FY ",A3," Final Cash Reserve Levy Limitations Source: FY ",A3-2," Certified Annual Report") -> SBRC FY 2026 Final Cash Reserve Levy Limitations Source: FY 2024 Certified Annual Report
A2: FiscalYear | B2: AEA | C2: Dist | D2: DistSub1 | E2: DistSub2 | F2: DistrictNumber | G2: Label | H2: Expenditures | I2: 20% of Expenditures | J2: Assigned and Unassigned Fund Balance | K2: Final Maximum Cash Reserve Levy | L2: Final Cash Reserve Levy | M2: Levying Maximum Cash Reserve
A3: 2026 | B3: 11 | C3: 0018 | F3: 0018 | G3: Adair-Casey | H3: =ROUND(SUMPRODUCT(SUMIF(Final!$G$4:$G$330,CashReserveLevy!D3:F3,Final!$C$4:$C$330)),0) -> 4907234 | I3: =ROUND(H3*0.2,0) -> 981447 | J3: =ROUND(SUMPRODUCT(SUMIF(Final!$G$4:$G$330,CashReserveLevy!D3:F3,Final!$E$4:$E$330)),0) -> 1437726 | K3: =IF(I3>J3,I3-J3,0) -> 0 | L3: =INDEX(ActualCRLevy_SAS!$A$2:$D$326,MATCH(CashReserveLevy!$C3,ActualCRLevy_SAS!$B$2:$B$326,0),4) -> 0 | M3: =IF(AND(L3=K3,K3>0),"Max","") | N3: =IF(AND(L3<K3,L3=0),"No Levy but have Capacity","") | O3: =IF(L3>K3,"Exceedes Maximum Limit","")
A4: 2026 | B4: 11 | C4: 0027 | F4: 0027 | G4: Adel-Desoto-Minburn | H4: =ROUND(SUMPRODUCT(SUMIF(Final!$G$4:$G$330,CashReserveLevy!D4:F4,Final!$C$4:$C$330)),0) -> 27144003 | I4: =ROUND(H4*0.2,0) -> 5428801 | J4: =ROUND(SUMPRODUCT(SUMIF(Final!$G$4:$G$330,CashReserveLevy!D4:F4,Final!$E$4:$E$330)),0) -> 4129415 | K4: =IF(I4>J4,I4-J4,0) -> 1299386 | L4: =INDEX(ActualCRLevy_SAS!$A$2:$D$326,MATCH(CashReserveLevy!$C4,ActualCRLevy_SAS!$B$2:$B$326,0),4) -> 1299386 | M4: =IF(AND(L4=K4,K4>0),"Max","") -> Max | N4: =IF(AND(L4<K4,L4=0),"No Levy but have Capacity","") | O4: =IF(L4>K4,"Exceedes Maximum Limit","")
A5: 2026 | B5: 07 | C5: 0009 | F5: 0009 | G5: AGWSR | H5: =ROUND(SUMPRODUCT(SUMIF(Final!$G$4:$G$330,CashReserveLevy!D5:F5,Final!$C$4:$C$330)),0) -> 10259078 | I5: =ROUND(H5*0.2,0) -> 2051816 | J5: =ROUND(SUMPRODUCT(SUMIF(Final!$G$4:$G$330,CashReserveLevy!D5:F5,Final!$E$4:$E$330)),0) -> -155502 | K5: =IF(I5>J5,I5-J5,0) -> 2207318 | L5: =INDEX(ActualCRLevy_SAS!$A$2:$D$326,MATCH(CashReserveLevy!$C5,ActualCRLevy_SAS!$B$2:$B$326,0),4) -> 1000000 | M5: =IF(AND(L5=K5,K5>0),"Max","") | N5: =IF(AND(L5<K5,L5=0),"No Levy but have Capacity","") | O5: =IF(L5>K5,"Exceedes Maximum Limit","")
A6: 2026 | B6: 13 | C6: 0441 | F6: 0441 | G6: AHSTW | H6: =ROUND(SUMPRODUCT(SUMIF(Final!$G$4:$G$330,CashReserveLevy!D6:F6,Final!$C$4:$C$330)),0) -> 10779050 | I6: =ROUND(H6*0.2,0) -> 2155810 | J6: =ROUND(SUMPRODUCT(SUMIF(Final!$G$4:$G$330,CashReserveLevy!D6:F6,Final!$E$4:$E$330)),0) -> 2037901 | K6: =IF(I6>J6,I6-J6,0) -> 117909 | L6: =INDEX(ActualCRLevy_SAS!$A$2:$D$326,MATCH(CashReserveLevy!$C6,ActualCRLevy_SAS!$B$2:$B$326,0),4) -> 117909 | M6: =IF(AND(L6=K6,K6>0),"Max","") -> Max | N6: =IF(AND(L6<K6,L6=0),"No Levy but have Capacity","") | O6: =IF(L6>K6,"Exceedes Maximum Limit","")
A7: 2026 | B7: 12 | C7: 0063 | F7: 0063 | G7: Akron-Westfield | H7: =ROUND(SUMPRODUCT(SUMIF(Final!$G$4:$G$330,CashReserveLevy!D7:F7,Final!$C$4:$C$330)),0) -> 8463070 | I7: =ROUND(H7*0.2,0) -> 1692614 | J7: =ROUND(SUMPRODUCT(SUMIF(Final!$G$4:$G$330,CashReserveLevy!D7:F7,Final!$E$4:$E$330)),0) -> 861251 | K7: =IF(I7>J7,I7-J7,0) -> 831363 | L7: =INDEX(ActualCRLevy_SAS!$A$2:$D$326,MATCH(CashReserveLevy!$C7,ActualCRLevy_SAS!$B$2:$B$326,0),4) -> 831363 | M7: =IF(AND(L7=K7,K7>0),"Max","") -> Max | N7: =IF(AND(L7<K7,L7=0),"No Levy but have Capacity","") | O7: =IF(L7>K7,"Exceedes Maximum Limit","")
A8: 2026 | B8: 05 | C8: 0072 | F8: 0072 | G8: Albert City-Truesdale | H8: =ROUND(SUMPRODUCT(SUMIF(Final!$G$4:$G$330,CashReserveLevy!D8:F8,Final!$C$4:$C$330)),0) -> 2967467 | I8: =ROUND(H8*0.2,0) -> 593493 | J8: =ROUND(SUMPRODUCT(SUMIF(Final!$G$4:$G$330,CashReserveLevy!D8:F8,Final!$E$4:$E$330)),0) -> 1552674 | K8: =IF(I8>J8,I8-J8,0) -> 0 | L8: =INDEX(ActualCRLevy_SAS!$A$2:$D$326,MATCH(CashReserveLevy!$C8,ActualCRLevy_SAS!$B$2:$B$326,0),4) -> 0 | M8: =IF(AND(L8=K8,K8>0),"Max","") | N8: =IF(AND(L8<K8,L8=0),"No Levy but have Capacity","") | O8: =IF(L8>K8,"Exceedes Maximum Limit","")
A9: 2026 | B9: 15 | C9: 0081 | F9: 0081 | G9: Albia | H9: =ROUND(SUMPRODUCT(SUMIF(Final!$G$4:$G$330,CashReserveLevy!D9:F9,Final!$C$4:$C$330)),0) -> 14649277 | I9: =ROUND(H9*0.2,0) -> 2929855 | J9: =ROUND(SUMPRODUCT(SUMIF(Final!$G$4:$G$330,CashReserveLevy!D9:F9,Final!$E$4:$E$330)),0) -> 4141165 | K9: =IF(I9>J9,I9-J9,0) -> 0 | L9: =INDEX(ActualCRLevy_SAS!$A$2:$D$326,MATCH(CashReserveLevy!$C9,ActualCRLevy_SAS!$B$2:$B$326,0),4) -> 0 | M9: =IF(AND(L9=K9,K9>0),"Max","") | N9: =IF(AND(L9<K9,L9=0),"No Levy but have Capacity","") | O9: =IF(L9>K9,"Exceedes Maximum Limit","")
A10: 2026 | B10: 10 | C10: 0099 | F10: 0099 | G10: Alburnett | H10: =ROUND(SUMPRODUCT(SUMIF(Final!$G$4:$G$330,CashReserveLevy!D10:F10,Final!$C$4:$C$330)),0) -> 9574247 | I10: =ROUND(H10*0.2,0) -> 1914849 | J10: =ROUND(SUMPRODUCT(SUMIF(Final!$G$4:$G$330,CashReserveLevy!D10:F10,Final!$E$4:$E$330)),0) -> 1279357 | K10: =IF(I10>J10,I10-J10,0) -> 635492 | L10: =INDEX(ActualCRLevy_SAS!$A$2:$D$326,MATCH(CashReserveLevy!$C10,ActualCRLevy_SAS!$B$2:$B$326,0),4) -> 300000 | M10: =IF(AND(L10=K10,K10>0),"Max","") | N10: =IF(AND(L10<K10,L10=0),"No Levy but have Capacity","") | O10: =IF(L10>K10,"Exceedes Maximum Limit","")
A11: 2026 | B11: 07 | C11: 0108 | F11: 0108 | G11: Alden | H11: =ROUND(SUMPRODUCT(SUMIF(Final!$G$4:$G$330,CashReserveLevy!D11:F11,Final!$C$4:$C$330)),0) -> 3882411 | I11: =ROUND(H11*0.2,0) -> 776482 | J11: =ROUND(SUMPRODUCT(SUMIF(Final!$G$4:$G$330,CashReserveLevy!D11:F11,Final!$E$4:$E$330)),0) -> 380516 | K11: =IF(I11>J11,I11-J11,0) -> 395966 | L11: =INDEX(ActualCRLevy_SAS!$A$2:$D$326,MATCH(CashReserveLevy!$C11,ActualCRLevy_SAS!$B$2:$B$326,0),4) -> 375000 | M11: =IF(AND(L11=K11,K11>0),"Max","") | N11: =IF(AND(L11<K11,L11=0),"No Levy but have Capacity","") | O11: =IF(L11>K11,"Exceedes Maximum Limit","")
A12: 2026 | B12: 05 | C12: 0126 | D12: 6417 | E12: 3897 | F12: 0126 | G12: Algona | H12: =ROUND(SUMPRODUCT(SUMIF(Final!$G$4:$G$330,CashReserveLevy!D12:F12,Final!$C$4:$C$330)),0) -> 22265557 | I12: =ROUND(H12*0.2,0) -> 4453111 | J12: =ROUND(SUMPRODUCT(SUMIF(Final!$G$4:$G$330,CashReserveLevy!D12:F12,Final!$E$4:$E$330)),0) -> 3638895 | K12: =IF(I12>J12,I12-J12,0) -> 814216 | L12: =INDEX(ActualCRLevy_SAS!$A$2:$D$326,MATCH(CashReserveLevy!$C12,ActualCRLevy_SAS!$B$2:$B$326,0),4) -> 814216 | M12: =IF(AND(L12=K12,K12>0),"Max","") -> Max | N12: =IF(AND(L12<K12,L12=0),"No Levy but have Capacity","") | O12: =IF(L12>K12,"Exceedes Maximum Limit","")
A13: 2026 | B13: 01 | C13: 0135 | F13: 0135 | G13: Allamakee | H13: =ROUND(SUMPRODUCT(SUMIF(Final!$G$4:$G$330,CashReserveLevy!D13:F13,Final!$C$4:$C$330)),0) -> 15125260 | I13: =ROUND(H13*0.2,0) -> 3025052 | J13: =ROUND(SUMPRODUCT(SUMIF(Final!$G$4:$G$330,CashReserveLevy!D13:F13,Final!$E$4:$E$330)),0) -> 1748725 | K13: =IF(I13>J13,I13-J13,0) -> 1276327 | L13: =INDEX(ActualCRLevy_SAS!$A$2:$D$326,MATCH(CashReserveLevy!$C13,ActualCRLevy_SAS!$B$2:$B$326,0),4) -> 400000 | M13: =IF(AND(L13=K13,K13>0),"Max","") | N13: =IF(AND(L13<K13,L13=0),"No Levy but have Capacity","") | O13: =IF(L13>K13,"Exceedes Maximum Limit","")
A14: 2026 | B14: 05 | C14: 0171 | F14: 0171 | G14: Alta-Aurelia | H14: =ROUND(SUMPRODUCT(SUMIF(Final!$G$4:$G$330,CashReserveLevy!D14:F14,Final!$C$4:$C$330)),0) -> 11750216 | I14: =ROUND(H14*0.2,0) -> 2350043 | J14: =ROUND(SUMPRODUCT(SUMIF(Final!$G$4:$G$330,CashReserveLevy!D14:F14,Final!$E$4:$E$330)),0) -> 1427391 | K14: =IF(I14>J14,I14-J14,0) -> 922652 | L14: =INDEX(ActualCRLevy_SAS!$A$2:$D$326,MATCH(CashReserveLevy!$C14,ActualCRLevy_SAS!$B$2:$B$326,0),4) -> 600000 | M14: =IF(AND(L14=K14,K14>0),"Max","") | N14: =IF(AND(L14<K14,L14=0),"No Levy but have Capacity","") | O14: =IF(L14>K14,"Exceedes Maximum Limit","")
A15: 2026 | B15: 11 | C15: 0225 | F15: 0225 | G15: Ames | H15: =ROUND(SUMPRODUCT(SUMIF(Final!$G$4:$G$330,CashReserveLevy!D15:F15,Final!$C$4:$C$330)),0) -> 65267651 | I15: =ROUND(H15*0.2,0) -> 13053530 | J15: =ROUND(SUMPRODUCT(SUMIF(Final!$G$4:$G$330,CashReserveLevy!D15:F15,Final!$E$4:$E$330)),0) -> 14130396 | K15: =IF(I15>J15,I15-J15,0) -> 0 | L15: =INDEX(ActualCRLevy_SAS!$A$2:$D$326,MATCH(CashReserveLevy!$C15,ActualCRLevy_SAS!$B$2:$B$326,0),4) -> 0 | M15: =IF(AND(L15=K15,K15>0),"Max","") | N15: =IF(AND(L15<K15,L15=0),"No Levy but have Capacity","") | O15: =IF(L15>K15,"Exceedes Maximum Limit","")
A16: 2026 | B16: 10 | C16: 0234 | F16: 0234 | G16: Anamosa | H16: =ROUND(SUMPRODUCT(SUMIF(Final!$G$4:$G$330,CashReserveLevy!D16:F16,Final!$C$4:$C$330)),0) -> 15431908 | I16: =ROUND(H16*0.2,0) -> 3086382 | J16: =ROUND(SUMPRODUCT(SUMIF(Final!$G$4:$G$330,CashReserveLevy!D16:F16,Final!$E$4:$E$330)),0) -> 5859509 | K16: =IF(I16>J16,I16-J16,0) -> 0 | L16: =INDEX(ActualCRLevy_SAS!$A$2:$D$326,MATCH(CashReserveLevy!$C16,ActualCRLevy_SAS!$B$2:$B$326,0),4) -> 0 | M16: =IF(AND(L16=K16,K16>0),"Max","") | N16: =IF(AND(L16<K16,L16=0),"No Levy but have Capacity","") | O16: =IF(L16>K16,"Exceedes Maximum Limit","")
A17: 2026 | B17: 09 | C17: 0243 | F17: 0243 | G17: Andrew | H17: =ROUND(SUMPRODUCT(SUMIF(Final!$G$4:$G$330,CashReserveLevy!D17:F17,Final!$C$4:$C$330)),0) -> 4658729 | I17: =ROUND(H17*0.2,0) -> 931746 | J17: =ROUND(SUMPRODUCT(SUMIF(Final!$G$4:$G$330,CashReserveLevy!D17:F17,Final!$E$4:$E$330)),0) -> 448207 | K17: =IF(I17>J17,I17-J17,0) -> 483539 | L17: =INDEX(ActualCRLevy_SAS!$A$2:$D$326,MATCH(CashReserveLevy!$C17,ActualCRLevy_SAS!$B$2:$B$326,0),4) -> 234020 | M17: =IF(AND(L17=K17,K17>0),"Max","") | N17: =IF(AND(L17<K17,L17=0),"No Levy but have Capacity","") | O17: =IF(L17>K17,"Exceedes Maximum Limit","")
A18: 2026 | B18: 11 | C18: 0261 | F18: 0261 | G18: Ankeny | H18: =ROUND(SUMPRODUCT(SUMIF(Final!$G$4:$G$330,CashReserveLevy!D18:F18,Final!$C$4:$C$330)),0) -> 164007723 | I18: =ROUND(H18*0.2,0) -> 32801545 | J18: =ROUND(SUMPRODUCT(SUMIF(Final!$G$4:$G$330,CashReserveLevy!D18:F18,Final!$E$4:$E$330)),0) -> 16833353 | K18: =IF(I18>J18,I18-J18,0) -> 15968192 | L18: =INDEX(ActualCRLevy_SAS!$A$2:$D$326,MATCH(CashReserveLevy!$C18,ActualCRLevy_SAS!$B$2:$B$326,0),4) -> 10750000 | M18: =IF(AND(L18=K18,K18>0),"Max","") | N18: =IF(AND(L18<K18,L18=0),"No Levy but have Capacity","") | O18: =IF(L18>K18,"Exceedes Maximum Limit","")
A19: 2026 | B19: 07 | C19: 0279 | F19: 0279 | G19: Aplington-Parkersburg | H19: =ROUND(SUMPRODUCT(SUMIF(Final!$G$4:$G$330,CashReserveLevy!D19:F19,Final!$C$4:$C$330)),0) -> 10493388 | I19: =ROUND(H19*0.2,0) -> 2098678 | J19: =ROUND(SUMPRODUCT(SUMIF(Final!$G$4:$G$330,CashReserveLevy!D19:F19,Final!$E$4:$E$330)),0) -> 3343883 | K19: =IF(I19>J19,I19-J19,0) -> 0 | L19: =INDEX(ActualCRLevy_SAS!$A$2:$D$326,MATCH(CashReserveLevy!$C19,ActualCRLevy_SAS!$B$2:$B$326,0),4) -> 0 | M19: =IF(AND(L19=K19,K19>0),"Max","") | N19: =IF(AND(L19<K19,L19=0),"No Levy but have Capacity","") | O19: =IF(L19>K19,"Exceedes Maximum Limit","")
A20: 2026 | B20: 12 | C20: 0355 | F20: 0355 | G20: Ar-We-Va | H20: =ROUND(SUMPRODUCT(SUMIF(Final!$G$4:$G$330,CashReserveLevy!D20:F20,Final!$C$4:$C$330)),0) -> 3771806 | I20: =ROUND(H20*0.2,0) -> 754361 | J20: =ROUND(SUMPRODUCT(SUMIF(Final!$G$4:$G$330,CashReserveLevy!D20:F20,Final!$E$4:$E$330)),0) -> 2760760 | K20: =IF(I20>J20,I20-J20,0) -> 0 | L20: =INDEX(ActualCRLevy_SAS!$A$2:$D$326,MATCH(CashReserveLevy!$C20,ActualCRLevy_SAS!$B$2:$B$326,0),4) -> 0 | M20: =IF(AND(L20=K20,K20>0),"Max","") | N20: =IF(AND(L20<K20,L20=0),"No Levy but have Capacity","") | O20: =IF(L20>K20,"Exceedes Maximum Limit","")
A21: 2026 | B21: 13 | C21: 0387 | F21: 0387 | G21: Atlantic | H21: =ROUND(SUMPRODUCT(SUMIF(Final!$G$4:$G$330,CashReserveLevy!D21:F21,Final!$C$4:$C$330)),0) -> 19748116 | I21: =ROUND(H21*0.2,0) -> 3949623 | J21: =ROUND(SUMPRODUCT(SUMIF(Final!$G$4:$G$330,CashReserveLevy!D21:F21,Final!$E$4:$E$330)),0) -> 5401605 | K21: =IF(I21>J21,I21-J21,0) -> 0 | L21: =INDEX(ActualCRLevy_SAS!$A$2:$D$326,MATCH(CashReserveLevy!$C21,ActualCRLevy_SAS!$B$2:$B$326,0),4) -> 0 | M21: =IF(AND(L21=K21,K21>0),"Max","") | N21: =IF(AND(L21<K21,L21=0),"No Levy but have Capacity","") | O21: =IF(L21>K21,"Exceedes Maximum Limit","")
A22: 2026 | B22: 11 | C22: 0414 | F22: 0414 | G22: Audubon | H22: =ROUND(SUMPRODUCT(SUMIF(Final!$G$4:$G$330,CashReserveLevy!D22:F22,Final!$C$4:$C$330)),0) -> 7771309 | I22: =ROUND(H22*0.2,0) -> 1554262 | J22: =ROUND(SUMPRODUCT(SUMIF(Final!$G$4:$G$330,CashReserveLevy!D22:F22,Final!$E$4:$E$330)),0) -> 2082294 | K22: =IF(I22>J22,I22-J22,0) -> 0 | L22: =INDEX(ActualCRLevy_SAS!$A$2:$D$326,MATCH(CashReserveLevy!$C22,ActualCRLevy_SAS!$B$2:$B$326,0),4) -> 0 | M22: =IF(AND(L22=K22,K22>0),"Max","") | N22: =IF(AND(L22<K22,L22=0),"No Levy but have Capacity","") | O22: =IF(L22>K22,"Exceedes Maximum Limit","")
A23: 2026 | B23: 11 | C23: 0472 | F23: 0472 | G23: Ballard | H23: =ROUND(SUMPRODUCT(SUMIF(Final!$G$4:$G$330,CashReserveLevy!D23:F23,Final!$C$4:$C$330)),0) -> 24250017 | I23: =ROUND(H23*0.2,0) -> 4850003 | J23: =ROUND(SUMPRODUCT(SUMIF(Final!$G$4:$G$330,CashReserveLevy!D23:F23,Final!$E$4:$E$330)),0) -> 1968321 | K23: =IF(I23>J23,I23-J23,0) -> 2881682 | L23: =INDEX(ActualCRLevy_SAS!$A$2:$D$326,MATCH(CashReserveLevy!$C23,ActualCRLevy_SAS!$B$2:$B$326,0),4) -> 2115000 | M23: =IF(AND(L23=K23,K23>0),"Max","") | N23: =IF(AND(L23<K23,L23=0),"No Levy but have Capacity","") | O23: =IF(L23>K23,"Exceedes Maximum Limit","")
A24: 2026 | B24: 11 | C24: 0513 | F24: 0513 | G24: Baxter | H24: =ROUND(SUMPRODUCT(SUMIF(Final!$G$4:$G$330,CashReserveLevy!D24:F24,Final!$C$4:$C$330)),0) -> 5835339 | I24: =ROUND(H24*0.2,0) -> 1167068 | J24: =ROUND(SUMPRODUCT(SUMIF(Final!$G$4:$G$330,CashReserveLevy!D24:F24,Final!$E$4:$E$330)),0) -> 657131 | K24: =IF(I24>J24,I24-J24,0) -> 509937 | L24: =INDEX(ActualCRLevy_SAS!$A$2:$D$326,MATCH(CashReserveLevy!$C24,ActualCRLevy_SAS!$B$2:$B$326,0),4) -> 365268 | M24: =IF(AND(L24=K24,K24>0),"Max","") | N24: =IF(AND(L24<K24,L24=0),"No Levy but have Capacity","") | O24: =IF(L24>K24,"Exceedes Maximum Limit","")
... A61: 2026 | B61: 13 | C61: 1197 | F61: 1197 | G61: Clarinda | H61: =ROUND(SUMPRODUCT(SUMIF(Final!$G$4:$G$330,CashReserveLevy!D61:F61,Final!$C$4:$C$330)),0) -> 14365730 | I61: =ROUND(H61*0.2,0) -> 2873146 | J61: =ROUND(SUMPRODUCT(SUMIF(Final!$G$4:$G$330,CashReserveLevy!D61:F61,Final!$E$4:$E$330)),0) -> 2129371 | K61: =IF(I61>J61,I61-J61,0) -> 743775 | L61: =INDEX(ActualCRLevy_SAS!$A$2:$D$326,MATCH(CashReserveLevy!$C61,ActualCRLevy_SAS!$B$2:$B$326,0),4) -> 743775 | M61: =IF(AND(L61=K61,K61>0),"Max","") -> Max | N61: =IF(AND(L61<K61,L61=0),"No Levy but have Capacity","") | O61: =IF(L61>K61,"Exceedes Maximum Limit","")
A62: 2026 | B62: 05 | C62: 1206 | D62: 1854 | F62: 1206 | G62: Clarion-Goldfield-Dows | H62: =ROUND(SUMPRODUCT(SUMIF(Final!$G$4:$G$330,CashReserveLevy!D62:F62,Final!$C$4:$C$330)),0) -> 14594100 | I62: =ROUND(H62*0.2,0) -> 2918820 | J62: =ROUND(SUMPRODUCT(SUMIF(Final!$G$4:$G$330,CashReserveLevy!D62:F62,Final!$E$4:$E$330)),0) -> 2298018 | K62: =IF(I62>J62,I62-J62,0) -> 620802 | L62: =INDEX(ActualCRLevy_SAS!$A$2:$D$326,MATCH(CashReserveLevy!$C62,ActualCRLevy_SAS!$B$2:$B$326,0),4) -> 620802 | M62: =IF(AND(L62=K62,K62>0),"Max","") -> Max | N62: =IF(AND(L62<K62,L62=0),"No Levy but have Capacity","") | O62: =IF(L62>K62,"Exceedes Maximum Limit","")
A63: 2026 | B63: 13 | C63: 1211 | F63: 1211 | G63: Clarke | H63: =ROUND(SUMPRODUCT(SUMIF(Final!$G$4:$G$330,CashReserveLevy!D63:F63,Final!$C$4:$C$330)),0) -> 20436675 | I63: =ROUND(H63*0.2,0) -> 4087335 | J63: =ROUND(SUMPRODUCT(SUMIF(Final!$G$4:$G$330,CashReserveLevy!D63:F63,Final!$E$4:$E$330)),0) -> 1855480 | K63: =IF(I63>J63,I63-J63,0) -> 2231855 | L63: =INDEX(ActualCRLevy_SAS!$A$2:$D$326,MATCH(CashReserveLevy!$C63,ActualCRLevy_SAS!$B$2:$B$326,0),4) -> 866423 | M63: =IF(AND(L63=K63,K63>0),"Max","") | N63: =IF(AND(L63<K63,L63=0),"No Levy but have Capacity","") | O63: =IF(L63>K63,"Exceedes Maximum Limit","")
A64: 2026 | B64: 07 | C64: 1215 | F64: 1215 | G64: Clarksville | H64: =ROUND(SUMPRODUCT(SUMIF(Final!$G$4:$G$330,CashReserveLevy!D64:F64,Final!$C$4:$C$330)),0) -> 4415093 | I64: =ROUND(H64*0.2,0) -> 883019 | J64: =ROUND(SUMPRODUCT(SUMIF(Final!$G$4:$G$330,CashReserveLevy!D64:F64,Final!$E$4:$E$330)),0) -> 692102 | K64: =IF(I64>J64,I64-J64,0) -> 190917 | L64: =INDEX(ActualCRLevy_SAS!$A$2:$D$326,MATCH(CashReserveLevy!$C64,ActualCRLevy_SAS!$B$2:$B$326,0),4) -> 175000 | M64: =IF(AND(L64=K64,K64>0),"Max","") | N64: =IF(AND(L64<K64,L64=0),"No Levy but have Capacity","") | O64: =IF(L64>K64,"Exceedes Maximum Limit","")
A65: 2026 | B65: 05 | C65: 1218 | F65: 1218 | G65: Clay Central-Everly | H65: =ROUND(SUMPRODUCT(SUMIF(Final!$G$4:$G$330,CashReserveLevy!D65:F65,Final!$C$4:$C$330)),0) -> 4172739 | I65: =ROUND(H65*0.2,0) -> 834548 | J65: =ROUND(SUMPRODUCT(SUMIF(Final!$G$4:$G$330,CashReserveLevy!D65:F65,Final!$E$4:$E$330)),0) -> 1626034 | K65: =IF(I65>J65,I65-J65,0) -> 0 | L65: =INDEX(ActualCRLevy_SAS!$A$2:$D$326,MATCH(CashReserveLevy!$C65,ActualCRLevy_SAS!$B$2:$B$326,0),4) -> 0 | M65: =IF(AND(L65=K65,K65>0),"Max","") | N65: =IF(AND(L65<K65,L65=0),"No Levy but have Capacity","") | O65: =IF(L65>K65,"Exceedes Maximum Limit","")
A66: 2026 | B66: 01 | C66: 2763 | F66: 2763 | G66: Clayton Ridge | H66: =ROUND(SUMPRODUCT(SUMIF(Final!$G$4:$G$330,CashReserveLevy!D66:F66,Final!$C$4:$C$330)),0) -> 17268032 | I66: =ROUND(H66*0.2,0) -> 3453606 | J66: =ROUND(SUMPRODUCT(SUMIF(Final!$G$4:$G$330,CashReserveLevy!D66:F66,Final!$E$4:$E$330)),0) -> 1125473 | K66: =IF(I66>J66,I66-J66,0) -> 2328133 | L66: =INDEX(ActualCRLevy_SAS!$A$2:$D$326,MATCH(CashReserveLevy!$C66,ActualCRLevy_SAS!$B$2:$B$326,0),4) -> 200000 | M66: =IF(AND(L66=K66,K66>0),"Max","") | N66: =IF(AND(L66<K66,L66=0),"No Levy but have Capacity","") | O66: =IF(L66>K66,"Exceedes Maximum Limit","")
A67: 2026 | B67: 10 | C67: 1221 | D67: 0216 | F67: 1221 | G67: Clear Creek-Amana | H67: =ROUND(SUMPRODUCT(SUMIF(Final!$G$4:$G$330,CashReserveLevy!D67:F67,Final!$C$4:$C$330)),0) -> 41176959 | I67: =ROUND(H67*0.2,0) -> 8235392 | J67: =ROUND(SUMPRODUCT(SUMIF(Final!$G$4:$G$330,CashReserveLevy!D67:F67,Final!$E$4:$E$330)),0) -> 2881128 | K67: =IF(I67>J67,I67-J67,0) -> 5354264 | L67: =INDEX(ActualCRLevy_SAS!$A$2:$D$326,MATCH(CashReserveLevy!$C67,ActualCRLevy_SAS!$B$2:$B$326,0),4) -> 2342248 | M67: =IF(AND(L67=K67,K67>0),"Max","") | N67: =IF(AND(L67<K67,L67=0),"No Levy but have Capacity","") | O67: =IF(L67>K67,"Exceedes Maximum Limit","")
A68: 2026 | B68: 07 | C68: 1233 | F68: 1233 | G68: Clear Lake | H68: =ROUND(SUMPRODUCT(SUMIF(Final!$G$4:$G$330,CashReserveLevy!D68:F68,Final!$C$4:$C$330)),0) -> 18176111 | I68: =ROUND(H68*0.2,0) -> 3635222 | J68: =ROUND(SUMPRODUCT(SUMIF(Final!$G$4:$G$330,CashReserveLevy!D68:F68,Final!$E$4:$E$330)),0) -> 4309564 | K68: =IF(I68>J68,I68-J68,0) -> 0 | L68: =INDEX(ActualCRLevy_SAS!$A$2:$D$326,MATCH(CashReserveLevy!$C68,ActualCRLevy_SAS!$B$2:$B$326,0),4) -> 0 | M68: =IF(AND(L68=K68,K68>0),"Max","") | N68: =IF(AND(L68<K68,L68=0),"No Levy but have Capacity","") | O68: =IF(L68>K68,"Exceedes Maximum Limit","")
A69: 2026 | B69: 09 | C69: 1278 | F69: 1278 | G69: Clinton | H69: =ROUND(SUMPRODUCT(SUMIF(Final!$G$4:$G$330,CashReserveLevy!D69:F69,Final!$C$4:$C$330)),0) -> 54456517 | I69: =ROUND(H69*0.2,0) -> 10891303 | J69: =ROUND(SUMPRODUCT(SUMIF(Final!$G$4:$G$330,CashReserveLevy!D69:F69,Final!$E$4:$E$330)),0) -> 9736878 | K69: =IF(I69>J69,I69-J69,0) -> 1154425 | L69: =INDEX(ActualCRLevy_SAS!$A$2:$D$326,MATCH(CashReserveLevy!$C69,ActualCRLevy_SAS!$B$2:$B$326,0),4) -> 800000 | M69: =IF(AND(L69=K69,K69>0),"Max","") | N69: =IF(AND(L69<K69,L69=0),"No Levy but have Capacity","") | O69: =IF(L69>K69,"Exceedes Maximum Limit","")
A70: 2026 | B70: 11 | C70: 1332 | F70: 1332 | G70: Colfax-Mingo | H70: =ROUND(SUMPRODUCT(SUMIF(Final!$G$4:$G$330,CashReserveLevy!D70:F70,Final!$C$4:$C$330)),0) -> 11494477 | I70: =ROUND(H70*0.2,0) -> 2298895 | J70: =ROUND(SUMPRODUCT(SUMIF(Final!$G$4:$G$330,CashReserveLevy!D70:F70,Final!$E$4:$E$330)),0) -> 42040 | K70: =IF(I70>J70,I70-J70,0) -> 2256855 | L70: =INDEX(ActualCRLevy_SAS!$A$2:$D$326,MATCH(CashReserveLevy!$C70,ActualCRLevy_SAS!$B$2:$B$326,0),4) -> 675000 | M70: =IF(AND(L70=K70,K70>0),"Max","") | N70: =IF(AND(L70<K70,L70=0),"No Levy but have Capacity","") | O70: =IF(L70>K70,"Exceedes Maximum Limit","")
A71: 2026 | B71: 10 | C71: 1337 | F71: 1337 | G71: College Community | H71: =ROUND(SUMPRODUCT(SUMIF(Final!$G$4:$G$330,CashReserveLevy!D71:F71,Final!$C$4:$C$330)),0) -> 75466834 | I71: =ROUND(H71*0.2,0) -> 15093367 | J71: =ROUND(SUMPRODUCT(SUMIF(Final!$G$4:$G$330,CashReserveLevy!D71:F71,Final!$E$4:$E$330)),0) -> 8872175 | K71: =IF(I71>J71,I71-J71,0) -> 6221192 | L71: =INDEX(ActualCRLevy_SAS!$A$2:$D$326,MATCH(CashReserveLevy!$C71,ActualCRLevy_SAS!$B$2:$B$326,0),4) -> 6221192 | M71: =IF(AND(L71=K71,K71>0),"Max","") -> Max | N71: =IF(AND(L71<K71,L71=0),"No Levy but have Capacity","") | O71: =IF(L71>K71,"Exceedes Maximum Limit","")
A72: 2026 | B72: 11 | C72: 1350 | F72: 1350 | G72: Collins-Maxwell | H72: =ROUND(SUMPRODUCT(SUMIF(Final!$G$4:$G$330,CashReserveLevy!D72:F72,Final!$C$4:$C$330)),0) -> 6185648 | I72: =ROUND(H72*0.2,0) -> 1237130 | J72: =ROUND(SUMPRODUCT(SUMIF(Final!$G$4:$G$330,CashReserveLevy!D72:F72,Final!$E$4:$E$330)),0) -> 2144701 | K72: =IF(I72>J72,I72-J72,0) -> 0 | L72: =INDEX(ActualCRLevy_SAS!$A$2:$D$326,MATCH(CashReserveLevy!$C72,ActualCRLevy_SAS!$B$2:$B$326,0),4) -> 0 | M72: =IF(AND(L72=K72,K72>0),"Max","") | N72: =IF(AND(L72<K72,L72=0),"No Levy but have Capacity","") | O72: =IF(L72>K72,"Exceedes Maximum Limit","")
A73: 2026 | B73: 11 | C73: 1359 | F73: 1359 | G73: Colo-Nesco | H73: =ROUND(SUMPRODUCT(SUMIF(Final!$G$4:$G$330,CashReserveLevy!D73:F73,Final!$C$4:$C$330)),0) -> 7041403 | I73: =ROUND(H73*0.2,0) -> 1408281 | J73: =ROUND(SUMPRODUCT(SUMIF(Final!$G$4:$G$330,CashReserveLevy!D73:F73,Final!$E$4:$E$330)),0) -> 540114 | K73: =IF(I73>J73,I73-J73,0) -> 868167 | L73: =INDEX(ActualCRLevy_SAS!$A$2:$D$326,MATCH(CashReserveLevy!$C73,ActualCRLevy_SAS!$B$2:$B$326,0),4) -> 500000 | M73: =IF(AND(L73=K73,K73>0),"Max","") | N73: =IF(AND(L73<K73,L73=0),"No Levy but have Capacity","") | O73: =IF(L73>K73,"Exceedes Maximum Limit","")
A74: 2026 | B74: 09 | C74: 1368 | F74: 1368 | G74: Columbus | H74: =ROUND(SUMPRODUCT(SUMIF(Final!$G$4:$G$330,CashReserveLevy!D74:F74,Final!$C$4:$C$330)),0) -> 11130300 | I74: =ROUND(H74*0.2,0) -> 2226060 | J74: =ROUND(SUMPRODUCT(SUMIF(Final!$G$4:$G$330,CashReserveLevy!D74:F74,Final!$E$4:$E$330)),0) -> 4565508 | K74: =IF(I74>J74,I74-J74,0) -> 0 | L74: =INDEX(ActualCRLevy_SAS!$A$2:$D$326,MATCH(CashReserveLevy!$C74,ActualCRLevy_SAS!$B$2:$B$326,0),4) -> 0 | M74: =IF(AND(L74=K74,K74>0),"Max","") | N74: =IF(AND(L74<K74,L74=0),"No Levy but have Capacity","") | O74: =IF(L74>K74,"Exceedes Maximum Limit","")
A75: 2026 | B75: 11 | C75: 1413 | F75: 1413 | G75: Coon Rapids-Bayard | H75: =ROUND(SUMPRODUCT(SUMIF(Final!$G$4:$G$330,CashReserveLevy!D75:F75,Final!$C$4:$C$330)),0) -> 5592018 | I75: =ROUND(H75*0.2,0) -> 1118404 | J75: =ROUND(SUMPRODUCT(SUMIF(Final!$G$4:$G$330,CashReserveLevy!D75:F75,Final!$E$4:$E$330)),0) -> 2861913 | K75: =IF(I75>J75,I75-J75,0) -> 0 | L75: =INDEX(ActualCRLevy_SAS!$A$2:$D$326,MATCH(CashReserveLevy!$C75,ActualCRLevy_SAS!$B$2:$B$326,0),4) -> 0 | M75: =IF(AND(L75=K75,K75>0),"Max","") | N75: =IF(AND(L75<K75,L75=0),"No Levy but have Capacity","") | O75: =IF(L75>K75,"Exceedes Maximum Limit","")
A76: 2026 | B76: 13 | C76: 1431 | F76: 1431 | G76: Corning | H76: =ROUND(SUMPRODUCT(SUMIF(Final!$G$4:$G$330,CashReserveLevy!D76:F76,Final!$C$4:$C$330)),0) -> 6664449 | I76: =ROUND(H76*0.2,0) -> 1332890 | J76: =ROUND(SUMPRODUCT(SUMIF(Final!$G$4:$G$330,CashReserveLevy!D76:F76,Final!$E$4:$E$330)),0) -> 1902130 | K76: =IF(I76>J76,I76-J76,0) -> 0 | L76: =INDEX(ActualCRLevy_SAS!$A$2:$D$326,MATCH(CashReserveLevy!$C76,ActualCRLevy_SAS!$B$2:$B$326,0),4) -> 0 | M76: =IF(AND(L76=K76,K76>0),"Max","") | N76: =IF(AND(L76<K76,L76=0),"No Levy but have Capacity","") | O76: =IF(L76>K76,"Exceedes Maximum Limit","")
...

Sheet Final
A1: FY24 Expenditures, Miscellaneous Income, Assigned/Unassigned Fund Balace, Total Fund Balance - Final
A3: Agency Number | B3: Agency Name | C3: Expenditures | D3: Miscellaneous Income | E3: Assigned & Unassigned Fund Balance | F3: Total Fund Balance
A4: 9 | B4: AGWSR Comm School District | C4: 10259078 | D4: 1013438.3 | E4: -155501.85 | F4: 487213.7 | G4: =TEXT(A4,"0000") -> 0009
A5: 18 | B5: Adair-Casey Comm School District | C5: 4907234.2 | D5: 1324784.4 | E5: 1437725.9 | F5: 1589963 | G5: =TEXT(A5,"0000") -> 0018
A6: 27 | B6: Adel DeSoto Minburn Comm School District | C6: 27144003 | D6: 3518011.7 | E6: 4129415.2 | F6: 5243672.6 | G6: =TEXT(A6,"0000") -> 0027
A7: 63 | B7: Akron Westfield Comm School District | C7: 8463069.6 | D7: 1513795.6 | E7: 861250.52 | F7: 1354462.3 | G7: =TEXT(A7,"0000") -> 0063
A8: 72 | B8: Albert City-Truesdale Comm School District | C8: 2967467 | D8: 507070.49 | E8: 1552673.8 | F8: 1648347.4 | G8: =TEXT(A8,"0000") -> 0072
A9: 81 | B9: Albia Comm School District | C9: 14649277 | D9: 2153367.1 | E9: 4141164.8 | F9: 4330667.8 | G9: =TEXT(A9,"0000") -> 0081
A10: 99 | B10: Alburnett Comm School District | C10: 9574247.4 | D10: 3366760.9 | E10: 1279357.2 | F10: 1396816.6 | G10: =TEXT(A10,"0000") -> 0099
A11: 108 | B11: Alden Comm School District | C11: 3882411.4 | D11: 508751.07 | E11: 380516.29 | F11: 641113.64 | G11: =TEXT(A11,"0000") -> 0108
A12: 126 | B12: Algona Comm School District | C12: 22265557 | D12: 3291012.8 | E12: 3638894.6 | F12: 4239198 | G12: =TEXT(A12,"0000") -> 0126
A13: 135 | B13: Allamakee Comm School District | C13: 15125260 | D13: 2444149 | E13: 1748724.6 | F13: 2440450.5 | G13: =TEXT(A13,"0000") -> 0135
A14: 153 | B14: North Butler Comm School District | C14: 7898950.8 | D14: 1359378.8 | E14: 1535841.6 | F14: 1897762.9 | G14: =TEXT(A14,"0000") -> 0153
A15: 171 | B15: Alta-Aurelia Comm School District | C15: 11750216 | D15: 1388374.9 | E15: 1427391.2 | F15: 2013651.9 | G15: =TEXT(A15,"0000") -> 0171
... A330: 8200 | B330: Charter Organization: Concept Schools | C330: 2998247.2 | D330: 4195460.8 | E330: 461371.18 | F330: 532332.51 | G330: =TEXT(A330,"0000") -> 8200
C331: =SUM(C4:C328) -> 7.1028868e+09 | D331: =SUM(D4:D328) -> 1.2060084e+09 | E331: =SUM(E4:E328) -> 1.3741061e+09 | F331: =SUM(F4:F328) -> 1.5956968e+09

Sheet ActualCRLevy_SAS
A1: FiscalYear | B1: Dist | C1: Label | D1: Final Cash Reserve Levy | E1: Final 6-25-2025
A2: 2026 | B2: 0009 | C2: AGWSR | D2: 1000000
A3: 2026 | B3: 0441 | C3: AHSTW | D3: 117909
A4: 2026 | B4: 0018 | C4: Adair-Casey | D4: 0
A5: 2026 | B5: 0027 | C5: Adel-Desoto-Minburn | D5: 1299386
A6: 2026 | B6: 0063 | C6: Akron-Westfield | D6: 831363
A7: 2026 | B7: 0072 | C7: Albert City-Truesdale | D7: 0
A8: 2026 | B8: 0081 | C8: Albia | D8: 0
A9: 2026 | B9: 0099 | C9: Alburnett | D9: 300000
A10: 2026 | B10: 0108 | C10: Alden | D10: 375000
A11: 2026 | B11: 0126 | C11: Algona | D11: 814216
A12: 2026 | B12: 0135 | C12: Allamakee | D12: 400000
A13: 2026 | B13: 0171 | C13: Alta-Aurelia | D13: 600000
... A326: 2026 | B326: 7110 | C326: Woodward-Granger | D326: 1025000
