Workbook

Sheet Assessed Non-TIF
A1: Iowa Department of Management - June 25, 2025 - Final
A2: =_xlfn.CONCAT("January 1, ",AssessedValuation[[#This Row],[Year]]," - 100% Valuations Before Rollback") -> January 1, 2024 - 100% Valuations Before Rollback
A3: =_xlfn.CONCAT("For Fiscal Year ",'2024_School_100pct Valuations B'!A2+2," Budgets") -> For Fiscal Year 2026 Budgets
A4: Non-TIF
A6: FiscalYear | B6: AEA | C6: Dist | D6: DistrictNumber | E6: NAME | F6: Label | G6: 100% Residential | H6: 100% Ag Land | I6: 100% Ag Building | J6: 100% Commercial | K6: 100% Industrial | L6: 100% Reserved | M6: 100% Reserved | N6: 100% Railroads | O6: 100% Utilities | P6: 100% Other | Q6: 100% Gross | R6: 100% Military Exempt | S6: 100% Homestead Exempt | T6: 100% Net | U6: 100% Gas & Elec Utilities | V6: Valuation With G&E Utilities
A7: 2026 | B7: 11 | C7: 0018 | D7: 0018 | E7: ADAIR-CASEY | F7: Adair-Casey | G7: =SUMIFS(AssessedValuation[100% Residential],AssessedValuation[Dist],$C7,AssessedValuation[Tif_NonTIF],$A$4) -> 112934849 | H7: =SUMIFS(AssessedValuation[100% Ag Land],AssessedValuation[Dist],$C7,AssessedValuation[Tif_NonTIF],$A$4) -> 120815774 | I7: =SUMIFS(AssessedValuation[100% Ag Building],AssessedValuation[Dist],$C7,AssessedValuation[Tif_NonTIF],$A$4) -> 4669820 | J7: =SUMIFS(AssessedValuation[100% Commercial],AssessedValuation[Dist],$C7,AssessedValuation[Tif_NonTIF],$A$4) -> 20844537 | K7: =SUMIFS(AssessedValuation[100% Industrial],AssessedValuation[Dist],$C7,AssessedValuation[Tif_NonTIF],$A$4) -> 35843801 | L7: =SUMIFS(AssessedValuation[100% Reserved],AssessedValuation[Dist],$C7,AssessedValuation[Tif_NonTIF],$A$4) -> 0 | M7: =SUMIFS(AssessedValuation[100% Reserved4],AssessedValuation[Dist],$C7,AssessedValuation[Tif_NonTIF],$A$4) -> 0 | N7: =SUMIFS(AssessedValuation[100% Railroads],AssessedValuation[Dist],$C7,AssessedValuation[Tif_NonTIF],$A$4) -> 3906523 | O7: =SUMIFS(AssessedValuation[100% Utilities],AssessedValuation[Dist],$C7,AssessedValuation[Tif_NonTIF],$A$4) -> 214215 | P7: =SUMIFS(AssessedValuation[100% Other],AssessedValuation[Dist],$C7,AssessedValuation[Tif_NonTIF],$A$4) -> 0 | Q7: =SUMIFS(AssessedValuation[100% Gross],AssessedValuation[Dist],$C7,AssessedValuation[Tif_NonTIF],$A$4) -> 299229519 | R7: =SUMIFS(AssessedValuation[100% Military Exempt],AssessedValuation[Dist],$C7,AssessedValuation[Tif_NonTIF],$A$4) -> 352000 | S7: =SUMIFS(AssessedValuation[100% Homestead Exempt],AssessedValuation[Dist],$C7,AssessedValuation[Tif_NonTIF],$A$4) -> 1014000 | T7: =SUMIFS(AssessedValuation[100% Net],AssessedValuation[Dist],$C7,AssessedValuation[Tif_NonTIF],$A$4) -> 297863519 | U7: =SUMIFS(AssessedValuation[100% Gas & Elec Utilities],AssessedValuation[Dist],$C7,AssessedValuation[Tif_NonTIF],$A$4) -> 103168214 | V7: =SUM(T7:U7) -> 401031733
A8: 2026 | B8: 11 | C8: 0027 | D8: 0027 | E8: ADEL-DESOTO-MINBURN | F8: Adel-Desoto-Minburn | G8: =SUMIFS(AssessedValuation[100% Residential],AssessedValuation[Dist],$C8,AssessedValuation[Tif_NonTIF],$A$4) -> 1140342743 | H8: =SUMIFS(AssessedValuation[100% Ag Land],AssessedValuation[Dist],$C8,AssessedValuation[Tif_NonTIF],$A$4) -> 114643770 | I8: =SUMIFS(AssessedValuation[100% Ag Building],AssessedValuation[Dist],$C8,AssessedValuation[Tif_NonTIF],$A$4) -> 5814100 | J8: =SUMIFS(AssessedValuation[100% Commercial],AssessedValuation[Dist],$C8,AssessedValuation[Tif_NonTIF],$A$4) -> 118479234 | K8: =SUMIFS(AssessedValuation[100% Industrial],AssessedValuation[Dist],$C8,AssessedValuation[Tif_NonTIF],$A$4) -> 27809531 | L8: =SUMIFS(AssessedValuation[100% Reserved],AssessedValuation[Dist],$C8,AssessedValuation[Tif_NonTIF],$A$4) -> 0 | M8: =SUMIFS(AssessedValuation[100% Reserved4],AssessedValuation[Dist],$C8,AssessedValuation[Tif_NonTIF],$A$4) -> 0 | N8: =SUMIFS(AssessedValuation[100% Railroads],AssessedValuation[Dist],$C8,AssessedValuation[Tif_NonTIF],$A$4) -> 1419212 | O8: =SUMIFS(AssessedValuation[100% Utilities],AssessedValuation[Dist],$C8,AssessedValuation[Tif_NonTIF],$A$4) -> 12466003 | P8: =SUMIFS(AssessedValuation[100% Other],AssessedValuation[Dist],$C8,AssessedValuation[Tif_NonTIF],$A$4) -> 0 | Q8: =SUMIFS(AssessedValuation[100% Gross],AssessedValuation[Dist],$C8,AssessedValuation[Tif_NonTIF],$A$4) -> 1420974593 | R8: =SUMIFS(AssessedValuation[100% Military Exempt],AssessedValuation[Dist],$C8,AssessedValuation[Tif_NonTIF],$A$4) -> 1243313 | S8: =SUMIFS(AssessedValuation[100% Homestead Exempt],AssessedValuation[Dist],$C8,AssessedValuation[Tif_NonTIF],$A$4) -> 4055303 | T8: =SUMIFS(AssessedValuation[100% Net],AssessedValuation[Dist],$C8,AssessedValuation[Tif_NonTIF],$A$4) -> 1415675977 | U8: =SUMIFS(AssessedValuation[100% Gas & Elec Utilities],AssessedValuation[Dist],$C8,AssessedValuation[Tif_NonTIF],$A$4) -> 186406186 | V8: =SUM(T8:U8) -> 1602082163
A9: 2026 | B9: 07 | C9: 0009 | D9: 0009 | E9: AGWSR | F9: AGWSR | G9: =SUMIFS(AssessedValuation[100% Residential],AssessedValuation[Dist],$C9,AssessedValuation[Tif_NonTIF],$A$4) -> 248859770 | H9: =SUMIFS(AssessedValuation[100% Ag Land],AssessedValuation[Dist],$C9,AssessedValuation[Tif_NonTIF],$A$4) -> 311279110 | I9: =SUMIFS(AssessedValuation[100% Ag Building],AssessedValuation[Dist],$C9,AssessedValuation[Tif_NonTIF],$A$4) -> 26371710 | J9: =SUMIFS(AssessedValuation[100% Commercial],AssessedValuation[Dist],$C9,AssessedValuation[Tif_NonTIF],$A$4) -> 35639926 | K9: =SUMIFS(AssessedValuation[100% Industrial],AssessedValuation[Dist],$C9,AssessedValuation[Tif_NonTIF],$A$4) -> 89018914 | L9: =SUMIFS(AssessedValuation[100% Reserved],AssessedValuation[Dist],$C9,AssessedValuation[Tif_NonTIF],$A$4) -> 0 | M9: =SUMIFS(AssessedValuation[100% Reserved4],AssessedValuation[Dist],$C9,AssessedValuation[Tif_NonTIF],$A$4) -> 0 | N9: =SUMIFS(AssessedValuation[100% Railroads],AssessedValuation[Dist],$C9,AssessedValuation[Tif_NonTIF],$A$4) -> 3608673 | O9: =SUMIFS(AssessedValuation[100% Utilities],AssessedValuation[Dist],$C9,AssessedValuation[Tif_NonTIF],$A$4) -> 27472612 | P9: =SUMIFS(AssessedValuation[100% Other],AssessedValuation[Dist],$C9,AssessedValuation[Tif_NonTIF],$A$4) -> 0 | Q9: =SUMIFS(AssessedValuation[100% Gross],AssessedValuation[Dist],$C9,AssessedValuation[Tif_NonTIF],$A$4) -> 742250715 | R9: =SUMIFS(AssessedValuation[100% Military Exempt],AssessedValuation[Dist],$C9,AssessedValuation[Tif_NonTIF],$A$4) -> 868000 | S9: =SUMIFS(AssessedValuation[100% Homestead Exempt],AssessedValuation[Dist],$C9,AssessedValuation[Tif_NonTIF],$A$4) -> 3243500 | T9: =SUMIFS(AssessedValuation[100% Net],AssessedValuation[Dist],$C9,AssessedValuation[Tif_NonTIF],$A$4) -> 738139215 | U9: =SUMIFS(AssessedValuation[100% Gas & Elec Utilities],AssessedValuation[Dist],$C9,AssessedValuation[Tif_NonTIF],$A$4) -> 94988696 | V9: =SUM(T9:U9) -> 833127911
A10: 2026 | B10: 13 | C10: 0441 | D10: 0441 | E10: AHSTW | F10: AHSTW | G10: =SUMIFS(AssessedValuation[100% Residential],AssessedValuation[Dist],$C10,AssessedValuation[Tif_NonTIF],$A$4) -> 334581837 | H10: =SUMIFS(AssessedValuation[100% Ag Land],AssessedValuation[Dist],$C10,AssessedValuation[Tif_NonTIF],$A$4) -> 343923406 | I10: =SUMIFS(AssessedValuation[100% Ag Building],AssessedValuation[Dist],$C10,AssessedValuation[Tif_NonTIF],$A$4) -> 12892389 | J10: =SUMIFS(AssessedValuation[100% Commercial],AssessedValuation[Dist],$C10,AssessedValuation[Tif_NonTIF],$A$4) -> 51722221 | K10: =SUMIFS(AssessedValuation[100% Industrial],AssessedValuation[Dist],$C10,AssessedValuation[Tif_NonTIF],$A$4) -> 140099164 | L10: =SUMIFS(AssessedValuation[100% Reserved],AssessedValuation[Dist],$C10,AssessedValuation[Tif_NonTIF],$A$4) -> 0 | M10: =SUMIFS(AssessedValuation[100% Reserved4],AssessedValuation[Dist],$C10,AssessedValuation[Tif_NonTIF],$A$4) -> 0 | N10: =SUMIFS(AssessedValuation[100% Railroads],AssessedValuation[Dist],$C10,AssessedValuation[Tif_NonTIF],$A$4) -> 4803487 | O10: =SUMIFS(AssessedValuation[100% Utilities],AssessedValuation[Dist],$C10,AssessedValuation[Tif_NonTIF],$A$4) -> 2997056 | P10: =SUMIFS(AssessedValuation[100% Other],AssessedValuation[Dist],$C10,AssessedValuation[Tif_NonTIF],$A$4) -> 272 | Q10: =SUMIFS(AssessedValuation[100% Gross],AssessedValuation[Dist],$C10,AssessedValuation[Tif_NonTIF],$A$4) -> 891019832 | R10: =SUMIFS(AssessedValuation[100% Military Exempt],AssessedValuation[Dist],$C10,AssessedValuation[Tif_NonTIF],$A$4) -> 1040000 | S10: =SUMIFS(AssessedValuation[100% Homestead Exempt],AssessedValuation[Dist],$C10,AssessedValuation[Tif_NonTIF],$A$4) -> 2522000 | T10: =SUMIFS(AssessedValuation[100% Net],AssessedValuation[Dist],$C10,AssessedValuation[Tif_NonTIF],$A$4) -> 887457832 | U10: =SUMIFS(AssessedValuation[100% Gas & Elec Utilities],AssessedValuation[Dist],$C10,AssessedValuation[Tif_NonTIF],$A$4) -> 85858755 | V10: =SUM(T10:U10) -> 973316587
A11: 2026 | B11: 12 | C11: 0063 | D11: 0063 | E11: AKRON-WESTFIELD | F11: Akron-Westfield | G11: =SUMIFS(AssessedValuation[100% Residential],AssessedValuation[Dist],$C11,AssessedValuation[Tif_NonTIF],$A$4) -> 256588093 | H11: =SUMIFS(AssessedValuation[100% Ag Land],AssessedValuation[Dist],$C11,AssessedValuation[Tif_NonTIF],$A$4) -> 153240220 | I11: =SUMIFS(AssessedValuation[100% Ag Building],AssessedValuation[Dist],$C11,AssessedValuation[Tif_NonTIF],$A$4) -> 10883100 | J11: =SUMIFS(AssessedValuation[100% Commercial],AssessedValuation[Dist],$C11,AssessedValuation[Tif_NonTIF],$A$4) -> 28136637 | K11: =SUMIFS(AssessedValuation[100% Industrial],AssessedValuation[Dist],$C11,AssessedValuation[Tif_NonTIF],$A$4) -> 1106340 | L11: =SUMIFS(AssessedValuation[100% Reserved],AssessedValuation[Dist],$C11,AssessedValuation[Tif_NonTIF],$A$4) -> 0 | M11: =SUMIFS(AssessedValuation[100% Reserved4],AssessedValuation[Dist],$C11,AssessedValuation[Tif_NonTIF],$A$4) -> 0 | N11: =SUMIFS(AssessedValuation[100% Railroads],AssessedValuation[Dist],$C11,AssessedValuation[Tif_NonTIF],$A$4) -> 0 | O11: =SUMIFS(AssessedValuation[100% Utilities],AssessedValuation[Dist],$C11,AssessedValuation[Tif_NonTIF],$A$4) -> 590283 | P11: =SUMIFS(AssessedValuation[100% Other],AssessedValuation[Dist],$C11,AssessedValuation[Tif_NonTIF],$A$4) -> 0 | Q11: =SUMIFS(AssessedValuation[100% Gross],AssessedValuation[Dist],$C11,AssessedValuation[Tif_NonTIF],$A$4) -> 450544673 | R11: =SUMIFS(AssessedValuation[100% Military Exempt],AssessedValuation[Dist],$C11,AssessedValuation[Tif_NonTIF],$A$4) -> 596000 | S11: =SUMIFS(AssessedValuation[100% Homestead Exempt],AssessedValuation[Dist],$C11,AssessedValuation[Tif_NonTIF],$A$4) -> 1482000 | T11: =SUMIFS(AssessedValuation[100% Net],AssessedValuation[Dist],$C11,AssessedValuation[Tif_NonTIF],$A$4) -> 448466673 | U11: =SUMIFS(AssessedValuation[100% Gas & Elec Utilities],AssessedValuation[Dist],$C11,AssessedValuation[Tif_NonTIF],$A$4) -> 6723670 | V11: =SUM(T11:U11) -> 455190343
A12: 2026 | B12: 05 | C12: 0072 | D12: 0072 | E12: ALBERT CITY-TRUESDALE | F12: Albert City-Truesdale | G12: =SUMIFS(AssessedValuation[100% Residential],AssessedValuation[Dist],$C12,AssessedValuation[Tif_NonTIF],$A$4) -> 83114574 | H12: =SUMIFS(AssessedValuation[100% Ag Land],AssessedValuation[Dist],$C12,AssessedValuation[Tif_NonTIF],$A$4) -> 123950008 | I12: =SUMIFS(AssessedValuation[100% Ag Building],AssessedValuation[Dist],$C12,AssessedValuation[Tif_NonTIF],$A$4) -> 14620979 | J12: =SUMIFS(AssessedValuation[100% Commercial],AssessedValuation[Dist],$C12,AssessedValuation[Tif_NonTIF],$A$4) -> 20975412 | K12: =SUMIFS(AssessedValuation[100% Industrial],AssessedValuation[Dist],$C12,AssessedValuation[Tif_NonTIF],$A$4) -> 21205460 | L12: =SUMIFS(AssessedValuation[100% Reserved],AssessedValuation[Dist],$C12,AssessedValuation[Tif_NonTIF],$A$4) -> 0 | M12: =SUMIFS(AssessedValuation[100% Reserved4],AssessedValuation[Dist],$C12,AssessedValuation[Tif_NonTIF],$A$4) -> 0 | N12: =SUMIFS(AssessedValuation[100% Railroads],AssessedValuation[Dist],$C12,AssessedValuation[Tif_NonTIF],$A$4) -> 4101488 | O12: =SUMIFS(AssessedValuation[100% Utilities],AssessedValuation[Dist],$C12,AssessedValuation[Tif_NonTIF],$A$4) -> 1464281 | P12: =SUMIFS(AssessedValuation[100% Other],AssessedValuation[Dist],$C12,AssessedValuation[Tif_NonTIF],$A$4) -> 0 | Q12: =SUMIFS(AssessedValuation[100% Gross],AssessedValuation[Dist],$C12,AssessedValuation[Tif_NonTIF],$A$4) -> 269432202 | R12: =SUMIFS(AssessedValuation[100% Military Exempt],AssessedValuation[Dist],$C12,AssessedValuation[Tif_NonTIF],$A$4) -> 256000 | S12: =SUMIFS(AssessedValuation[100% Homestead Exempt],AssessedValuation[Dist],$C12,AssessedValuation[Tif_NonTIF],$A$4) -> 786500 | T12: =SUMIFS(AssessedValuation[100% Net],AssessedValuation[Dist],$C12,AssessedValuation[Tif_NonTIF],$A$4) -> 268389702 | U12: =SUMIFS(AssessedValuation[100% Gas & Elec Utilities],AssessedValuation[Dist],$C12,AssessedValuation[Tif_NonTIF],$A$4) -> 13616539 | V12: =SUM(T12:U12) -> 282006241
A13: 2026 | B13: 15 | C13: 0081 | D13: 0081 | E13: ALBIA | F13: Albia | G13: =SUMIFS(AssessedValuation[100% Residential],AssessedValuation[Dist],$C13,AssessedValuation[Tif_NonTIF],$A$4) -> 401700372 | H13: =SUMIFS(AssessedValuation[100% Ag Land],AssessedValuation[Dist],$C13,AssessedValuation[Tif_NonTIF],$A$4) -> 130882750 | I13: =SUMIFS(AssessedValuation[100% Ag Building],AssessedValuation[Dist],$C13,AssessedValuation[Tif_NonTIF],$A$4) -> 4426100 | J13: =SUMIFS(AssessedValuation[100% Commercial],AssessedValuation[Dist],$C13,AssessedValuation[Tif_NonTIF],$A$4) -> 42438666 | K13: =SUMIFS(AssessedValuation[100% Industrial],AssessedValuation[Dist],$C13,AssessedValuation[Tif_NonTIF],$A$4) -> 12910608 | L13: =SUMIFS(AssessedValuation[100% Reserved],AssessedValuation[Dist],$C13,AssessedValuation[Tif_NonTIF],$A$4) -> 0 | M13: =SUMIFS(AssessedValuation[100% Reserved4],AssessedValuation[Dist],$C13,AssessedValuation[Tif_NonTIF],$A$4) -> 0 | N13: =SUMIFS(AssessedValuation[100% Railroads],AssessedValuation[Dist],$C13,AssessedValuation[Tif_NonTIF],$A$4) -> 43097322 | O13: =SUMIFS(AssessedValuation[100% Utilities],AssessedValuation[Dist],$C13,AssessedValuation[Tif_NonTIF],$A$4) -> 1770575 | P13: =SUMIFS(AssessedValuation[100% Other],AssessedValuation[Dist],$C13,AssessedValuation[Tif_NonTIF],$A$4) -> 39012 | Q13: =SUMIFS(AssessedValuation[100% Gross],AssessedValuation[Dist],$C13,AssessedValuation[Tif_NonTIF],$A$4) -> 637265405 | R13: =SUMIFS(AssessedValuation[100% Military Exempt],AssessedValuation[Dist],$C13,AssessedValuation[Tif_NonTIF],$A$4) -> 1006401 | S13: =SUMIFS(AssessedValuation[100% Homestead Exempt],AssessedValuation[Dist],$C13,AssessedValuation[Tif_NonTIF],$A$4) -> 4701123 | T13: =SUMIFS(AssessedValuation[100% Net],AssessedValuation[Dist],$C13,AssessedValuation[Tif_NonTIF],$A$4) -> 631557881 | U13: =SUMIFS(AssessedValuation[100% Gas & Elec Utilities],AssessedValuation[Dist],$C13,AssessedValuation[Tif_NonTIF],$A$4) -> 30778266 | V13: =SUM(T13:U13) -> 662336147
A14: 2026 | B14: 10 | C14: 0099 | D14: 0099 | E14: ALBURNETT | F14: Alburnett | G14: =SUMIFS(AssessedValuation[100% Residential],AssessedValuation[Dist],$C14,AssessedValuation[Tif_NonTIF],$A$4) -> 442955324 | H14: =SUMIFS(AssessedValuation[100% Ag Land],AssessedValuation[Dist],$C14,AssessedValuation[Tif_NonTIF],$A$4) -> 68723215 | I14: =SUMIFS(AssessedValuation[100% Ag Building],AssessedValuation[Dist],$C14,AssessedValuation[Tif_NonTIF],$A$4) -> 6992388 | J14: =SUMIFS(AssessedValuation[100% Commercial],AssessedValuation[Dist],$C14,AssessedValuation[Tif_NonTIF],$A$4) -> 17751619 | K14: =SUMIFS(AssessedValuation[100% Industrial],AssessedValuation[Dist],$C14,AssessedValuation[Tif_NonTIF],$A$4) -> 377700 | L14: =SUMIFS(AssessedValuation[100% Reserved],AssessedValuation[Dist],$C14,AssessedValuation[Tif_NonTIF],$A$4) -> 0 | M14: =SUMIFS(AssessedValuation[100% Reserved4],AssessedValuation[Dist],$C14,AssessedValuation[Tif_NonTIF],$A$4) -> 0 | N14: =SUMIFS(AssessedValuation[100% Railroads],AssessedValuation[Dist],$C14,AssessedValuation[Tif_NonTIF],$A$4) -> 1977734 | O14: =SUMIFS(AssessedValuation[100% Utilities],AssessedValuation[Dist],$C14,AssessedValuation[Tif_NonTIF],$A$4) -> 1474 | P14: =SUMIFS(AssessedValuation[100% Other],AssessedValuation[Dist],$C14,AssessedValuation[Tif_NonTIF],$A$4) -> 0 | Q14: =SUMIFS(AssessedValuation[100% Gross],AssessedValuation[Dist],$C14,AssessedValuation[Tif_NonTIF],$A$4) -> 538779454 | R14: =SUMIFS(AssessedValuation[100% Military Exempt],AssessedValuation[Dist],$C14,AssessedValuation[Tif_NonTIF],$A$4) -> 656000 | S14: =SUMIFS(AssessedValuation[100% Homestead Exempt],AssessedValuation[Dist],$C14,AssessedValuation[Tif_NonTIF],$A$4) -> 2834000 | T14: =SUMIFS(AssessedValuation[100% Net],AssessedValuation[Dist],$C14,AssessedValuation[Tif_NonTIF],$A$4) -> 535289454 | U14: =SUMIFS(AssessedValuation[100% Gas & Elec Utilities],AssessedValuation[Dist],$C14,AssessedValuation[Tif_NonTIF],$A$4) -> 30493535 | V14: =SUM(T14:U14) -> 565782989
A15: 2026 | B15: 07 | C15: 0108 | D15: 0108 | E15: ALDEN | F15: Alden | G15: =SUMIFS(AssessedValuation[100% Residential],AssessedValuation[Dist],$C15,AssessedValuation[Tif_NonTIF],$A$4) -> 69305340 | H15: =SUMIFS(AssessedValuation[100% Ag Land],AssessedValuation[Dist],$C15,AssessedValuation[Tif_NonTIF],$A$4) -> 106433170 | I15: =SUMIFS(AssessedValuation[100% Ag Building],AssessedValuation[Dist],$C15,AssessedValuation[Tif_NonTIF],$A$4) -> 16802740 | J15: =SUMIFS(AssessedValuation[100% Commercial],AssessedValuation[Dist],$C15,AssessedValuation[Tif_NonTIF],$A$4) -> 22015010 | K15: =SUMIFS(AssessedValuation[100% Industrial],AssessedValuation[Dist],$C15,AssessedValuation[Tif_NonTIF],$A$4) -> 17115740 | L15: =SUMIFS(AssessedValuation[100% Reserved],AssessedValuation[Dist],$C15,AssessedValuation[Tif_NonTIF],$A$4) -> 0 | M15: =SUMIFS(AssessedValuation[100% Reserved4],AssessedValuation[Dist],$C15,AssessedValuation[Tif_NonTIF],$A$4) -> 0 | N15: =SUMIFS(AssessedValuation[100% Railroads],AssessedValuation[Dist],$C15,AssessedValuation[Tif_NonTIF],$A$4) -> 12945486 | O15: =SUMIFS(AssessedValuation[100% Utilities],AssessedValuation[Dist],$C15,AssessedValuation[Tif_NonTIF],$A$4) -> 1348401 | P15: =SUMIFS(AssessedValuation[100% Other],AssessedValuation[Dist],$C15,AssessedValuation[Tif_NonTIF],$A$4) -> 0 | Q15: =SUMIFS(AssessedValuation[100% Gross],AssessedValuation[Dist],$C15,AssessedValuation[Tif_NonTIF],$A$4) -> 245965887 | R15: =SUMIFS(AssessedValuation[100% Military Exempt],AssessedValuation[Dist],$C15,AssessedValuation[Tif_NonTIF],$A$4) -> 276000 | S15: =SUMIFS(AssessedValuation[100% Homestead Exempt],AssessedValuation[Dist],$C15,AssessedValuation[Tif_NonTIF],$A$4) -> 682500 | T15: =SUMIFS(AssessedValuation[100% Net],AssessedValuation[Dist],$C15,AssessedValuation[Tif_NonTIF],$A$4) -> 245007387 | U15: =SUMIFS(AssessedValuation[100% Gas & Elec Utilities],AssessedValuation[Dist],$C15,AssessedValuation[Tif_NonTIF],$A$4) -> 13147802 | V15: =SUM(T15:U15) -> 258155189
A16: 2026 | B16: 05 | C16: 0126 | D16: 0126 | E16: ALGONA (ALGONA) | F16: Algona | G16: =SUMIFS(AssessedValuation[100% Residential],AssessedValuation[Dist],$C16,AssessedValuation[Tif_NonTIF],$A$4) -> 636261289 | H16: =SUMIFS(AssessedValuation[100% Ag Land],AssessedValuation[Dist],$C16,AssessedValuation[Tif_NonTIF],$A$4) -> 322694985 | I16: =SUMIFS(AssessedValuation[100% Ag Building],AssessedValuation[Dist],$C16,AssessedValuation[Tif_NonTIF],$A$4) -> 23071572 | J16: =SUMIFS(AssessedValuation[100% Commercial],AssessedValuation[Dist],$C16,AssessedValuation[Tif_NonTIF],$A$4) -> 135974392 | K16: =SUMIFS(AssessedValuation[100% Industrial],AssessedValuation[Dist],$C16,AssessedValuation[Tif_NonTIF],$A$4) -> 77882876 | L16: =SUMIFS(AssessedValuation[100% Reserved],AssessedValuation[Dist],$C16,AssessedValuation[Tif_NonTIF],$A$4) -> 0 | M16: =SUMIFS(AssessedValuation[100% Reserved4],AssessedValuation[Dist],$C16,AssessedValuation[Tif_NonTIF],$A$4) -> 0 | N16: =SUMIFS(AssessedValuation[100% Railroads],AssessedValuation[Dist],$C16,AssessedValuation[Tif_NonTIF],$A$4) -> 33638046 | O16: =SUMIFS(AssessedValuation[100% Utilities],AssessedValuation[Dist],$C16,AssessedValuation[Tif_NonTIF],$A$4) -> 1576197 | P16: =SUMIFS(AssessedValuation[100% Other],AssessedValuation[Dist],$C16,AssessedValuation[Tif_NonTIF],$A$4) -> 0 | Q16: =SUMIFS(AssessedValuation[100% Gross],AssessedValuation[Dist],$C16,AssessedValuation[Tif_NonTIF],$A$4) -> 1231099357 | R16: =SUMIFS(AssessedValuation[100% Military Exempt],AssessedValuation[Dist],$C16,AssessedValuation[Tif_NonTIF],$A$4) -> 1512000 | S16: =SUMIFS(AssessedValuation[100% Homestead Exempt],AssessedValuation[Dist],$C16,AssessedValuation[Tif_NonTIF],$A$4) -> 5577000 | T16: =SUMIFS(AssessedValuation[100% Net],AssessedValuation[Dist],$C16,AssessedValuation[Tif_NonTIF],$A$4) -> 1224010357 | U16: =SUMIFS(AssessedValuation[100% Gas & Elec Utilities],AssessedValuation[Dist],$C16,AssessedValuation[Tif_NonTIF],$A$4) -> 132867354 | V16: =SUM(T16:U16) -> 1356877711
A17: 2026 | B17: 05 | C17: 6417 | D17: 6417 | E17: ALGONA (TITONKA) | F17: Algona (Titonka) | G17: =SUMIFS(AssessedValuation[100% Residential],AssessedValuation[Dist],$C17,AssessedValuation[Tif_NonTIF],$A$4) -> 48708993 | H17: =SUMIFS(AssessedValuation[100% Ag Land],AssessedValuation[Dist],$C17,AssessedValuation[Tif_NonTIF],$A$4) -> 105720218 | I17: =SUMIFS(AssessedValuation[100% Ag Building],AssessedValuation[Dist],$C17,AssessedValuation[Tif_NonTIF],$A$4) -> 6176192 | J17: =SUMIFS(AssessedValuation[100% Commercial],AssessedValuation[Dist],$C17,AssessedValuation[Tif_NonTIF],$A$4) -> 7618232 | K17: =SUMIFS(AssessedValuation[100% Industrial],AssessedValuation[Dist],$C17,AssessedValuation[Tif_NonTIF],$A$4) -> 0 | L17: =SUMIFS(AssessedValuation[100% Reserved],AssessedValuation[Dist],$C17,AssessedValuation[Tif_NonTIF],$A$4) -> 0 | M17: =SUMIFS(AssessedValuation[100% Reserved4],AssessedValuation[Dist],$C17,AssessedValuation[Tif_NonTIF],$A$4) -> 0 | N17: =SUMIFS(AssessedValuation[100% Railroads],AssessedValuation[Dist],$C17,AssessedValuation[Tif_NonTIF],$A$4) -> 0 | O17: =SUMIFS(AssessedValuation[100% Utilities],AssessedValuation[Dist],$C17,AssessedValuation[Tif_NonTIF],$A$4) -> 0 | P17: =SUMIFS(AssessedValuation[100% Other],AssessedValuation[Dist],$C17,AssessedValuation[Tif_NonTIF],$A$4) -> 0 | Q17: =SUMIFS(AssessedValuation[100% Gross],AssessedValuation[Dist],$C17,AssessedValuation[Tif_NonTIF],$A$4) -> 168223635 | R17: =SUMIFS(AssessedValuation[100% Military Exempt],AssessedValuation[Dist],$C17,AssessedValuation[Tif_NonTIF],$A$4) -> 212000 | S17: =SUMIFS(AssessedValuation[100% Homestead Exempt],AssessedValuation[Dist],$C17,AssessedValuation[Tif_NonTIF],$A$4) -> 689000 | T17: =SUMIFS(AssessedValuation[100% Net],AssessedValuation[Dist],$C17,AssessedValuation[Tif_NonTIF],$A$4) -> 167322635 | U17: =SUMIFS(AssessedValuation[100% Gas & Elec Utilities],AssessedValuation[Dist],$C17,AssessedValuation[Tif_NonTIF],$A$4) -> 8520868 | V17: =SUM(T17:U17) -> 175843503
A18: 2026 | B18: 05 | C18: 3897 | D18: 3897 | E18: ALGONA (LU VERNE) | F18: Algona (Lu Verne) | G18: =SUMIFS(AssessedValuation[100% Residential],AssessedValuation[Dist],$C18,AssessedValuation[Tif_NonTIF],$A$4) -> 69642838 | H18: =SUMIFS(AssessedValuation[100% Ag Land],AssessedValuation[Dist],$C18,AssessedValuation[Tif_NonTIF],$A$4) -> 196227482 | I18: =SUMIFS(AssessedValuation[100% Ag Building],AssessedValuation[Dist],$C18,AssessedValuation[Tif_NonTIF],$A$4) -> 33559665 | J18: =SUMIFS(AssessedValuation[100% Commercial],AssessedValuation[Dist],$C18,AssessedValuation[Tif_NonTIF],$A$4) -> 35759559 | K18: =SUMIFS(AssessedValuation[100% Industrial],AssessedValuation[Dist],$C18,AssessedValuation[Tif_NonTIF],$A$4) -> 22133438 | L18: =SUMIFS(AssessedValuation[100% Reserved],AssessedValuation[Dist],$C18,AssessedValuation[Tif_NonTIF],$A$4) -> 0 | M18: =SUMIFS(AssessedValuation[100% Reserved4],AssessedValuation[Dist],$C18,AssessedValuation[Tif_NonTIF],$A$4) -> 0 | N18: =SUMIFS(AssessedValuation[100% Railroads],AssessedValuation[Dist],$C18,AssessedValuation[Tif_NonTIF],$A$4) -> 17078351 | O18: =SUMIFS(AssessedValuation[100% Utilities],AssessedValuation[Dist],$C18,AssessedValuation[Tif_NonTIF],$A$4) -> 653944 | P18: =SUMIFS(AssessedValuation[100% Other],AssessedValuation[Dist],$C18,AssessedValuation[Tif_NonTIF],$A$4) -> 0 | Q18: =SUMIFS(AssessedValuation[100% Gross],AssessedValuation[Dist],$C18,AssessedValuation[Tif_NonTIF],$A$4) -> 375055277 | R18: =SUMIFS(AssessedValuation[100% Military Exempt],AssessedValuation[Dist],$C18,AssessedValuation[Tif_NonTIF],$A$4) -> 304664 | S18: =SUMIFS(AssessedValuation[100% Homestead Exempt],AssessedValuation[Dist],$C18,AssessedValuation[Tif_NonTIF],$A$4) -> 816199 | T18: =SUMIFS(AssessedValuation[100% Net],AssessedValuation[Dist],$C18,AssessedValuation[Tif_NonTIF],$A$4) -> 373934414 | U18: =SUMIFS(AssessedValuation[100% Gas & Elec Utilities],AssessedValuation[Dist],$C18,AssessedValuation[Tif_NonTIF],$A$4) -> 61525723 | V18: =SUM(T18:U18) -> 435460137
... A73: 2026 | B73: 01 | C73: 2763 | D73: 2763 | E73: CLAYTON RIDGE | F73: Clayton Ridge | G73: =SUMIFS(AssessedValuation[100% Residential],AssessedValuation[Dist],$C73,AssessedValuation[Tif_NonTIF],$A$4) -> 510958182 | H73: =SUMIFS(AssessedValuation[100% Ag Land],AssessedValuation[Dist],$C73,AssessedValuation[Tif_NonTIF],$A$4) -> 136961838 | I73: =SUMIFS(AssessedValuation[100% Ag Building],AssessedValuation[Dist],$C73,AssessedValuation[Tif_NonTIF],$A$4) -> 12094949 | J73: =SUMIFS(AssessedValuation[100% Commercial],AssessedValuation[Dist],$C73,AssessedValuation[Tif_NonTIF],$A$4) -> 43698085 | K73: =SUMIFS(AssessedValuation[100% Industrial],AssessedValuation[Dist],$C73,AssessedValuation[Tif_NonTIF],$A$4) -> 14443596 | L73: =SUMIFS(AssessedValuation[100% Reserved],AssessedValuation[Dist],$C73,AssessedValuation[Tif_NonTIF],$A$4) -> 0 | M73: =SUMIFS(AssessedValuation[100% Reserved4],AssessedValuation[Dist],$C73,AssessedValuation[Tif_NonTIF],$A$4) -> 0 | N73: =SUMIFS(AssessedValuation[100% Railroads],AssessedValuation[Dist],$C73,AssessedValuation[Tif_NonTIF],$A$4) -> 8077884 | O73: =SUMIFS(AssessedValuation[100% Utilities],AssessedValuation[Dist],$C73,AssessedValuation[Tif_NonTIF],$A$4) -> 3839493 | P73: =SUMIFS(AssessedValuation[100% Other],AssessedValuation[Dist],$C73,AssessedValuation[Tif_NonTIF],$A$4) -> 0 | Q73: =SUMIFS(AssessedValuation[100% Gross],AssessedValuation[Dist],$C73,AssessedValuation[Tif_NonTIF],$A$4) -> 730074027 | R73: =SUMIFS(AssessedValuation[100% Military Exempt],AssessedValuation[Dist],$C73,AssessedValuation[Tif_NonTIF],$A$4) -> 1132000 | S73: =SUMIFS(AssessedValuation[100% Homestead Exempt],AssessedValuation[Dist],$C73,AssessedValuation[Tif_NonTIF],$A$4) -> 4815041 | T73: =SUMIFS(AssessedValuation[100% Net],AssessedValuation[Dist],$C73,AssessedValuation[Tif_NonTIF],$A$4) -> 724126986 | U73: =SUMIFS(AssessedValuation[100% Gas & Elec Utilities],AssessedValuation[Dist],$C73,AssessedValuation[Tif_NonTIF],$A$4) -> 44614667 | V73: =SUM(T73:U73) -> 768741653
A74: 2026 | C74: 0216 | D74: 0216 | E74: CLEAR CREEK-AMANA (AMANA) | F74: Clear Creek-Amana (Amana) | G74: =SUMIFS(AssessedValuation[100% Residential],AssessedValuation[Dist],$C74,AssessedValuation[Tif_NonTIF],$A$4) -> 191877609 | H74: =SUMIFS(AssessedValuation[100% Ag Land],AssessedValuation[Dist],$C74,AssessedValuation[Tif_NonTIF],$A$4) -> 24813860 | I74: =SUMIFS(AssessedValuation[100% Ag Building],AssessedValuation[Dist],$C74,AssessedValuation[Tif_NonTIF],$A$4) -> 1285170 | J74: =SUMIFS(AssessedValuation[100% Commercial],AssessedValuation[Dist],$C74,AssessedValuation[Tif_NonTIF],$A$4) -> 23702371 | K74: =SUMIFS(AssessedValuation[100% Industrial],AssessedValuation[Dist],$C74,AssessedValuation[Tif_NonTIF],$A$4) -> 13605920 | L74: =SUMIFS(AssessedValuation[100% Reserved],AssessedValuation[Dist],$C74,AssessedValuation[Tif_NonTIF],$A$4) -> 0 | M74: =SUMIFS(AssessedValuation[100% Reserved4],AssessedValuation[Dist],$C74,AssessedValuation[Tif_NonTIF],$A$4) -> 0 | N74: =SUMIFS(AssessedValuation[100% Railroads],AssessedValuation[Dist],$C74,AssessedValuation[Tif_NonTIF],$A$4) -> 10381867 | O74: =SUMIFS(AssessedValuation[100% Utilities],AssessedValuation[Dist],$C74,AssessedValuation[Tif_NonTIF],$A$4) -> 1744600 | P74: =SUMIFS(AssessedValuation[100% Other],AssessedValuation[Dist],$C74,AssessedValuation[Tif_NonTIF],$A$4) -> 0 | Q74: =SUMIFS(AssessedValuation[100% Gross],AssessedValuation[Dist],$C74,AssessedValuation[Tif_NonTIF],$A$4) -> 267411397 | R74: =SUMIFS(AssessedValuation[100% Military Exempt],AssessedValuation[Dist],$C74,AssessedValuation[Tif_NonTIF],$A$4) -> 344000 | S74: =SUMIFS(AssessedValuation[100% Homestead Exempt],AssessedValuation[Dist],$C74,AssessedValuation[Tif_NonTIF],$A$4) -> 1228500 | T74: =SUMIFS(AssessedValuation[100% Net],AssessedValuation[Dist],$C74,AssessedValuation[Tif_NonTIF],$A$4) -> 265838897 | U74: =SUMIFS(AssessedValuation[100% Gas & Elec Utilities],AssessedValuation[Dist],$C74,AssessedValuation[Tif_NonTIF],$A$4) -> 11862095 | V74: =SUM(T74:U74) -> 277700992
A75: 2026 | B75: 10 | C75: 1221 | D75: 1221 | E75: CLEAR CREEK-AMANA (CLEAR CREEK) | F75: Clear Creek-Amana | G75: =SUMIFS(AssessedValuation[100% Residential],AssessedValuation[Dist],$C75,AssessedValuation[Tif_NonTIF],$A$4) -> 1849449818 | H75: =SUMIFS(AssessedValuation[100% Ag Land],AssessedValuation[Dist],$C75,AssessedValuation[Tif_NonTIF],$A$4) -> 85963238 | I75: =SUMIFS(AssessedValuation[100% Ag Building],AssessedValuation[Dist],$C75,AssessedValuation[Tif_NonTIF],$A$4) -> 6666409 | J75: =SUMIFS(AssessedValuation[100% Commercial],AssessedValuation[Dist],$C75,AssessedValuation[Tif_NonTIF],$A$4) -> 499003979 | K75: =SUMIFS(AssessedValuation[100% Industrial],AssessedValuation[Dist],$C75,AssessedValuation[Tif_NonTIF],$A$4) -> 35278158 | L75: =SUMIFS(AssessedValuation[100% Reserved],AssessedValuation[Dist],$C75,AssessedValuation[Tif_NonTIF],$A$4) -> 0 | M75: =SUMIFS(AssessedValuation[100% Reserved4],AssessedValuation[Dist],$C75,AssessedValuation[Tif_NonTIF],$A$4) -> 0 | N75: =SUMIFS(AssessedValuation[100% Railroads],AssessedValuation[Dist],$C75,AssessedValuation[Tif_NonTIF],$A$4) -> 13818160 | O75: =SUMIFS(AssessedValuation[100% Utilities],AssessedValuation[Dist],$C75,AssessedValuation[Tif_NonTIF],$A$4) -> 4841475 | P75: =SUMIFS(AssessedValuation[100% Other],AssessedValuation[Dist],$C75,AssessedValuation[Tif_NonTIF],$A$4) -> 0 | Q75: =SUMIFS(AssessedValuation[100% Gross],AssessedValuation[Dist],$C75,AssessedValuation[Tif_NonTIF],$A$4) -> 2495021237 | R75: =SUMIFS(AssessedValuation[100% Military Exempt],AssessedValuation[Dist],$C75,AssessedValuation[Tif_NonTIF],$A$4) -> 1320000 | S75: =SUMIFS(AssessedValuation[100% Homestead Exempt],AssessedValuation[Dist],$C75,AssessedValuation[Tif_NonTIF],$A$4) -> 4524000 | T75: =SUMIFS(AssessedValuation[100% Net],AssessedValuation[Dist],$C75,AssessedValuation[Tif_NonTIF],$A$4) -> 2489177237 | U75: =SUMIFS(AssessedValuation[100% Gas & Elec Utilities],AssessedValuation[Dist],$C75,AssessedValuation[Tif_NonTIF],$A$4) -> 93478590 | V75: =SUM(T75:U75) -> 2582655827
A76: 2026 | B76: 07 | C76: 1233 | D76: 1233 | E76: CLEAR LAKE | F76: Clear Lake | G76: =SUMIFS(AssessedValuation[100% Residential],AssessedValuation[Dist],$C76,AssessedValuation[Tif_NonTIF],$A$4) -> 1719295679 | H76: =SUMIFS(AssessedValuation[100% Ag Land],AssessedValuation[Dist],$C76,AssessedValuation[Tif_NonTIF],$A$4) -> 85014690 | I76: =SUMIFS(AssessedValuation[100% Ag Building],AssessedValuation[Dist],$C76,AssessedValuation[Tif_NonTIF],$A$4) -> 4990090 | J76: =SUMIFS(AssessedValuation[100% Commercial],AssessedValuation[Dist],$C76,AssessedValuation[Tif_NonTIF],$A$4) -> 208200312 | K76: =SUMIFS(AssessedValuation[100% Industrial],AssessedValuation[Dist],$C76,AssessedValuation[Tif_NonTIF],$A$4) -> 13470547 | L76: =SUMIFS(AssessedValuation[100% Reserved],AssessedValuation[Dist],$C76,AssessedValuation[Tif_NonTIF],$A$4) -> 0 | M76: =SUMIFS(AssessedValuation[100% Reserved4],AssessedValuation[Dist],$C76,AssessedValuation[Tif_NonTIF],$A$4) -> 0 | N76: =SUMIFS(AssessedValuation[100% Railroads],AssessedValuation[Dist],$C76,AssessedValuation[Tif_NonTIF],$A$4) -> 2946886 | O76: =SUMIFS(AssessedValuation[100% Utilities],AssessedValuation[Dist],$C76,AssessedValuation[Tif_NonTIF],$A$4) -> 22560716 | P76: =SUMIFS(AssessedValuation[100% Other],AssessedValuation[Dist],$C76,AssessedValuation[Tif_NonTIF],$A$4) -> 0 | Q76: =SUMIFS(AssessedValuation[100% Gross],AssessedValuation[Dist],$C76,AssessedValuation[Tif_NonTIF],$A$4) -> 2056478920 | R76: =SUMIFS(AssessedValuation[100% Military Exempt],AssessedValuation[Dist],$C76,AssessedValuation[Tif_NonTIF],$A$4) -> 1412000 | S76: =SUMIFS(AssessedValuation[100% Homestead Exempt],AssessedValuation[Dist],$C76,AssessedValuation[Tif_NonTIF],$A$4) -> 5044000 | T76: =SUMIFS(AssessedValuation[100% Net],AssessedValuation[Dist],$C76,AssessedValuation[Tif_NonTIF],$A$4) -> 2050022920 | U76: =SUMIFS(AssessedValuation[100% Gas & Elec Utilities],AssessedValuation[Dist],$C76,AssessedValuation[Tif_NonTIF],$A$4) -> 983780134 | V76: =SUM(T76:U76) -> 3033803054
A77: 2026 | B77: 09 | C77: 1278 | D77: 1278 | E77: CLINTON | F77: Clinton | G77: =SUMIFS(AssessedValuation[100% Residential],AssessedValuation[Dist],$C77,AssessedValuation[Tif_NonTIF],$A$4) -> 1166311608 | H77: =SUMIFS(AssessedValuation[100% Ag Land],AssessedValuation[Dist],$C77,AssessedValuation[Tif_NonTIF],$A$4) -> 8956130 | I77: =SUMIFS(AssessedValuation[100% Ag Building],AssessedValuation[Dist],$C77,AssessedValuation[Tif_NonTIF],$A$4) -> 1089980 | J77: =SUMIFS(AssessedValuation[100% Commercial],AssessedValuation[Dist],$C77,AssessedValuation[Tif_NonTIF],$A$4) -> 285851486 | K77: =SUMIFS(AssessedValuation[100% Industrial],AssessedValuation[Dist],$C77,AssessedValuation[Tif_NonTIF],$A$4) -> 163077726 | L77: =SUMIFS(AssessedValuation[100% Reserved],AssessedValuation[Dist],$C77,AssessedValuation[Tif_NonTIF],$A$4) -> 0 | M77: =SUMIFS(AssessedValuation[100% Reserved4],AssessedValuation[Dist],$C77,AssessedValuation[Tif_NonTIF],$A$4) -> 0 | N77: =SUMIFS(AssessedValuation[100% Railroads],AssessedValuation[Dist],$C77,AssessedValuation[Tif_NonTIF],$A$4) -> 9082338 | O77: =SUMIFS(AssessedValuation[100% Utilities],AssessedValuation[Dist],$C77,AssessedValuation[Tif_NonTIF],$A$4) -> 0 | P77: =SUMIFS(AssessedValuation[100% Other],AssessedValuation[Dist],$C77,AssessedValuation[Tif_NonTIF],$A$4) -> 446750 | Q77: =SUMIFS(AssessedValuation[100% Gross],AssessedValuation[Dist],$C77,AssessedValuation[Tif_NonTIF],$A$4) -> 1634816018 | R77: =SUMIFS(AssessedValuation[100% Military Exempt],AssessedValuation[Dist],$C77,AssessedValuation[Tif_NonTIF],$A$4) -> 4108000 | S77: =SUMIFS(AssessedValuation[100% Homestead Exempt],AssessedValuation[Dist],$C77,AssessedValuation[Tif_NonTIF],$A$4) -> 11940500 | T77: =SUMIFS(AssessedValuation[100% Net],AssessedValuation[Dist],$C77,AssessedValuation[Tif_NonTIF],$A$4) -> 1618767518 | U77: =SUMIFS(AssessedValuation[100% Gas & Elec Utilities],AssessedValuation[Dist],$C77,AssessedValuation[Tif_NonTIF],$A$4) -> 290004455 | V77: =SUM(T77:U77) -> 1908771973
A78: 2026 | B78: 11 | C78: 1332 | D78: 1332 | E78: COLFAX-MINGO | F78: Colfax-Mingo | G78: =SUMIFS(AssessedValuation[100% Residential],AssessedValuation[Dist],$C78,AssessedValuation[Tif_NonTIF],$A$4) -> 333305761 | H78: =SUMIFS(AssessedValuation[100% Ag Land],AssessedValuation[Dist],$C78,AssessedValuation[Tif_NonTIF],$A$4) -> 111881500 | I78: =SUMIFS(AssessedValuation[100% Ag Building],AssessedValuation[Dist],$C78,AssessedValuation[Tif_NonTIF],$A$4) -> 4102420 | J78: =SUMIFS(AssessedValuation[100% Commercial],AssessedValuation[Dist],$C78,AssessedValuation[Tif_NonTIF],$A$4) -> 34110359 | K78: =SUMIFS(AssessedValuation[100% Industrial],AssessedValuation[Dist],$C78,AssessedValuation[Tif_NonTIF],$A$4) -> 1186620 | L78: =SUMIFS(AssessedValuation[100% Reserved],AssessedValuation[Dist],$C78,AssessedValuation[Tif_NonTIF],$A$4) -> 0 | M78: =SUMIFS(AssessedValuation[100% Reserved4],AssessedValuation[Dist],$C78,AssessedValuation[Tif_NonTIF],$A$4) -> 0 | N78: =SUMIFS(AssessedValuation[100% Railroads],AssessedValuation[Dist],$C78,AssessedValuation[Tif_NonTIF],$A$4) -> 2838425 | O78: =SUMIFS(AssessedValuation[100% Utilities],AssessedValuation[Dist],$C78,AssessedValuation[Tif_NonTIF],$A$4) -> 35140403 | P78: =SUMIFS(AssessedValuation[100% Other],AssessedValuation[Dist],$C78,AssessedValuation[Tif_NonTIF],$A$4) -> 0 | Q78: =SUMIFS(AssessedValuation[100% Gross],AssessedValuation[Dist],$C78,AssessedValuation[Tif_NonTIF],$A$4) -> 522565488 | R78: =SUMIFS(AssessedValuation[100% Military Exempt],AssessedValuation[Dist],$C78,AssessedValuation[Tif_NonTIF],$A$4) -> 592000 | S78: =SUMIFS(AssessedValuation[100% Homestead Exempt],AssessedValuation[Dist],$C78,AssessedValuation[Tif_NonTIF],$A$4) -> 1683500 | T78: =SUMIFS(AssessedValuation[100% Net],AssessedValuation[Dist],$C78,AssessedValuation[Tif_NonTIF],$A$4) -> 520289988 | U78: =SUMIFS(AssessedValuation[100% Gas & Elec Utilities],AssessedValuation[Dist],$C78,AssessedValuation[Tif_NonTIF],$A$4) -> 22386425 | V78: =SUM(T78:U78) -> 542676413
A79: 2026 | B79: 10 | C79: 1337 | D79: 1337 | E79: COLLEGE COMMUNITY | F79: College Community | G79: =SUMIFS(AssessedValuation[100% Residential],AssessedValuation[Dist],$C79,AssessedValuation[Tif_NonTIF],$A$4) -> 2792329713 | H79: =SUMIFS(AssessedValuation[100% Ag Land],AssessedValuation[Dist],$C79,AssessedValuation[Tif_NonTIF],$A$4) -> 101634169 | I79: =SUMIFS(AssessedValuation[100% Ag Building],AssessedValuation[Dist],$C79,AssessedValuation[Tif_NonTIF],$A$4) -> 10753203 | J79: =SUMIFS(AssessedValuation[100% Commercial],AssessedValuation[Dist],$C79,AssessedValuation[Tif_NonTIF],$A$4) -> 1033199220 | K79: =SUMIFS(AssessedValuation[100% Industrial],AssessedValuation[Dist],$C79,AssessedValuation[Tif_NonTIF],$A$4) -> 376615565 | L79: =SUMIFS(AssessedValuation[100% Reserved],AssessedValuation[Dist],$C79,AssessedValuation[Tif_NonTIF],$A$4) -> 0 | M79: =SUMIFS(AssessedValuation[100% Reserved4],AssessedValuation[Dist],$C79,AssessedValuation[Tif_NonTIF],$A$4) -> 0 | N79: =SUMIFS(AssessedValuation[100% Railroads],AssessedValuation[Dist],$C79,AssessedValuation[Tif_NonTIF],$A$4) -> 47369828 | O79: =SUMIFS(AssessedValuation[100% Utilities],AssessedValuation[Dist],$C79,AssessedValuation[Tif_NonTIF],$A$4) -> 13548773 | P79: =SUMIFS(AssessedValuation[100% Other],AssessedValuation[Dist],$C79,AssessedValuation[Tif_NonTIF],$A$4) -> 0 | Q79: =SUMIFS(AssessedValuation[100% Gross],AssessedValuation[Dist],$C79,AssessedValuation[Tif_NonTIF],$A$4) -> 4375450471 | R79: =SUMIFS(AssessedValuation[100% Military Exempt],AssessedValuation[Dist],$C79,AssessedValuation[Tif_NonTIF],$A$4) -> 3636000 | S79: =SUMIFS(AssessedValuation[100% Homestead Exempt],AssessedValuation[Dist],$C79,AssessedValuation[Tif_NonTIF],$A$4) -> 13026000 | T79: =SUMIFS(AssessedValuation[100% Net],AssessedValuation[Dist],$C79,AssessedValuation[Tif_NonTIF],$A$4) -> 4358788471 | U79: =SUMIFS(AssessedValuation[100% Gas & Elec Utilities],AssessedValuation[Dist],$C79,AssessedValuation[Tif_NonTIF],$A$4) -> 684262158 | V79: =SUM(T79:U79) -> 5043050629
A80: 2026 | B80: 11 | C80: 1350 | D80: 1350 | E80: COLLINS-MAXWELL | F80: Collins-Maxwell | G80: =SUMIFS(AssessedValuation[100% Residential],AssessedValuation[Dist],$C80,AssessedValuation[Tif_NonTIF],$A$4) -> 236661679 | H80: =SUMIFS(AssessedValuation[100% Ag Land],AssessedValuation[Dist],$C80,AssessedValuation[Tif_NonTIF],$A$4) -> 115467230 | I80: =SUMIFS(AssessedValuation[100% Ag Building],AssessedValuation[Dist],$C80,AssessedValuation[Tif_NonTIF],$A$4) -> 5218270 | J80: =SUMIFS(AssessedValuation[100% Commercial],AssessedValuation[Dist],$C80,AssessedValuation[Tif_NonTIF],$A$4) -> 8101821 | K80: =SUMIFS(AssessedValuation[100% Industrial],AssessedValuation[Dist],$C80,AssessedValuation[Tif_NonTIF],$A$4) -> 0 | L80: =SUMIFS(AssessedValuation[100% Reserved],AssessedValuation[Dist],$C80,AssessedValuation[Tif_NonTIF],$A$4) -> 0 | M80: =SUMIFS(AssessedValuation[100% Reserved4],AssessedValuation[Dist],$C80,AssessedValuation[Tif_NonTIF],$A$4) -> 0 | N80: =SUMIFS(AssessedValuation[100% Railroads],AssessedValuation[Dist],$C80,AssessedValuation[Tif_NonTIF],$A$4) -> 0 | O80: =SUMIFS(AssessedValuation[100% Utilities],AssessedValuation[Dist],$C80,AssessedValuation[Tif_NonTIF],$A$4) -> 12535488 | P80: =SUMIFS(AssessedValuation[100% Other],AssessedValuation[Dist],$C80,AssessedValuation[Tif_NonTIF],$A$4) -> 0 | Q80: =SUMIFS(AssessedValuation[100% Gross],AssessedValuation[Dist],$C80,AssessedValuation[Tif_NonTIF],$A$4) -> 377984488 | R80: =SUMIFS(AssessedValuation[100% Military Exempt],AssessedValuation[Dist],$C80,AssessedValuation[Tif_NonTIF],$A$4) -> 428106 | S80: =SUMIFS(AssessedValuation[100% Homestead Exempt],AssessedValuation[Dist],$C80,AssessedValuation[Tif_NonTIF],$A$4) -> 1496408 | T80: =SUMIFS(AssessedValuation[100% Net],AssessedValuation[Dist],$C80,AssessedValuation[Tif_NonTIF],$A$4) -> 376059974 | U80: =SUMIFS(AssessedValuation[100% Gas & Elec Utilities],AssessedValuation[Dist],$C80,AssessedValuation[Tif_NonTIF],$A$4) -> 21433360 | V80: =SUM(T80:U80) -> 397493334
A81: 2026 | B81: 11 | C81: 1359 | D81: 1359 | E81: COLO-NESCO | F81: Colo-Nesco | G81: =SUMIFS(AssessedValuation[100% Residential],AssessedValuation[Dist],$C81,AssessedValuation[Tif_NonTIF],$A$4) -> 241568141 | H81: =SUMIFS(AssessedValuation[100% Ag Land],AssessedValuation[Dist],$C81,AssessedValuation[Tif_NonTIF],$A$4) -> 199360520 | I81: =SUMIFS(AssessedValuation[100% Ag Building],AssessedValuation[Dist],$C81,AssessedValuation[Tif_NonTIF],$A$4) -> 8494620 | J81: =SUMIFS(AssessedValuation[100% Commercial],AssessedValuation[Dist],$C81,AssessedValuation[Tif_NonTIF],$A$4) -> 18972622 | K81: =SUMIFS(AssessedValuation[100% Industrial],AssessedValuation[Dist],$C81,AssessedValuation[Tif_NonTIF],$A$4) -> 69865645 | L81: =SUMIFS(AssessedValuation[100% Reserved],AssessedValuation[Dist],$C81,AssessedValuation[Tif_NonTIF],$A$4) -> 0 | M81: =SUMIFS(AssessedValuation[100% Reserved4],AssessedValuation[Dist],$C81,AssessedValuation[Tif_NonTIF],$A$4) -> 0 | N81: =SUMIFS(AssessedValuation[100% Railroads],AssessedValuation[Dist],$C81,AssessedValuation[Tif_NonTIF],$A$4) -> 18409005 | O81: =SUMIFS(AssessedValuation[100% Utilities],AssessedValuation[Dist],$C81,AssessedValuation[Tif_NonTIF],$A$4) -> 683277 | P81: =SUMIFS(AssessedValuation[100% Other],AssessedValuation[Dist],$C81,AssessedValuation[Tif_NonTIF],$A$4) -> 0 | Q81: =SUMIFS(AssessedValuation[100% Gross],AssessedValuation[Dist],$C81,AssessedValuation[Tif_NonTIF],$A$4) -> 557353830 | R81: =SUMIFS(AssessedValuation[100% Military Exempt],AssessedValuation[Dist],$C81,AssessedValuation[Tif_NonTIF],$A$4) -> 415704 | S81: =SUMIFS(AssessedValuation[100% Homestead Exempt],AssessedValuation[Dist],$C81,AssessedValuation[Tif_NonTIF],$A$4) -> 1842316 | T81: =SUMIFS(AssessedValuation[100% Net],AssessedValuation[Dist],$C81,AssessedValuation[Tif_NonTIF],$A$4) -> 555095810 | U81: =SUMIFS(AssessedValuation[100% Gas & Elec Utilities],AssessedValuation[Dist],$C81,AssessedValuation[Tif_NonTIF],$A$4) -> 40112786 | V81: =SUM(T81:U81) -> 595208596
A82: 2026 | B82: 09 | C82: 1368 | D82: 1368 | E82: COLUMBUS | F82: Columbus | G82: =SUMIFS(AssessedValuation[100% Residential],AssessedValuation[Dist],$C82,AssessedValuation[Tif_NonTIF],$A$4) -> 207320807 | H82: =SUMIFS(AssessedValuation[100% Ag Land],AssessedValuation[Dist],$C82,AssessedValuation[Tif_NonTIF],$A$4) -> 113129730 | I82: =SUMIFS(AssessedValuation[100% Ag Building],AssessedValuation[Dist],$C82,AssessedValuation[Tif_NonTIF],$A$4) -> 10798910 | J82: =SUMIFS(AssessedValuation[100% Commercial],AssessedValuation[Dist],$C82,AssessedValuation[Tif_NonTIF],$A$4) -> 19737929 | K82: =SUMIFS(AssessedValuation[100% Industrial],AssessedValuation[Dist],$C82,AssessedValuation[Tif_NonTIF],$A$4) -> 10463830 | L82: =SUMIFS(AssessedValuation[100% Reserved],AssessedValuation[Dist],$C82,AssessedValuation[Tif_NonTIF],$A$4) -> 0 | M82: =SUMIFS(AssessedValuation[100% Reserved4],AssessedValuation[Dist],$C82,AssessedValuation[Tif_NonTIF],$A$4) -> 0 | N82: =SUMIFS(AssessedValuation[100% Railroads],AssessedValuation[Dist],$C82,AssessedValuation[Tif_NonTIF],$A$4) -> 3161878 | O82: =SUMIFS(AssessedValuation[100% Utilities],AssessedValuation[Dist],$C82,AssessedValuation[Tif_NonTIF],$A$4) -> 90817264 | P82: =SUMIFS(AssessedValuation[100% Other],AssessedValuation[Dist],$C82,AssessedValuation[Tif_NonTIF],$A$4) -> 0 | Q82: =SUMIFS(AssessedValuation[100% Gross],AssessedValuation[Dist],$C82,AssessedValuation[Tif_NonTIF],$A$4) -> 455430348 | R82: =SUMIFS(AssessedValuation[100% Military Exempt],AssessedValuation[Dist],$C82,AssessedValuation[Tif_NonTIF],$A$4) -> 572000 | S82: =SUMIFS(AssessedValuation[100% Homestead Exempt],AssessedValuation[Dist],$C82,AssessedValuation[Tif_NonTIF],$A$4) -> 1599000 | T82: =SUMIFS(AssessedValuation[100% Net],AssessedValuation[Dist],$C82,AssessedValuation[Tif_NonTIF],$A$4) -> 453259348 | U82: =SUMIFS(AssessedValuation[100% Gas & Elec Utilities],AssessedValuation[Dist],$C82,AssessedValuation[Tif_NonTIF],$A$4) -> 37603978 | V82: =SUM(T82:U82) -> 490863326
A83: 2026 | B83: 11 | C83: 1413 | D83: 1413 | E83: COON RAPIDS-BAYARD | F83: Coon Rapids-Bayard | G83: =SUMIFS(AssessedValuation[100% Residential],AssessedValuation[Dist],$C83,AssessedValuation[Tif_NonTIF],$A$4) -> 137244832 | H83: =SUMIFS(AssessedValuation[100% Ag Land],AssessedValuation[Dist],$C83,AssessedValuation[Tif_NonTIF],$A$4) -> 183865440 | I83: =SUMIFS(AssessedValuation[100% Ag Building],AssessedValuation[Dist],$C83,AssessedValuation[Tif_NonTIF],$A$4) -> 12758560 | J83: =SUMIFS(AssessedValuation[100% Commercial],AssessedValuation[Dist],$C83,AssessedValuation[Tif_NonTIF],$A$4) -> 21833461 | K83: =SUMIFS(AssessedValuation[100% Industrial],AssessedValuation[Dist],$C83,AssessedValuation[Tif_NonTIF],$A$4) -> 20574707 | L83: =SUMIFS(AssessedValuation[100% Reserved],AssessedValuation[Dist],$C83,AssessedValuation[Tif_NonTIF],$A$4) -> 0 | M83: =SUMIFS(AssessedValuation[100% Reserved4],AssessedValuation[Dist],$C83,AssessedValuation[Tif_NonTIF],$A$4) -> 0 | N83: =SUMIFS(AssessedValuation[100% Railroads],AssessedValuation[Dist],$C83,AssessedValuation[Tif_NonTIF],$A$4) -> 11869224 | O83: =SUMIFS(AssessedValuation[100% Utilities],AssessedValuation[Dist],$C83,AssessedValuation[Tif_NonTIF],$A$4) -> 2224905 | P83: =SUMIFS(AssessedValuation[100% Other],AssessedValuation[Dist],$C83,AssessedValuation[Tif_NonTIF],$A$4) -> 0 | Q83: =SUMIFS(AssessedValuation[100% Gross],AssessedValuation[Dist],$C83,AssessedValuation[Tif_NonTIF],$A$4) -> 390371129 | R83: =SUMIFS(AssessedValuation[100% Military Exempt],AssessedValuation[Dist],$C83,AssessedValuation[Tif_NonTIF],$A$4) -> 478642 | S83: =SUMIFS(AssessedValuation[100% Homestead Exempt],AssessedValuation[Dist],$C83,AssessedValuation[Tif_NonTIF],$A$4) -> 1446250 | T83: =SUMIFS(AssessedValuation[100% Net],AssessedValuation[Dist],$C83,AssessedValuation[Tif_NonTIF],$A$4) -> 388446237 | U83: =SUMIFS(AssessedValuation[100% Gas & Elec Utilities],AssessedValuation[Dist],$C83,AssessedValuation[Tif_NonTIF],$A$4) -> 27223834 | V83: =SUM(T83:U83) -> 415670071
A84: 2026 | B84: 13 | C84: 1431 | D84: 1431 | E84: CORNING | F84: Corning | G84: =SUMIFS(AssessedValuation[100% Residential],AssessedValuation[Dist],$C84,AssessedValuation[Tif_NonTIF],$A$4) -> 175577454 | H84: =SUMIFS(AssessedValuation[100% Ag Land],AssessedValuation[Dist],$C84,AssessedValuation[Tif_NonTIF],$A$4) -> 178703500 | I84: =SUMIFS(AssessedValuation[100% Ag Building],AssessedValuation[Dist],$C84,AssessedValuation[Tif_NonTIF],$A$4) -> 20806770 | J84: =SUMIFS(AssessedValuation[100% Commercial],AssessedValuation[Dist],$C84,AssessedValuation[Tif_NonTIF],$A$4) -> 16495856 | K84: =SUMIFS(AssessedValuation[100% Industrial],AssessedValuation[Dist],$C84,AssessedValuation[Tif_NonTIF],$A$4) -> 97131100 | L84: =SUMIFS(AssessedValuation[100% Reserved],AssessedValuation[Dist],$C84,AssessedValuation[Tif_NonTIF],$A$4) -> 0 | M84: =SUMIFS(AssessedValuation[100% Reserved4],AssessedValuation[Dist],$C84,AssessedValuation[Tif_NonTIF],$A$4) -> 0 | N84: =SUMIFS(AssessedValuation[100% Railroads],AssessedValuation[Dist],$C84,AssessedValuation[Tif_NonTIF],$A$4) -> 15802562 | O84: =SUMIFS(AssessedValuation[100% Utilities],AssessedValuation[Dist],$C84,AssessedValuation[Tif_NonTIF],$A$4) -> 7602985 | P84: =SUMIFS(AssessedValuation[100% Other],AssessedValuation[Dist],$C84,AssessedValuation[Tif_NonTIF],$A$4) -> 0 | Q84: =SUMIFS(AssessedValuation[100% Gross],AssessedValuation[Dist],$C84,AssessedValuation[Tif_NonTIF],$A$4) -> 512120227 | R84: =SUMIFS(AssessedValuation[100% Military Exempt],AssessedValuation[Dist],$C84,AssessedValuation[Tif_NonTIF],$A$4) -> 540000 | S84: =SUMIFS(AssessedValuation[100% Homestead Exempt],AssessedValuation[Dist],$C84,AssessedValuation[Tif_NonTIF],$A$4) -> 1885000 | T84: =SUMIFS(AssessedValuation[100% Net],AssessedValuation[Dist],$C84,AssessedValuation[Tif_NonTIF],$A$4) -> 509695227 | U84: =SUMIFS(AssessedValuation[100% Gas & Elec Utilities],AssessedValuation[Dist],$C84,AssessedValuation[Tif_NonTIF],$A$4) -> 38384199 | V84: =SUM(T84:U84) -> 548079426
A85: 2026 | B85: 13 | C85: 1476 | D85: 1476 | E85: COUNCIL BLUFFS | F85: Council Bluffs | G85: =SUMIFS(AssessedValuation[100% Residential],AssessedValuation[Dist],$C85,AssessedValuation[Tif_NonTIF],$A$4) -> 3607955259 | H85: =SUMIFS(AssessedValuation[100% Ag Land],AssessedValuation[Dist],$C85,AssessedValuation[Tif_NonTIF],$A$4) -> 32813000 | I85: =SUMIFS(AssessedValuation[100% Ag Building],AssessedValuation[Dist],$C85,AssessedValuation[Tif_NonTIF],$A$4) -> 2817000 | J85: =SUMIFS(AssessedValuation[100% Commercial],AssessedValuation[Dist],$C85,AssessedValuation[Tif_NonTIF],$A$4) -> 1002965762 | K85: =SUMIFS(AssessedValuation[100% Industrial],AssessedValuation[Dist],$C85,AssessedValuation[Tif_NonTIF],$A$4) -> 125696067 | L85: =SUMIFS(AssessedValuation[100% Reserved],AssessedValuation[Dist],$C85,AssessedValuation[Tif_NonTIF],$A$4) -> 0 | M85: =SUMIFS(AssessedValuation[100% Reserved4],AssessedValuation[Dist],$C85,AssessedValuation[Tif_NonTIF],$A$4) -> 0 | N85: =SUMIFS(AssessedValuation[100% Railroads],AssessedValuation[Dist],$C85,AssessedValuation[Tif_NonTIF],$A$4) -> 33872142 | O85: =SUMIFS(AssessedValuation[100% Utilities],AssessedValuation[Dist],$C85,AssessedValuation[Tif_NonTIF],$A$4) -> 2791899 | P85: =SUMIFS(AssessedValuation[100% Other],AssessedValuation[Dist],$C85,AssessedValuation[Tif_NonTIF],$A$4) -> 0 | Q85: =SUMIFS(AssessedValuation[100% Gross],AssessedValuation[Dist],$C85,AssessedValuation[Tif_NonTIF],$A$4) -> 4808911129 | R85: =SUMIFS(AssessedValuation[100% Military Exempt],AssessedValuation[Dist],$C85,AssessedValuation[Tif_NonTIF],$A$4) -> 7668000 | S85: =SUMIFS(AssessedValuation[100% Homestead Exempt],AssessedValuation[Dist],$C85,AssessedValuation[Tif_NonTIF],$A$4) -> 19396000 | T85: =SUMIFS(AssessedValuation[100% Net],AssessedValuation[Dist],$C85,AssessedValuation[Tif_NonTIF],$A$4) -> 4781847129 | U85: =SUMIFS(AssessedValuation[100% Gas & Elec Utilities],AssessedValuation[Dist],$C85,AssessedValuation[Tif_NonTIF],$A$4) -> 294134368 | V85: =SUM(T85:U85) -> 5075981497
A86: 2026 | B86: 13 | C86: 1503 | D86: 1503 | E86: CRESTON | F86: Creston | G86: =SUMIFS(AssessedValuation[100% Residential],AssessedValuation[Dist],$C86,AssessedValuation[Tif_NonTIF],$A$4) -> 584212764 | H86: =SUMIFS(AssessedValuation[100% Ag Land],AssessedValuation[Dist],$C86,AssessedValuation[Tif_NonTIF],$A$4) -> 158139417 | I86: =SUMIFS(AssessedValuation[100% Ag Building],AssessedValuation[Dist],$C86,AssessedValuation[Tif_NonTIF],$A$4) -> 17233188 | J86: =SUMIFS(AssessedValuation[100% Commercial],AssessedValuation[Dist],$C86,AssessedValuation[Tif_NonTIF],$A$4) -> 98938632 | K86: =SUMIFS(AssessedValuation[100% Industrial],AssessedValuation[Dist],$C86,AssessedValuation[Tif_NonTIF],$A$4) -> 28679602 | L86: =SUMIFS(AssessedValuation[100% Reserved],AssessedValuation[Dist],$C86,AssessedValuation[Tif_NonTIF],$A$4) -> 0 | M86: =SUMIFS(AssessedValuation[100% Reserved4],AssessedValuation[Dist],$C86,AssessedValuation[Tif_NonTIF],$A$4) -> 0 | N86: =SUMIFS(AssessedValuation[100% Railroads],AssessedValuation[Dist],$C86,AssessedValuation[Tif_NonTIF],$A$4) -> 25007269 | O86: =SUMIFS(AssessedValuation[100% Utilities],AssessedValuation[Dist],$C86,AssessedValuation[Tif_NonTIF],$A$4) -> 6087838 | P86: =SUMIFS(AssessedValuation[100% Other],AssessedValuation[Dist],$C86,AssessedValuation[Tif_NonTIF],$A$4) -> 0 | Q86: =SUMIFS(AssessedValuation[100% Gross],AssessedValuation[Dist],$C86,AssessedValuation[Tif_NonTIF],$A$4) -> 918298710 | R86: =SUMIFS(AssessedValuation[100% Military Exempt],AssessedValuation[Dist],$C86,AssessedValuation[Tif_NonTIF],$A$4) -> 1498747 | S86: =SUMIFS(AssessedValuation[100% Homestead Exempt],AssessedValuation[Dist],$C86,AssessedValuation[Tif_NonTIF],$A$4) -> 6174028 | T86: =SUMIFS(AssessedValuation[100% Net],AssessedValuation[Dist],$C86,AssessedValuation[Tif_NonTIF],$A$4) -> 910625935 | U86: =SUMIFS(AssessedValuation[100% Gas & Elec Utilities],AssessedValuation[Dist],$C86,AssessedValuation[Tif_NonTIF],$A$4) -> 281815556 | V86: =SUM(T86:U86) -> 1192441491
... A337: 2026 | B337: 11 | C337: 7110 | D337: 7110 | E337: WOODWARD-GRANGER | F337: Woodward-Granger | G337: =SUMIFS(AssessedValuation[100% Residential],AssessedValuation[Dist],$C337,AssessedValuation[Tif_NonTIF],$A$4) -> 646906743 | H337: =SUMIFS(AssessedValuation[100% Ag Land],AssessedValuation[Dist],$C337,AssessedValuation[Tif_NonTIF],$A$4) -> 90475832 | I337: =SUMIFS(AssessedValuation[100% Ag Building],AssessedValuation[Dist],$C337,AssessedValuation[Tif_NonTIF],$A$4) -> 5206020 | J337: =SUMIFS(AssessedValuation[100% Commercial],AssessedValuation[Dist],$C337,AssessedValuation[Tif_NonTIF],$A$4) -> 50105103 | K337: =SUMIFS(AssessedValuation[100% Industrial],AssessedValuation[Dist],$C337,AssessedValuation[Tif_NonTIF],$A$4) -> 225250 | L337: =SUMIFS(AssessedValuation[100% Reserved],AssessedValuation[Dist],$C337,AssessedValuation[Tif_NonTIF],$A$4) -> 0 | M337: =SUMIFS(AssessedValuation[100% Reserved4],AssessedValuation[Dist],$C337,AssessedValuation[Tif_NonTIF],$A$4) -> 0 | N337: =SUMIFS(AssessedValuation[100% Railroads],AssessedValuation[Dist],$C337,AssessedValuation[Tif_NonTIF],$A$4) -> 0 | O337: =SUMIFS(AssessedValuation[100% Utilities],AssessedValuation[Dist],$C337,AssessedValuation[Tif_NonTIF],$A$4) -> 5651630 | P337: =SUMIFS(AssessedValuation[100% Other],AssessedValuation[Dist],$C337,AssessedValuation[Tif_NonTIF],$A$4) -> 4841 | Q337: =SUMIFS(AssessedValuation[100% Gross],AssessedValuation[Dist],$C337,AssessedValuation[Tif_NonTIF],$A$4) -> 798575419 | R337: =SUMIFS(AssessedValuation[100% Military Exempt],AssessedValuation[Dist],$C337,AssessedValuation[Tif_NonTIF],$A$4) -> 800000 | S337: =SUMIFS(AssessedValuation[100% Homestead Exempt],AssessedValuation[Dist],$C337,AssessedValuation[Tif_NonTIF],$A$4) -> 2197000 | T337: =SUMIFS(AssessedValuation[100% Net],AssessedValuation[Dist],$C337,AssessedValuation[Tif_NonTIF],$A$4) -> 795578419 | U337: =SUMIFS(AssessedValuation[100% Gas & Elec Utilities],AssessedValuation[Dist],$C337,AssessedValuation[Tif_NonTIF],$A$4) -> 36391486 | V337: =SUM(T337:U337) -> 831969905
G338: =SUM(G7:G337) -> 264701348114 | H338: =SUM(H7:H337) -> 52323547267 | I338: =SUM(I7:I337) -> 3944549474 | J338: =SUM(J7:J337) -> 45342559883 | K338: =SUM(K7:K337) -> 12525096309 | L338: =SUM(L7:L337) -> 0 | M338: =SUM(M7:M337) -> 0 | N338: =SUM(N7:N337) -> 3136757995 | ... V338: =SUM(V7:V337) -> 412989940336

Sheet Assessed TIF
A1: ='Assessed Non-TIF'!$A$1 -> Iowa Department of Management - June 25, 2025 - Final
A2: =_xlfn.CONCAT("January 1, ",AssessedValuation[[#This Row],[Year]]," - 100% Valuations Before Rollback") -> January 1, 2024 - 100% Valuations Before Rollback
A3: =_xlfn.CONCAT("For Fiscal Year ",'2024_School_100pct Valuations B'!A2+2," Budgets") -> For Fiscal Year 2026 Budgets
A4: TIF
A6: FiscalYear | B6: AEA | C6: Dist | D6: DistrictNumber | E6: NAME | F6: Label | G6: 100% Residential | H6: 100% Ag Land | I6: 100% Ag Building | J6: 100% Commercial | K6: 100% Industrial | L6: 100% Reserved | M6: 100% Reserved | N6: 100% Railroads | O6: 100% Utilities | P6: 100% Other | Q6: 100% Gross | R6: 100% Military Exempt | S6: 100% Homestead Exempt | T6: 100% Net | U6: 100% Gas & Elec Utilities | V6: Valuation With G&E Utilities
A7: ='Assessed Non-TIF'!A7 -> 2026 | B7: ='Assessed Non-TIF'!B7 -> 11 | C7: ='Assessed Non-TIF'!C7 -> 0018 | D7: ='Assessed Non-TIF'!D7 -> 0018 | E7: ='Assessed Non-TIF'!E7 -> ADAIR-CASEY | F7: ='Assessed Non-TIF'!F7 -> Adair-Casey | G7: =SUMIFS(AssessedValuation[100% Residential],AssessedValuation[Dist],$C7,AssessedValuation[Tif_NonTIF],$A$4) -> 14885468 | H7: =SUMIFS(AssessedValuation[100% Ag Land],AssessedValuation[Dist],$C7,AssessedValuation[Tif_NonTIF],$A$4) -> 206646 | I7: =SUMIFS(AssessedValuation[100% Ag Building],AssessedValuation[Dist],$C7,AssessedValuation[Tif_NonTIF],$A$4) -> 0 | J7: =SUMIFS(AssessedValuation[100% Commercial],AssessedValuation[Dist],$C7,AssessedValuation[Tif_NonTIF],$A$4) -> 8493516 | K7: =SUMIFS(AssessedValuation[100% Industrial],AssessedValuation[Dist],$C7,AssessedValuation[Tif_NonTIF],$A$4) -> 148565749 | L7: =SUMIFS(AssessedValuation[100% Reserved],AssessedValuation[Dist],$C7,AssessedValuation[Tif_NonTIF],$A$4) -> 0 | M7: =SUMIFS(AssessedValuation[100% Reserved4],AssessedValuation[Dist],$C7,AssessedValuation[Tif_NonTIF],$A$4) -> 0 | N7: =SUMIFS(AssessedValuation[100% Railroads],AssessedValuation[Dist],$C7,AssessedValuation[Tif_NonTIF],$A$4) -> 0 | O7: =SUMIFS(AssessedValuation[100% Utilities],AssessedValuation[Dist],$C7,AssessedValuation[Tif_NonTIF],$A$4) -> 0 | P7: =SUMIFS(AssessedValuation[100% Other],AssessedValuation[Dist],$C7,AssessedValuation[Tif_NonTIF],$A$4) -> 0 | Q7: =SUMIFS(AssessedValuation[100% Gross],AssessedValuation[Dist],$C7,AssessedValuation[Tif_NonTIF],$A$4) -> 172151379 | R7: =SUMIFS(AssessedValuation[100% Military Exempt],AssessedValuation[Dist],$C7,AssessedValuation[Tif_NonTIF],$A$4) -> 8000 | S7: =SUMIFS(AssessedValuation[100% Homestead Exempt],AssessedValuation[Dist],$C7,AssessedValuation[Tif_NonTIF],$A$4) -> 19500 | T7: =SUMIFS(AssessedValuation[100% Net],AssessedValuation[Dist],$C7,AssessedValuation[Tif_NonTIF],$A$4) -> 172123879 | U7: =SUMIFS(AssessedValuation[100% Gas & Elec Utilities],AssessedValuation[Dist],$C7,AssessedValuation[Tif_NonTIF],$A$4) -> 0 | V7: =SUM(T7:U7) -> 172123879
